[2024-02-17 17:35:30,045][flwr][WARNING] - Both server and strategy were provided, ignoring strategy
[2024-02-17 17:35:30,048][flwr][INFO] - Starting Flower simulation, config: ServerConfig(num_rounds=1, round_timeout=None)
[2024-02-17 17:35:37,288][flwr][INFO] - Flower VCE: Ray initialized with resources: {'node:127.0.0.1': 1.0, 'memory': 1635205940.0, 'object_store_memory': 817602969.0, 'node:__internal_head__': 1.0, 'CPU': 4.0}
[2024-02-17 17:35:37,288][flwr][INFO] - Optimize your simulation with Flower VCE: https://flower.dev/docs/framework/how-to-run-simulations.html
[2024-02-17 17:35:37,288][flwr][INFO] - Flower VCE: Resources for each Virtual Client: {'num_cpus': 2, 'num_gpus': 0.0}
[2024-02-17 17:35:37,314][flwr][INFO] - Flower VCE: Creating VirtualClientEngineActorPool with 2 actors
[2024-02-17 17:35:37,318][flwr][INFO] - Initializing global parameters
[2024-02-17 17:35:37,318][flwr][INFO] - Requesting initial parameters from one random ScaffoldClient
[2024-02-17 17:35:45,471][flwr][INFO] - Received initial parameters from one random ScaffoldClient
[2024-02-17 17:35:45,513][flwr][INFO] - Evaluating initial parameters
[2024-02-17 17:38:46,664][flwr][INFO] - initial parameters (loss, other metrics): 0.022486926078796387, {'accuracy': 26.6015625}
[2024-02-17 17:38:46,684][flwr][INFO] - FL starting
[2024-02-17 17:38:47,488][flwr][DEBUG] - fit_round 1: strategy sampled 10 clients (out of 100)
[2024-02-17 17:38:50,867][flwr][ERROR] - Traceback (most recent call last):
  File "C:\Users\Stavros\miniconda3\envs\pyt_pg\Lib\site-packages\flwr\simulation\ray_transport\ray_client_proxy.py", line 151, in _submit_job
    res, updated_context = self.actor_pool.get_client_result(self.cid, timeout)
                           ^^^^^^^^^^^^^^^^^^^^^^^^^^^^^^^^^^^^^^^^^^^^^^^^^^^^
  File "C:\Users\Stavros\miniconda3\envs\pyt_pg\Lib\site-packages\flwr\simulation\ray_transport\ray_actor.py", line 425, in get_client_result
    return self._fetch_future_result(cid)
           ^^^^^^^^^^^^^^^^^^^^^^^^^^^^^^
  File "C:\Users\Stavros\miniconda3\envs\pyt_pg\Lib\site-packages\flwr\simulation\ray_transport\ray_actor.py", line 306, in _fetch_future_result
    res_cid, res, updated_context = ray.get(
                                    ^^^^^^^^
  File "C:\Users\Stavros\miniconda3\envs\pyt_pg\Lib\site-packages\ray\_private\auto_init_hook.py", line 24, in auto_init_wrapper
    return fn(*args, **kwargs)
           ^^^^^^^^^^^^^^^^^^^
  File "C:\Users\Stavros\miniconda3\envs\pyt_pg\Lib\site-packages\ray\_private\client_mode_hook.py", line 103, in wrapper
    return func(*args, **kwargs)
           ^^^^^^^^^^^^^^^^^^^^^
  File "C:\Users\Stavros\miniconda3\envs\pyt_pg\Lib\site-packages\ray\_private\worker.py", line 2524, in get
    raise value.as_instanceof_cause()
ray.exceptions.RayTaskError(ClientException): [36mray::DefaultActor.run()[39m (pid=7276, ip=127.0.0.1, actor_id=2b56f33712a0c96a8e8982de01000000, repr=<flwr.simulation.ray_transport.ray_actor.DefaultActor object at 0x0000019069371690>)
                  ^^^^^^^^^^^^^^
  File "C:\Users\Stavros\miniconda3\envs\pyt_pg\Lib\site-packages\flwr\simulation\ray_transport\ray_client_proxy.py", line 207, in fit
    return maybe_call_fit(
           ^^^^^^^^^^^^^^^
  File "C:\Users\Stavros\miniconda3\envs\pyt_pg\Lib\site-packages\flwr\client\client.py", line 234, in maybe_call_fit
    return client.fit(fit_ins)
           ^^^^^^^^^^^^^^^^^^^
  File "C:\Users\Stavros\miniconda3\envs\pyt_pg\Lib\site-packages\flwr\client\numpy_client.py", line 238, in _fit
    results = self.numpy_client.fit(parameters, ins.config)  # type: ignore
              ^^^^^^^^^^^^^^^^^^^^^^^^^^^^^^^^^^^^^^^^^^^^^
  File "C:\Users\Stavros\Desktop\PythonProjects\FlowerYtTut\client_scaffold.py", line 67, in fit
    self.set_parameters(parameters)
  File "C:\Users\Stavros\Desktop\PythonProjects\FlowerYtTut\client_scaffold.py", line 52, in set_parameters
    self.model.load_state_dict(state_dict, strict=True)
  File "C:\Users\Stavros\miniconda3\envs\pyt_pg\Lib\site-packages\torch\nn\modules\module.py", line 2138, in load_state_dict
    load(self, state_dict)
  File "C:\Users\Stavros\miniconda3\envs\pyt_pg\Lib\site-packages\torch\nn\modules\module.py", line 2126, in load
    load(child, child_state_dict, child_prefix)
  File "C:\Users\Stavros\miniconda3\envs\pyt_pg\Lib\site-packages\torch\nn\modules\module.py", line 2126, in load
    load(child, child_state_dict, child_prefix)
  File "C:\Users\Stavros\miniconda3\envs\pyt_pg\Lib\site-packages\torch\nn\modules\module.py", line 2120, in load
    module._load_from_state_dict(
  File "C:\Users\Stavros\miniconda3\envs\pyt_pg\Lib\site-packages\torch\nn\modules\batchnorm.py", line 110, in _load_from_state_dict
    super()._load_from_state_dict(
  File "C:\Users\Stavros\miniconda3\envs\pyt_pg\Lib\site-packages\torch\nn\modules\module.py", line 2015, in _load_from_state_dict
    input_param = input_param[0]
                  ~~~~~~~~~~~^^^
IndexError: index 0 is out of bounds for dimension 0 with size 0

The above exception was the direct cause of the following exception:

[36mray::DefaultActor.run()[39m (pid=7276, ip=127.0.0.1, actor_id=2b56f33712a0c96a8e8982de01000000, repr=<flwr.simulation.ray_transport.ray_actor.DefaultActor object at 0x0000019069371690>)
  File "python\ray\_raylet.pyx", line 1418, in ray._raylet.execute_task
  File "python\ray\_raylet.pyx", line 1498, in ray._raylet.execute_task
  File "python\ray\_raylet.pyx", line 1424, in ray._raylet.execute_task
  File "python\ray\_raylet.pyx", line 1364, in ray._raylet.execute_task.function_executor
  File "C:\Users\Stavros\miniconda3\envs\pyt_pg\Lib\site-packages\ray\_private\function_manager.py", line 726, in actor_method_executor
    return method(__ray_actor, *args, **kwargs)
           ^^^^^^^^^^^^^^^^^^^^^^^^^^^^^^^^^^^^
  File "C:\Users\Stavros\miniconda3\envs\pyt_pg\Lib\site-packages\ray\util\tracing\tracing_helper.py", line 464, in _resume_span
    return method(self, *_args, **_kwargs)
           ^^^^^^^^^^^^^^^^^^^^^^^^^^^^^^^
  File "C:\Users\Stavros\miniconda3\envs\pyt_pg\Lib\site-packages\flwr\simulation\ray_transport\ray_actor.py", line 90, in run
    raise ClientException(str(message)) from ex
flwr.simulation.ray_transport.ray_actor.ClientException: 
>>>>>>>A ClientException occurred.('\n\tSomething went wrong when running your client run.\n\tClient 78 crashed when the DefaultActor was running its run.\n\tException triggered on the client side: Traceback (most recent call last):\n  File "C:\\Users\\Stavros\\miniconda3\\envs\\pyt_pg\\Lib\\site-packages\\flwr\\simulation\\ray_transport\\ray_actor.py", line 76, in run\n    job_results = job_fn(client)\n                  ^^^^^^^^^^^^^^\n  File "C:\\Users\\Stavros\\miniconda3\\envs\\pyt_pg\\Lib\\site-packages\\flwr\\simulation\\ray_transport\\ray_client_proxy.py", line 207, in fit\n    return maybe_call_fit(\n           ^^^^^^^^^^^^^^^\n  File "C:\\Users\\Stavros\\miniconda3\\envs\\pyt_pg\\Lib\\site-packages\\flwr\\client\\client.py", line 234, in maybe_call_fit\n    return client.fit(fit_ins)\n           ^^^^^^^^^^^^^^^^^^^\n  File "C:\\Users\\Stavros\\miniconda3\\envs\\pyt_pg\\Lib\\site-packages\\flwr\\client\\numpy_client.py", line 238, in _fit\n    results = self.numpy_client.fit(parameters, ins.config)  # type: ignore\n              ^^^^^^^^^^^^^^^^^^^^^^^^^^^^^^^^^^^^^^^^^^^^^\n  File "C:\\Users\\Stavros\\Desktop\\PythonProjects\\FlowerYtTut\\client_scaffold.py", line 67, in fit\n    self.set_parameters(parameters)\n  File "C:\\Users\\Stavros\\Desktop\\PythonProjects\\FlowerYtTut\\client_scaffold.py", line 52, in set_parameters\n    self.model.load_state_dict(state_dict, strict=True)\n  File "C:\\Users\\Stavros\\miniconda3\\envs\\pyt_pg\\Lib\\site-packages\\torch\\nn\\modules\\module.py", line 2138, in load_state_dict\n    load(self, state_dict)\n  File "C:\\Users\\Stavros\\miniconda3\\envs\\pyt_pg\\Lib\\site-packages\\torch\\nn\\modules\\module.py", line 2126, in load\n    load(child, child_state_dict, child_prefix)\n  File "C:\\Users\\Stavros\\miniconda3\\envs\\pyt_pg\\Lib\\site-packages\\torch\\nn\\modules\\module.py", line 2126, in load\n    load(child, child_state_dict, child_prefix)\n  File "C:\\Users\\Stavros\\miniconda3\\envs\\pyt_pg\\Lib\\site-packages\\torch\\nn\\modules\\module.py", line 2120, in load\n    module._load_from_state_dict(\n  File "C:\\Users\\Stavros\\miniconda3\\envs\\pyt_pg\\Lib\\site-packages\\torch\\nn\\modules\\batchnorm.py", line 110, in _load_from_state_dict\n    super()._load_from_state_dict(\n  File "C:\\Users\\Stavros\\miniconda3\\envs\\pyt_pg\\Lib\\site-packages\\torch\\nn\\modules\\module.py", line 2015, in _load_from_state_dict\n    input_param = input_param[0]\n                  ~~~~~~~~~~~^^^\nIndexError: index 0 is out of bounds for dimension 0 with size 0\n',)

[2024-02-17 17:38:50,892][flwr][ERROR] - [36mray::DefaultActor.run()[39m (pid=7276, ip=127.0.0.1, actor_id=2b56f33712a0c96a8e8982de01000000, repr=<flwr.simulation.ray_transport.ray_actor.DefaultActor object at 0x0000019069371690>)
                  ^^^^^^^^^^^^^^
  File "C:\Users\Stavros\miniconda3\envs\pyt_pg\Lib\site-packages\flwr\simulation\ray_transport\ray_client_proxy.py", line 207, in fit
    return maybe_call_fit(
           ^^^^^^^^^^^^^^^
  File "C:\Users\Stavros\miniconda3\envs\pyt_pg\Lib\site-packages\flwr\client\client.py", line 234, in maybe_call_fit
    return client.fit(fit_ins)
           ^^^^^^^^^^^^^^^^^^^
  File "C:\Users\Stavros\miniconda3\envs\pyt_pg\Lib\site-packages\flwr\client\numpy_client.py", line 238, in _fit
    results = self.numpy_client.fit(parameters, ins.config)  # type: ignore
              ^^^^^^^^^^^^^^^^^^^^^^^^^^^^^^^^^^^^^^^^^^^^^
  File "C:\Users\Stavros\Desktop\PythonProjects\FlowerYtTut\client_scaffold.py", line 67, in fit
    self.set_parameters(parameters)
  File "C:\Users\Stavros\Desktop\PythonProjects\FlowerYtTut\client_scaffold.py", line 52, in set_parameters
    self.model.load_state_dict(state_dict, strict=True)
  File "C:\Users\Stavros\miniconda3\envs\pyt_pg\Lib\site-packages\torch\nn\modules\module.py", line 2138, in load_state_dict
    load(self, state_dict)
  File "C:\Users\Stavros\miniconda3\envs\pyt_pg\Lib\site-packages\torch\nn\modules\module.py", line 2126, in load
    load(child, child_state_dict, child_prefix)
  File "C:\Users\Stavros\miniconda3\envs\pyt_pg\Lib\site-packages\torch\nn\modules\module.py", line 2126, in load
    load(child, child_state_dict, child_prefix)
  File "C:\Users\Stavros\miniconda3\envs\pyt_pg\Lib\site-packages\torch\nn\modules\module.py", line 2120, in load
    module._load_from_state_dict(
  File "C:\Users\Stavros\miniconda3\envs\pyt_pg\Lib\site-packages\torch\nn\modules\batchnorm.py", line 110, in _load_from_state_dict
    super()._load_from_state_dict(
  File "C:\Users\Stavros\miniconda3\envs\pyt_pg\Lib\site-packages\torch\nn\modules\module.py", line 2015, in _load_from_state_dict
    input_param = input_param[0]
                  ~~~~~~~~~~~^^^
IndexError: index 0 is out of bounds for dimension 0 with size 0

The above exception was the direct cause of the following exception:

[36mray::DefaultActor.run()[39m (pid=7276, ip=127.0.0.1, actor_id=2b56f33712a0c96a8e8982de01000000, repr=<flwr.simulation.ray_transport.ray_actor.DefaultActor object at 0x0000019069371690>)
  File "python\ray\_raylet.pyx", line 1418, in ray._raylet.execute_task
  File "python\ray\_raylet.pyx", line 1498, in ray._raylet.execute_task
  File "python\ray\_raylet.pyx", line 1424, in ray._raylet.execute_task
  File "python\ray\_raylet.pyx", line 1364, in ray._raylet.execute_task.function_executor
  File "C:\Users\Stavros\miniconda3\envs\pyt_pg\Lib\site-packages\ray\_private\function_manager.py", line 726, in actor_method_executor
    return method(__ray_actor, *args, **kwargs)
           ^^^^^^^^^^^^^^^^^^^^^^^^^^^^^^^^^^^^
  File "C:\Users\Stavros\miniconda3\envs\pyt_pg\Lib\site-packages\ray\util\tracing\tracing_helper.py", line 464, in _resume_span
    return method(self, *_args, **_kwargs)
           ^^^^^^^^^^^^^^^^^^^^^^^^^^^^^^^
  File "C:\Users\Stavros\miniconda3\envs\pyt_pg\Lib\site-packages\flwr\simulation\ray_transport\ray_actor.py", line 90, in run
    raise ClientException(str(message)) from ex
flwr.simulation.ray_transport.ray_actor.ClientException: 
>>>>>>>A ClientException occurred.('\n\tSomething went wrong when running your client run.\n\tClient 78 crashed when the DefaultActor was running its run.\n\tException triggered on the client side: Traceback (most recent call last):\n  File "C:\\Users\\Stavros\\miniconda3\\envs\\pyt_pg\\Lib\\site-packages\\flwr\\simulation\\ray_transport\\ray_actor.py", line 76, in run\n    job_results = job_fn(client)\n                  ^^^^^^^^^^^^^^\n  File "C:\\Users\\Stavros\\miniconda3\\envs\\pyt_pg\\Lib\\site-packages\\flwr\\simulation\\ray_transport\\ray_client_proxy.py", line 207, in fit\n    return maybe_call_fit(\n           ^^^^^^^^^^^^^^^\n  File "C:\\Users\\Stavros\\miniconda3\\envs\\pyt_pg\\Lib\\site-packages\\flwr\\client\\client.py", line 234, in maybe_call_fit\n    return client.fit(fit_ins)\n           ^^^^^^^^^^^^^^^^^^^\n  File "C:\\Users\\Stavros\\miniconda3\\envs\\pyt_pg\\Lib\\site-packages\\flwr\\client\\numpy_client.py", line 238, in _fit\n    results = self.numpy_client.fit(parameters, ins.config)  # type: ignore\n              ^^^^^^^^^^^^^^^^^^^^^^^^^^^^^^^^^^^^^^^^^^^^^\n  File "C:\\Users\\Stavros\\Desktop\\PythonProjects\\FlowerYtTut\\client_scaffold.py", line 67, in fit\n    self.set_parameters(parameters)\n  File "C:\\Users\\Stavros\\Desktop\\PythonProjects\\FlowerYtTut\\client_scaffold.py", line 52, in set_parameters\n    self.model.load_state_dict(state_dict, strict=True)\n  File "C:\\Users\\Stavros\\miniconda3\\envs\\pyt_pg\\Lib\\site-packages\\torch\\nn\\modules\\module.py", line 2138, in load_state_dict\n    load(self, state_dict)\n  File "C:\\Users\\Stavros\\miniconda3\\envs\\pyt_pg\\Lib\\site-packages\\torch\\nn\\modules\\module.py", line 2126, in load\n    load(child, child_state_dict, child_prefix)\n  File "C:\\Users\\Stavros\\miniconda3\\envs\\pyt_pg\\Lib\\site-packages\\torch\\nn\\modules\\module.py", line 2126, in load\n    load(child, child_state_dict, child_prefix)\n  File "C:\\Users\\Stavros\\miniconda3\\envs\\pyt_pg\\Lib\\site-packages\\torch\\nn\\modules\\module.py", line 2120, in load\n    module._load_from_state_dict(\n  File "C:\\Users\\Stavros\\miniconda3\\envs\\pyt_pg\\Lib\\site-packages\\torch\\nn\\modules\\batchnorm.py", line 110, in _load_from_state_dict\n    super()._load_from_state_dict(\n  File "C:\\Users\\Stavros\\miniconda3\\envs\\pyt_pg\\Lib\\site-packages\\torch\\nn\\modules\\module.py", line 2015, in _load_from_state_dict\n    input_param = input_param[0]\n                  ~~~~~~~~~~~^^^\nIndexError: index 0 is out of bounds for dimension 0 with size 0\n',)
[2024-02-17 17:38:53,078][flwr][ERROR] - Traceback (most recent call last):
  File "C:\Users\Stavros\miniconda3\envs\pyt_pg\Lib\site-packages\flwr\simulation\ray_transport\ray_client_proxy.py", line 151, in _submit_job
    res, updated_context = self.actor_pool.get_client_result(self.cid, timeout)
                           ^^^^^^^^^^^^^^^^^^^^^^^^^^^^^^^^^^^^^^^^^^^^^^^^^^^^
  File "C:\Users\Stavros\miniconda3\envs\pyt_pg\Lib\site-packages\flwr\simulation\ray_transport\ray_actor.py", line 425, in get_client_result
    return self._fetch_future_result(cid)
           ^^^^^^^^^^^^^^^^^^^^^^^^^^^^^^
  File "C:\Users\Stavros\miniconda3\envs\pyt_pg\Lib\site-packages\flwr\simulation\ray_transport\ray_actor.py", line 306, in _fetch_future_result
    res_cid, res, updated_context = ray.get(
                                    ^^^^^^^^
  File "C:\Users\Stavros\miniconda3\envs\pyt_pg\Lib\site-packages\ray\_private\auto_init_hook.py", line 24, in auto_init_wrapper
    return fn(*args, **kwargs)
           ^^^^^^^^^^^^^^^^^^^
  File "C:\Users\Stavros\miniconda3\envs\pyt_pg\Lib\site-packages\ray\_private\client_mode_hook.py", line 103, in wrapper
    return func(*args, **kwargs)
           ^^^^^^^^^^^^^^^^^^^^^
  File "C:\Users\Stavros\miniconda3\envs\pyt_pg\Lib\site-packages\ray\_private\worker.py", line 2524, in get
    raise value.as_instanceof_cause()
ray.exceptions.RayTaskError(ClientException): [36mray::DefaultActor.run()[39m (pid=7276, ip=127.0.0.1, actor_id=2b56f33712a0c96a8e8982de01000000, repr=<flwr.simulation.ray_transport.ray_actor.DefaultActor object at 0x0000019069371690>)
                  ^^^^^^^^^^^^^^
  File "C:\Users\Stavros\miniconda3\envs\pyt_pg\Lib\site-packages\flwr\simulation\ray_transport\ray_client_proxy.py", line 207, in fit
    return maybe_call_fit(
           ^^^^^^^^^^^^^^^
  File "C:\Users\Stavros\miniconda3\envs\pyt_pg\Lib\site-packages\flwr\client\client.py", line 234, in maybe_call_fit
    return client.fit(fit_ins)
           ^^^^^^^^^^^^^^^^^^^
  File "C:\Users\Stavros\miniconda3\envs\pyt_pg\Lib\site-packages\flwr\client\numpy_client.py", line 238, in _fit
    results = self.numpy_client.fit(parameters, ins.config)  # type: ignore
              ^^^^^^^^^^^^^^^^^^^^^^^^^^^^^^^^^^^^^^^^^^^^^
  File "C:\Users\Stavros\Desktop\PythonProjects\FlowerYtTut\client_scaffold.py", line 67, in fit
    self.set_parameters(parameters)
  File "C:\Users\Stavros\Desktop\PythonProjects\FlowerYtTut\client_scaffold.py", line 52, in set_parameters
    self.model.load_state_dict(state_dict, strict=True)
  File "C:\Users\Stavros\miniconda3\envs\pyt_pg\Lib\site-packages\torch\nn\modules\module.py", line 2138, in load_state_dict
    load(self, state_dict)
  File "C:\Users\Stavros\miniconda3\envs\pyt_pg\Lib\site-packages\torch\nn\modules\module.py", line 2126, in load
    load(child, child_state_dict, child_prefix)
  File "C:\Users\Stavros\miniconda3\envs\pyt_pg\Lib\site-packages\torch\nn\modules\module.py", line 2126, in load
    load(child, child_state_dict, child_prefix)
  File "C:\Users\Stavros\miniconda3\envs\pyt_pg\Lib\site-packages\torch\nn\modules\module.py", line 2120, in load
    module._load_from_state_dict(
  File "C:\Users\Stavros\miniconda3\envs\pyt_pg\Lib\site-packages\torch\nn\modules\batchnorm.py", line 110, in _load_from_state_dict
    super()._load_from_state_dict(
  File "C:\Users\Stavros\miniconda3\envs\pyt_pg\Lib\site-packages\torch\nn\modules\module.py", line 2015, in _load_from_state_dict
    input_param = input_param[0]
                  ~~~~~~~~~~~^^^
IndexError: index 0 is out of bounds for dimension 0 with size 0

The above exception was the direct cause of the following exception:

[36mray::DefaultActor.run()[39m (pid=7276, ip=127.0.0.1, actor_id=2b56f33712a0c96a8e8982de01000000, repr=<flwr.simulation.ray_transport.ray_actor.DefaultActor object at 0x0000019069371690>)
  File "python\ray\_raylet.pyx", line 1418, in ray._raylet.execute_task
  File "python\ray\_raylet.pyx", line 1498, in ray._raylet.execute_task
  File "python\ray\_raylet.pyx", line 1424, in ray._raylet.execute_task
  File "python\ray\_raylet.pyx", line 1364, in ray._raylet.execute_task.function_executor
  File "C:\Users\Stavros\miniconda3\envs\pyt_pg\Lib\site-packages\ray\_private\function_manager.py", line 726, in actor_method_executor
    return method(__ray_actor, *args, **kwargs)
           ^^^^^^^^^^^^^^^^^^^^^^^^^^^^^^^^^^^^
  File "C:\Users\Stavros\miniconda3\envs\pyt_pg\Lib\site-packages\ray\util\tracing\tracing_helper.py", line 464, in _resume_span
    return method(self, *_args, **_kwargs)
           ^^^^^^^^^^^^^^^^^^^^^^^^^^^^^^^
  File "C:\Users\Stavros\miniconda3\envs\pyt_pg\Lib\site-packages\flwr\simulation\ray_transport\ray_actor.py", line 90, in run
    raise ClientException(str(message)) from ex
flwr.simulation.ray_transport.ray_actor.ClientException: 
>>>>>>>A ClientException occurred.('\n\tSomething went wrong when running your client run.\n\tClient 68 crashed when the DefaultActor was running its run.\n\tException triggered on the client side: Traceback (most recent call last):\n  File "C:\\Users\\Stavros\\miniconda3\\envs\\pyt_pg\\Lib\\site-packages\\flwr\\simulation\\ray_transport\\ray_actor.py", line 76, in run\n    job_results = job_fn(client)\n                  ^^^^^^^^^^^^^^\n  File "C:\\Users\\Stavros\\miniconda3\\envs\\pyt_pg\\Lib\\site-packages\\flwr\\simulation\\ray_transport\\ray_client_proxy.py", line 207, in fit\n    return maybe_call_fit(\n           ^^^^^^^^^^^^^^^\n  File "C:\\Users\\Stavros\\miniconda3\\envs\\pyt_pg\\Lib\\site-packages\\flwr\\client\\client.py", line 234, in maybe_call_fit\n    return client.fit(fit_ins)\n           ^^^^^^^^^^^^^^^^^^^\n  File "C:\\Users\\Stavros\\miniconda3\\envs\\pyt_pg\\Lib\\site-packages\\flwr\\client\\numpy_client.py", line 238, in _fit\n    results = self.numpy_client.fit(parameters, ins.config)  # type: ignore\n              ^^^^^^^^^^^^^^^^^^^^^^^^^^^^^^^^^^^^^^^^^^^^^\n  File "C:\\Users\\Stavros\\Desktop\\PythonProjects\\FlowerYtTut\\client_scaffold.py", line 67, in fit\n    self.set_parameters(parameters)\n  File "C:\\Users\\Stavros\\Desktop\\PythonProjects\\FlowerYtTut\\client_scaffold.py", line 52, in set_parameters\n    self.model.load_state_dict(state_dict, strict=True)\n  File "C:\\Users\\Stavros\\miniconda3\\envs\\pyt_pg\\Lib\\site-packages\\torch\\nn\\modules\\module.py", line 2138, in load_state_dict\n    load(self, state_dict)\n  File "C:\\Users\\Stavros\\miniconda3\\envs\\pyt_pg\\Lib\\site-packages\\torch\\nn\\modules\\module.py", line 2126, in load\n    load(child, child_state_dict, child_prefix)\n  File "C:\\Users\\Stavros\\miniconda3\\envs\\pyt_pg\\Lib\\site-packages\\torch\\nn\\modules\\module.py", line 2126, in load\n    load(child, child_state_dict, child_prefix)\n  File "C:\\Users\\Stavros\\miniconda3\\envs\\pyt_pg\\Lib\\site-packages\\torch\\nn\\modules\\module.py", line 2120, in load\n    module._load_from_state_dict(\n  File "C:\\Users\\Stavros\\miniconda3\\envs\\pyt_pg\\Lib\\site-packages\\torch\\nn\\modules\\batchnorm.py", line 110, in _load_from_state_dict\n    super()._load_from_state_dict(\n  File "C:\\Users\\Stavros\\miniconda3\\envs\\pyt_pg\\Lib\\site-packages\\torch\\nn\\modules\\module.py", line 2015, in _load_from_state_dict\n    input_param = input_param[0]\n                  ~~~~~~~~~~~^^^\nIndexError: index 0 is out of bounds for dimension 0 with size 0\n',)

[2024-02-17 17:38:53,122][flwr][ERROR] - [36mray::DefaultActor.run()[39m (pid=7276, ip=127.0.0.1, actor_id=2b56f33712a0c96a8e8982de01000000, repr=<flwr.simulation.ray_transport.ray_actor.DefaultActor object at 0x0000019069371690>)
                  ^^^^^^^^^^^^^^
  File "C:\Users\Stavros\miniconda3\envs\pyt_pg\Lib\site-packages\flwr\simulation\ray_transport\ray_client_proxy.py", line 207, in fit
    return maybe_call_fit(
           ^^^^^^^^^^^^^^^
  File "C:\Users\Stavros\miniconda3\envs\pyt_pg\Lib\site-packages\flwr\client\client.py", line 234, in maybe_call_fit
    return client.fit(fit_ins)
           ^^^^^^^^^^^^^^^^^^^
  File "C:\Users\Stavros\miniconda3\envs\pyt_pg\Lib\site-packages\flwr\client\numpy_client.py", line 238, in _fit
    results = self.numpy_client.fit(parameters, ins.config)  # type: ignore
              ^^^^^^^^^^^^^^^^^^^^^^^^^^^^^^^^^^^^^^^^^^^^^
  File "C:\Users\Stavros\Desktop\PythonProjects\FlowerYtTut\client_scaffold.py", line 67, in fit
    self.set_parameters(parameters)
  File "C:\Users\Stavros\Desktop\PythonProjects\FlowerYtTut\client_scaffold.py", line 52, in set_parameters
    self.model.load_state_dict(state_dict, strict=True)
  File "C:\Users\Stavros\miniconda3\envs\pyt_pg\Lib\site-packages\torch\nn\modules\module.py", line 2138, in load_state_dict
    load(self, state_dict)
  File "C:\Users\Stavros\miniconda3\envs\pyt_pg\Lib\site-packages\torch\nn\modules\module.py", line 2126, in load
    load(child, child_state_dict, child_prefix)
  File "C:\Users\Stavros\miniconda3\envs\pyt_pg\Lib\site-packages\torch\nn\modules\module.py", line 2126, in load
    load(child, child_state_dict, child_prefix)
  File "C:\Users\Stavros\miniconda3\envs\pyt_pg\Lib\site-packages\torch\nn\modules\module.py", line 2120, in load
    module._load_from_state_dict(
  File "C:\Users\Stavros\miniconda3\envs\pyt_pg\Lib\site-packages\torch\nn\modules\batchnorm.py", line 110, in _load_from_state_dict
    super()._load_from_state_dict(
  File "C:\Users\Stavros\miniconda3\envs\pyt_pg\Lib\site-packages\torch\nn\modules\module.py", line 2015, in _load_from_state_dict
    input_param = input_param[0]
                  ~~~~~~~~~~~^^^
IndexError: index 0 is out of bounds for dimension 0 with size 0

The above exception was the direct cause of the following exception:

[36mray::DefaultActor.run()[39m (pid=7276, ip=127.0.0.1, actor_id=2b56f33712a0c96a8e8982de01000000, repr=<flwr.simulation.ray_transport.ray_actor.DefaultActor object at 0x0000019069371690>)
  File "python\ray\_raylet.pyx", line 1418, in ray._raylet.execute_task
  File "python\ray\_raylet.pyx", line 1498, in ray._raylet.execute_task
  File "python\ray\_raylet.pyx", line 1424, in ray._raylet.execute_task
  File "python\ray\_raylet.pyx", line 1364, in ray._raylet.execute_task.function_executor
  File "C:\Users\Stavros\miniconda3\envs\pyt_pg\Lib\site-packages\ray\_private\function_manager.py", line 726, in actor_method_executor
    return method(__ray_actor, *args, **kwargs)
           ^^^^^^^^^^^^^^^^^^^^^^^^^^^^^^^^^^^^
  File "C:\Users\Stavros\miniconda3\envs\pyt_pg\Lib\site-packages\ray\util\tracing\tracing_helper.py", line 464, in _resume_span
    return method(self, *_args, **_kwargs)
           ^^^^^^^^^^^^^^^^^^^^^^^^^^^^^^^
  File "C:\Users\Stavros\miniconda3\envs\pyt_pg\Lib\site-packages\flwr\simulation\ray_transport\ray_actor.py", line 90, in run
    raise ClientException(str(message)) from ex
flwr.simulation.ray_transport.ray_actor.ClientException: 
>>>>>>>A ClientException occurred.('\n\tSomething went wrong when running your client run.\n\tClient 68 crashed when the DefaultActor was running its run.\n\tException triggered on the client side: Traceback (most recent call last):\n  File "C:\\Users\\Stavros\\miniconda3\\envs\\pyt_pg\\Lib\\site-packages\\flwr\\simulation\\ray_transport\\ray_actor.py", line 76, in run\n    job_results = job_fn(client)\n                  ^^^^^^^^^^^^^^\n  File "C:\\Users\\Stavros\\miniconda3\\envs\\pyt_pg\\Lib\\site-packages\\flwr\\simulation\\ray_transport\\ray_client_proxy.py", line 207, in fit\n    return maybe_call_fit(\n           ^^^^^^^^^^^^^^^\n  File "C:\\Users\\Stavros\\miniconda3\\envs\\pyt_pg\\Lib\\site-packages\\flwr\\client\\client.py", line 234, in maybe_call_fit\n    return client.fit(fit_ins)\n           ^^^^^^^^^^^^^^^^^^^\n  File "C:\\Users\\Stavros\\miniconda3\\envs\\pyt_pg\\Lib\\site-packages\\flwr\\client\\numpy_client.py", line 238, in _fit\n    results = self.numpy_client.fit(parameters, ins.config)  # type: ignore\n              ^^^^^^^^^^^^^^^^^^^^^^^^^^^^^^^^^^^^^^^^^^^^^\n  File "C:\\Users\\Stavros\\Desktop\\PythonProjects\\FlowerYtTut\\client_scaffold.py", line 67, in fit\n    self.set_parameters(parameters)\n  File "C:\\Users\\Stavros\\Desktop\\PythonProjects\\FlowerYtTut\\client_scaffold.py", line 52, in set_parameters\n    self.model.load_state_dict(state_dict, strict=True)\n  File "C:\\Users\\Stavros\\miniconda3\\envs\\pyt_pg\\Lib\\site-packages\\torch\\nn\\modules\\module.py", line 2138, in load_state_dict\n    load(self, state_dict)\n  File "C:\\Users\\Stavros\\miniconda3\\envs\\pyt_pg\\Lib\\site-packages\\torch\\nn\\modules\\module.py", line 2126, in load\n    load(child, child_state_dict, child_prefix)\n  File "C:\\Users\\Stavros\\miniconda3\\envs\\pyt_pg\\Lib\\site-packages\\torch\\nn\\modules\\module.py", line 2126, in load\n    load(child, child_state_dict, child_prefix)\n  File "C:\\Users\\Stavros\\miniconda3\\envs\\pyt_pg\\Lib\\site-packages\\torch\\nn\\modules\\module.py", line 2120, in load\n    module._load_from_state_dict(\n  File "C:\\Users\\Stavros\\miniconda3\\envs\\pyt_pg\\Lib\\site-packages\\torch\\nn\\modules\\batchnorm.py", line 110, in _load_from_state_dict\n    super()._load_from_state_dict(\n  File "C:\\Users\\Stavros\\miniconda3\\envs\\pyt_pg\\Lib\\site-packages\\torch\\nn\\modules\\module.py", line 2015, in _load_from_state_dict\n    input_param = input_param[0]\n                  ~~~~~~~~~~~^^^\nIndexError: index 0 is out of bounds for dimension 0 with size 0\n',)
[2024-02-17 17:38:55,178][flwr][ERROR] - Traceback (most recent call last):
  File "C:\Users\Stavros\miniconda3\envs\pyt_pg\Lib\site-packages\flwr\simulation\ray_transport\ray_client_proxy.py", line 151, in _submit_job
    res, updated_context = self.actor_pool.get_client_result(self.cid, timeout)
                           ^^^^^^^^^^^^^^^^^^^^^^^^^^^^^^^^^^^^^^^^^^^^^^^^^^^^
  File "C:\Users\Stavros\miniconda3\envs\pyt_pg\Lib\site-packages\flwr\simulation\ray_transport\ray_actor.py", line 425, in get_client_result
    return self._fetch_future_result(cid)
           ^^^^^^^^^^^^^^^^^^^^^^^^^^^^^^
  File "C:\Users\Stavros\miniconda3\envs\pyt_pg\Lib\site-packages\flwr\simulation\ray_transport\ray_actor.py", line 306, in _fetch_future_result
    res_cid, res, updated_context = ray.get(
                                    ^^^^^^^^
  File "C:\Users\Stavros\miniconda3\envs\pyt_pg\Lib\site-packages\ray\_private\auto_init_hook.py", line 24, in auto_init_wrapper
    return fn(*args, **kwargs)
           ^^^^^^^^^^^^^^^^^^^
  File "C:\Users\Stavros\miniconda3\envs\pyt_pg\Lib\site-packages\ray\_private\client_mode_hook.py", line 103, in wrapper
    return func(*args, **kwargs)
           ^^^^^^^^^^^^^^^^^^^^^
  File "C:\Users\Stavros\miniconda3\envs\pyt_pg\Lib\site-packages\ray\_private\worker.py", line 2524, in get
    raise value.as_instanceof_cause()
ray.exceptions.RayTaskError(ClientException): [36mray::DefaultActor.run()[39m (pid=7276, ip=127.0.0.1, actor_id=2b56f33712a0c96a8e8982de01000000, repr=<flwr.simulation.ray_transport.ray_actor.DefaultActor object at 0x0000019069371690>)
                  ^^^^^^^^^^^^^^
  File "C:\Users\Stavros\miniconda3\envs\pyt_pg\Lib\site-packages\flwr\simulation\ray_transport\ray_client_proxy.py", line 207, in fit
    return maybe_call_fit(
           ^^^^^^^^^^^^^^^
  File "C:\Users\Stavros\miniconda3\envs\pyt_pg\Lib\site-packages\flwr\client\client.py", line 234, in maybe_call_fit
    return client.fit(fit_ins)
           ^^^^^^^^^^^^^^^^^^^
  File "C:\Users\Stavros\miniconda3\envs\pyt_pg\Lib\site-packages\flwr\client\numpy_client.py", line 238, in _fit
    results = self.numpy_client.fit(parameters, ins.config)  # type: ignore
              ^^^^^^^^^^^^^^^^^^^^^^^^^^^^^^^^^^^^^^^^^^^^^
  File "C:\Users\Stavros\Desktop\PythonProjects\FlowerYtTut\client_scaffold.py", line 67, in fit
    self.set_parameters(parameters)
  File "C:\Users\Stavros\Desktop\PythonProjects\FlowerYtTut\client_scaffold.py", line 52, in set_parameters
    self.model.load_state_dict(state_dict, strict=True)
  File "C:\Users\Stavros\miniconda3\envs\pyt_pg\Lib\site-packages\torch\nn\modules\module.py", line 2138, in load_state_dict
    load(self, state_dict)
  File "C:\Users\Stavros\miniconda3\envs\pyt_pg\Lib\site-packages\torch\nn\modules\module.py", line 2126, in load
    load(child, child_state_dict, child_prefix)
  File "C:\Users\Stavros\miniconda3\envs\pyt_pg\Lib\site-packages\torch\nn\modules\module.py", line 2126, in load
    load(child, child_state_dict, child_prefix)
  File "C:\Users\Stavros\miniconda3\envs\pyt_pg\Lib\site-packages\torch\nn\modules\module.py", line 2120, in load
    module._load_from_state_dict(
  File "C:\Users\Stavros\miniconda3\envs\pyt_pg\Lib\site-packages\torch\nn\modules\batchnorm.py", line 110, in _load_from_state_dict
    super()._load_from_state_dict(
  File "C:\Users\Stavros\miniconda3\envs\pyt_pg\Lib\site-packages\torch\nn\modules\module.py", line 2015, in _load_from_state_dict
    input_param = input_param[0]
                  ~~~~~~~~~~~^^^
IndexError: index 0 is out of bounds for dimension 0 with size 0

The above exception was the direct cause of the following exception:

[36mray::DefaultActor.run()[39m (pid=7276, ip=127.0.0.1, actor_id=2b56f33712a0c96a8e8982de01000000, repr=<flwr.simulation.ray_transport.ray_actor.DefaultActor object at 0x0000019069371690>)
  File "python\ray\_raylet.pyx", line 1418, in ray._raylet.execute_task
  File "python\ray\_raylet.pyx", line 1498, in ray._raylet.execute_task
  File "python\ray\_raylet.pyx", line 1424, in ray._raylet.execute_task
  File "python\ray\_raylet.pyx", line 1364, in ray._raylet.execute_task.function_executor
  File "C:\Users\Stavros\miniconda3\envs\pyt_pg\Lib\site-packages\ray\_private\function_manager.py", line 726, in actor_method_executor
    return method(__ray_actor, *args, **kwargs)
           ^^^^^^^^^^^^^^^^^^^^^^^^^^^^^^^^^^^^
  File "C:\Users\Stavros\miniconda3\envs\pyt_pg\Lib\site-packages\ray\util\tracing\tracing_helper.py", line 464, in _resume_span
    return method(self, *_args, **_kwargs)
           ^^^^^^^^^^^^^^^^^^^^^^^^^^^^^^^
  File "C:\Users\Stavros\miniconda3\envs\pyt_pg\Lib\site-packages\flwr\simulation\ray_transport\ray_actor.py", line 90, in run
    raise ClientException(str(message)) from ex
flwr.simulation.ray_transport.ray_actor.ClientException: 
>>>>>>>A ClientException occurred.('\n\tSomething went wrong when running your client run.\n\tClient 40 crashed when the DefaultActor was running its run.\n\tException triggered on the client side: Traceback (most recent call last):\n  File "C:\\Users\\Stavros\\miniconda3\\envs\\pyt_pg\\Lib\\site-packages\\flwr\\simulation\\ray_transport\\ray_actor.py", line 76, in run\n    job_results = job_fn(client)\n                  ^^^^^^^^^^^^^^\n  File "C:\\Users\\Stavros\\miniconda3\\envs\\pyt_pg\\Lib\\site-packages\\flwr\\simulation\\ray_transport\\ray_client_proxy.py", line 207, in fit\n    return maybe_call_fit(\n           ^^^^^^^^^^^^^^^\n  File "C:\\Users\\Stavros\\miniconda3\\envs\\pyt_pg\\Lib\\site-packages\\flwr\\client\\client.py", line 234, in maybe_call_fit\n    return client.fit(fit_ins)\n           ^^^^^^^^^^^^^^^^^^^\n  File "C:\\Users\\Stavros\\miniconda3\\envs\\pyt_pg\\Lib\\site-packages\\flwr\\client\\numpy_client.py", line 238, in _fit\n    results = self.numpy_client.fit(parameters, ins.config)  # type: ignore\n              ^^^^^^^^^^^^^^^^^^^^^^^^^^^^^^^^^^^^^^^^^^^^^\n  File "C:\\Users\\Stavros\\Desktop\\PythonProjects\\FlowerYtTut\\client_scaffold.py", line 67, in fit\n    self.set_parameters(parameters)\n  File "C:\\Users\\Stavros\\Desktop\\PythonProjects\\FlowerYtTut\\client_scaffold.py", line 52, in set_parameters\n    self.model.load_state_dict(state_dict, strict=True)\n  File "C:\\Users\\Stavros\\miniconda3\\envs\\pyt_pg\\Lib\\site-packages\\torch\\nn\\modules\\module.py", line 2138, in load_state_dict\n    load(self, state_dict)\n  File "C:\\Users\\Stavros\\miniconda3\\envs\\pyt_pg\\Lib\\site-packages\\torch\\nn\\modules\\module.py", line 2126, in load\n    load(child, child_state_dict, child_prefix)\n  File "C:\\Users\\Stavros\\miniconda3\\envs\\pyt_pg\\Lib\\site-packages\\torch\\nn\\modules\\module.py", line 2126, in load\n    load(child, child_state_dict, child_prefix)\n  File "C:\\Users\\Stavros\\miniconda3\\envs\\pyt_pg\\Lib\\site-packages\\torch\\nn\\modules\\module.py", line 2120, in load\n    module._load_from_state_dict(\n  File "C:\\Users\\Stavros\\miniconda3\\envs\\pyt_pg\\Lib\\site-packages\\torch\\nn\\modules\\batchnorm.py", line 110, in _load_from_state_dict\n    super()._load_from_state_dict(\n  File "C:\\Users\\Stavros\\miniconda3\\envs\\pyt_pg\\Lib\\site-packages\\torch\\nn\\modules\\module.py", line 2015, in _load_from_state_dict\n    input_param = input_param[0]\n                  ~~~~~~~~~~~^^^\nIndexError: index 0 is out of bounds for dimension 0 with size 0\n',)

[2024-02-17 17:38:55,190][flwr][ERROR] - [36mray::DefaultActor.run()[39m (pid=7276, ip=127.0.0.1, actor_id=2b56f33712a0c96a8e8982de01000000, repr=<flwr.simulation.ray_transport.ray_actor.DefaultActor object at 0x0000019069371690>)
                  ^^^^^^^^^^^^^^
  File "C:\Users\Stavros\miniconda3\envs\pyt_pg\Lib\site-packages\flwr\simulation\ray_transport\ray_client_proxy.py", line 207, in fit
    return maybe_call_fit(
           ^^^^^^^^^^^^^^^
  File "C:\Users\Stavros\miniconda3\envs\pyt_pg\Lib\site-packages\flwr\client\client.py", line 234, in maybe_call_fit
    return client.fit(fit_ins)
           ^^^^^^^^^^^^^^^^^^^
  File "C:\Users\Stavros\miniconda3\envs\pyt_pg\Lib\site-packages\flwr\client\numpy_client.py", line 238, in _fit
    results = self.numpy_client.fit(parameters, ins.config)  # type: ignore
              ^^^^^^^^^^^^^^^^^^^^^^^^^^^^^^^^^^^^^^^^^^^^^
  File "C:\Users\Stavros\Desktop\PythonProjects\FlowerYtTut\client_scaffold.py", line 67, in fit
    self.set_parameters(parameters)
  File "C:\Users\Stavros\Desktop\PythonProjects\FlowerYtTut\client_scaffold.py", line 52, in set_parameters
    self.model.load_state_dict(state_dict, strict=True)
  File "C:\Users\Stavros\miniconda3\envs\pyt_pg\Lib\site-packages\torch\nn\modules\module.py", line 2138, in load_state_dict
    load(self, state_dict)
  File "C:\Users\Stavros\miniconda3\envs\pyt_pg\Lib\site-packages\torch\nn\modules\module.py", line 2126, in load
    load(child, child_state_dict, child_prefix)
  File "C:\Users\Stavros\miniconda3\envs\pyt_pg\Lib\site-packages\torch\nn\modules\module.py", line 2126, in load
    load(child, child_state_dict, child_prefix)
  File "C:\Users\Stavros\miniconda3\envs\pyt_pg\Lib\site-packages\torch\nn\modules\module.py", line 2120, in load
    module._load_from_state_dict(
  File "C:\Users\Stavros\miniconda3\envs\pyt_pg\Lib\site-packages\torch\nn\modules\batchnorm.py", line 110, in _load_from_state_dict
    super()._load_from_state_dict(
  File "C:\Users\Stavros\miniconda3\envs\pyt_pg\Lib\site-packages\torch\nn\modules\module.py", line 2015, in _load_from_state_dict
    input_param = input_param[0]
                  ~~~~~~~~~~~^^^
IndexError: index 0 is out of bounds for dimension 0 with size 0

The above exception was the direct cause of the following exception:

[36mray::DefaultActor.run()[39m (pid=7276, ip=127.0.0.1, actor_id=2b56f33712a0c96a8e8982de01000000, repr=<flwr.simulation.ray_transport.ray_actor.DefaultActor object at 0x0000019069371690>)
  File "python\ray\_raylet.pyx", line 1418, in ray._raylet.execute_task
  File "python\ray\_raylet.pyx", line 1498, in ray._raylet.execute_task
  File "python\ray\_raylet.pyx", line 1424, in ray._raylet.execute_task
  File "python\ray\_raylet.pyx", line 1364, in ray._raylet.execute_task.function_executor
  File "C:\Users\Stavros\miniconda3\envs\pyt_pg\Lib\site-packages\ray\_private\function_manager.py", line 726, in actor_method_executor
    return method(__ray_actor, *args, **kwargs)
           ^^^^^^^^^^^^^^^^^^^^^^^^^^^^^^^^^^^^
  File "C:\Users\Stavros\miniconda3\envs\pyt_pg\Lib\site-packages\ray\util\tracing\tracing_helper.py", line 464, in _resume_span
    return method(self, *_args, **_kwargs)
           ^^^^^^^^^^^^^^^^^^^^^^^^^^^^^^^
  File "C:\Users\Stavros\miniconda3\envs\pyt_pg\Lib\site-packages\flwr\simulation\ray_transport\ray_actor.py", line 90, in run
    raise ClientException(str(message)) from ex
flwr.simulation.ray_transport.ray_actor.ClientException: 
>>>>>>>A ClientException occurred.('\n\tSomething went wrong when running your client run.\n\tClient 40 crashed when the DefaultActor was running its run.\n\tException triggered on the client side: Traceback (most recent call last):\n  File "C:\\Users\\Stavros\\miniconda3\\envs\\pyt_pg\\Lib\\site-packages\\flwr\\simulation\\ray_transport\\ray_actor.py", line 76, in run\n    job_results = job_fn(client)\n                  ^^^^^^^^^^^^^^\n  File "C:\\Users\\Stavros\\miniconda3\\envs\\pyt_pg\\Lib\\site-packages\\flwr\\simulation\\ray_transport\\ray_client_proxy.py", line 207, in fit\n    return maybe_call_fit(\n           ^^^^^^^^^^^^^^^\n  File "C:\\Users\\Stavros\\miniconda3\\envs\\pyt_pg\\Lib\\site-packages\\flwr\\client\\client.py", line 234, in maybe_call_fit\n    return client.fit(fit_ins)\n           ^^^^^^^^^^^^^^^^^^^\n  File "C:\\Users\\Stavros\\miniconda3\\envs\\pyt_pg\\Lib\\site-packages\\flwr\\client\\numpy_client.py", line 238, in _fit\n    results = self.numpy_client.fit(parameters, ins.config)  # type: ignore\n              ^^^^^^^^^^^^^^^^^^^^^^^^^^^^^^^^^^^^^^^^^^^^^\n  File "C:\\Users\\Stavros\\Desktop\\PythonProjects\\FlowerYtTut\\client_scaffold.py", line 67, in fit\n    self.set_parameters(parameters)\n  File "C:\\Users\\Stavros\\Desktop\\PythonProjects\\FlowerYtTut\\client_scaffold.py", line 52, in set_parameters\n    self.model.load_state_dict(state_dict, strict=True)\n  File "C:\\Users\\Stavros\\miniconda3\\envs\\pyt_pg\\Lib\\site-packages\\torch\\nn\\modules\\module.py", line 2138, in load_state_dict\n    load(self, state_dict)\n  File "C:\\Users\\Stavros\\miniconda3\\envs\\pyt_pg\\Lib\\site-packages\\torch\\nn\\modules\\module.py", line 2126, in load\n    load(child, child_state_dict, child_prefix)\n  File "C:\\Users\\Stavros\\miniconda3\\envs\\pyt_pg\\Lib\\site-packages\\torch\\nn\\modules\\module.py", line 2126, in load\n    load(child, child_state_dict, child_prefix)\n  File "C:\\Users\\Stavros\\miniconda3\\envs\\pyt_pg\\Lib\\site-packages\\torch\\nn\\modules\\module.py", line 2120, in load\n    module._load_from_state_dict(\n  File "C:\\Users\\Stavros\\miniconda3\\envs\\pyt_pg\\Lib\\site-packages\\torch\\nn\\modules\\batchnorm.py", line 110, in _load_from_state_dict\n    super()._load_from_state_dict(\n  File "C:\\Users\\Stavros\\miniconda3\\envs\\pyt_pg\\Lib\\site-packages\\torch\\nn\\modules\\module.py", line 2015, in _load_from_state_dict\n    input_param = input_param[0]\n                  ~~~~~~~~~~~^^^\nIndexError: index 0 is out of bounds for dimension 0 with size 0\n',)
[2024-02-17 17:38:57,158][flwr][ERROR] - Traceback (most recent call last):
  File "C:\Users\Stavros\miniconda3\envs\pyt_pg\Lib\site-packages\flwr\simulation\ray_transport\ray_client_proxy.py", line 151, in _submit_job
    res, updated_context = self.actor_pool.get_client_result(self.cid, timeout)
                           ^^^^^^^^^^^^^^^^^^^^^^^^^^^^^^^^^^^^^^^^^^^^^^^^^^^^
  File "C:\Users\Stavros\miniconda3\envs\pyt_pg\Lib\site-packages\flwr\simulation\ray_transport\ray_actor.py", line 425, in get_client_result
    return self._fetch_future_result(cid)
           ^^^^^^^^^^^^^^^^^^^^^^^^^^^^^^
  File "C:\Users\Stavros\miniconda3\envs\pyt_pg\Lib\site-packages\flwr\simulation\ray_transport\ray_actor.py", line 306, in _fetch_future_result
    res_cid, res, updated_context = ray.get(
                                    ^^^^^^^^
  File "C:\Users\Stavros\miniconda3\envs\pyt_pg\Lib\site-packages\ray\_private\auto_init_hook.py", line 24, in auto_init_wrapper
    return fn(*args, **kwargs)
           ^^^^^^^^^^^^^^^^^^^
  File "C:\Users\Stavros\miniconda3\envs\pyt_pg\Lib\site-packages\ray\_private\client_mode_hook.py", line 103, in wrapper
    return func(*args, **kwargs)
           ^^^^^^^^^^^^^^^^^^^^^
  File "C:\Users\Stavros\miniconda3\envs\pyt_pg\Lib\site-packages\ray\_private\worker.py", line 2524, in get
    raise value.as_instanceof_cause()
ray.exceptions.RayTaskError(ClientException): [36mray::DefaultActor.run()[39m (pid=7276, ip=127.0.0.1, actor_id=2b56f33712a0c96a8e8982de01000000, repr=<flwr.simulation.ray_transport.ray_actor.DefaultActor object at 0x0000019069371690>)
                  ^^^^^^^^^^^^^^
  File "C:\Users\Stavros\miniconda3\envs\pyt_pg\Lib\site-packages\flwr\simulation\ray_transport\ray_client_proxy.py", line 207, in fit
    return maybe_call_fit(
           ^^^^^^^^^^^^^^^
  File "C:\Users\Stavros\miniconda3\envs\pyt_pg\Lib\site-packages\flwr\client\client.py", line 234, in maybe_call_fit
    return client.fit(fit_ins)
           ^^^^^^^^^^^^^^^^^^^
  File "C:\Users\Stavros\miniconda3\envs\pyt_pg\Lib\site-packages\flwr\client\numpy_client.py", line 238, in _fit
    results = self.numpy_client.fit(parameters, ins.config)  # type: ignore
              ^^^^^^^^^^^^^^^^^^^^^^^^^^^^^^^^^^^^^^^^^^^^^
  File "C:\Users\Stavros\Desktop\PythonProjects\FlowerYtTut\client_scaffold.py", line 67, in fit
    self.set_parameters(parameters)
  File "C:\Users\Stavros\Desktop\PythonProjects\FlowerYtTut\client_scaffold.py", line 52, in set_parameters
    self.model.load_state_dict(state_dict, strict=True)
  File "C:\Users\Stavros\miniconda3\envs\pyt_pg\Lib\site-packages\torch\nn\modules\module.py", line 2138, in load_state_dict
    load(self, state_dict)
  File "C:\Users\Stavros\miniconda3\envs\pyt_pg\Lib\site-packages\torch\nn\modules\module.py", line 2126, in load
    load(child, child_state_dict, child_prefix)
  File "C:\Users\Stavros\miniconda3\envs\pyt_pg\Lib\site-packages\torch\nn\modules\module.py", line 2126, in load
    load(child, child_state_dict, child_prefix)
  File "C:\Users\Stavros\miniconda3\envs\pyt_pg\Lib\site-packages\torch\nn\modules\module.py", line 2120, in load
    module._load_from_state_dict(
  File "C:\Users\Stavros\miniconda3\envs\pyt_pg\Lib\site-packages\torch\nn\modules\batchnorm.py", line 110, in _load_from_state_dict
    super()._load_from_state_dict(
  File "C:\Users\Stavros\miniconda3\envs\pyt_pg\Lib\site-packages\torch\nn\modules\module.py", line 2015, in _load_from_state_dict
    input_param = input_param[0]
                  ~~~~~~~~~~~^^^
IndexError: index 0 is out of bounds for dimension 0 with size 0

The above exception was the direct cause of the following exception:

[36mray::DefaultActor.run()[39m (pid=7276, ip=127.0.0.1, actor_id=2b56f33712a0c96a8e8982de01000000, repr=<flwr.simulation.ray_transport.ray_actor.DefaultActor object at 0x0000019069371690>)
  File "python\ray\_raylet.pyx", line 1418, in ray._raylet.execute_task
  File "python\ray\_raylet.pyx", line 1498, in ray._raylet.execute_task
  File "python\ray\_raylet.pyx", line 1424, in ray._raylet.execute_task
  File "python\ray\_raylet.pyx", line 1364, in ray._raylet.execute_task.function_executor
  File "C:\Users\Stavros\miniconda3\envs\pyt_pg\Lib\site-packages\ray\_private\function_manager.py", line 726, in actor_method_executor
    return method(__ray_actor, *args, **kwargs)
           ^^^^^^^^^^^^^^^^^^^^^^^^^^^^^^^^^^^^
  File "C:\Users\Stavros\miniconda3\envs\pyt_pg\Lib\site-packages\ray\util\tracing\tracing_helper.py", line 464, in _resume_span
    return method(self, *_args, **_kwargs)
           ^^^^^^^^^^^^^^^^^^^^^^^^^^^^^^^
  File "C:\Users\Stavros\miniconda3\envs\pyt_pg\Lib\site-packages\flwr\simulation\ray_transport\ray_actor.py", line 90, in run
    raise ClientException(str(message)) from ex
flwr.simulation.ray_transport.ray_actor.ClientException: 
>>>>>>>A ClientException occurred.('\n\tSomething went wrong when running your client run.\n\tClient 75 crashed when the DefaultActor was running its run.\n\tException triggered on the client side: Traceback (most recent call last):\n  File "C:\\Users\\Stavros\\miniconda3\\envs\\pyt_pg\\Lib\\site-packages\\flwr\\simulation\\ray_transport\\ray_actor.py", line 76, in run\n    job_results = job_fn(client)\n                  ^^^^^^^^^^^^^^\n  File "C:\\Users\\Stavros\\miniconda3\\envs\\pyt_pg\\Lib\\site-packages\\flwr\\simulation\\ray_transport\\ray_client_proxy.py", line 207, in fit\n    return maybe_call_fit(\n           ^^^^^^^^^^^^^^^\n  File "C:\\Users\\Stavros\\miniconda3\\envs\\pyt_pg\\Lib\\site-packages\\flwr\\client\\client.py", line 234, in maybe_call_fit\n    return client.fit(fit_ins)\n           ^^^^^^^^^^^^^^^^^^^\n  File "C:\\Users\\Stavros\\miniconda3\\envs\\pyt_pg\\Lib\\site-packages\\flwr\\client\\numpy_client.py", line 238, in _fit\n    results = self.numpy_client.fit(parameters, ins.config)  # type: ignore\n              ^^^^^^^^^^^^^^^^^^^^^^^^^^^^^^^^^^^^^^^^^^^^^\n  File "C:\\Users\\Stavros\\Desktop\\PythonProjects\\FlowerYtTut\\client_scaffold.py", line 67, in fit\n    self.set_parameters(parameters)\n  File "C:\\Users\\Stavros\\Desktop\\PythonProjects\\FlowerYtTut\\client_scaffold.py", line 52, in set_parameters\n    self.model.load_state_dict(state_dict, strict=True)\n  File "C:\\Users\\Stavros\\miniconda3\\envs\\pyt_pg\\Lib\\site-packages\\torch\\nn\\modules\\module.py", line 2138, in load_state_dict\n    load(self, state_dict)\n  File "C:\\Users\\Stavros\\miniconda3\\envs\\pyt_pg\\Lib\\site-packages\\torch\\nn\\modules\\module.py", line 2126, in load\n    load(child, child_state_dict, child_prefix)\n  File "C:\\Users\\Stavros\\miniconda3\\envs\\pyt_pg\\Lib\\site-packages\\torch\\nn\\modules\\module.py", line 2126, in load\n    load(child, child_state_dict, child_prefix)\n  File "C:\\Users\\Stavros\\miniconda3\\envs\\pyt_pg\\Lib\\site-packages\\torch\\nn\\modules\\module.py", line 2120, in load\n    module._load_from_state_dict(\n  File "C:\\Users\\Stavros\\miniconda3\\envs\\pyt_pg\\Lib\\site-packages\\torch\\nn\\modules\\batchnorm.py", line 110, in _load_from_state_dict\n    super()._load_from_state_dict(\n  File "C:\\Users\\Stavros\\miniconda3\\envs\\pyt_pg\\Lib\\site-packages\\torch\\nn\\modules\\module.py", line 2015, in _load_from_state_dict\n    input_param = input_param[0]\n                  ~~~~~~~~~~~^^^\nIndexError: index 0 is out of bounds for dimension 0 with size 0\n',)

[2024-02-17 17:38:57,180][flwr][ERROR] - [36mray::DefaultActor.run()[39m (pid=7276, ip=127.0.0.1, actor_id=2b56f33712a0c96a8e8982de01000000, repr=<flwr.simulation.ray_transport.ray_actor.DefaultActor object at 0x0000019069371690>)
                  ^^^^^^^^^^^^^^
  File "C:\Users\Stavros\miniconda3\envs\pyt_pg\Lib\site-packages\flwr\simulation\ray_transport\ray_client_proxy.py", line 207, in fit
    return maybe_call_fit(
           ^^^^^^^^^^^^^^^
  File "C:\Users\Stavros\miniconda3\envs\pyt_pg\Lib\site-packages\flwr\client\client.py", line 234, in maybe_call_fit
    return client.fit(fit_ins)
           ^^^^^^^^^^^^^^^^^^^
  File "C:\Users\Stavros\miniconda3\envs\pyt_pg\Lib\site-packages\flwr\client\numpy_client.py", line 238, in _fit
    results = self.numpy_client.fit(parameters, ins.config)  # type: ignore
              ^^^^^^^^^^^^^^^^^^^^^^^^^^^^^^^^^^^^^^^^^^^^^
  File "C:\Users\Stavros\Desktop\PythonProjects\FlowerYtTut\client_scaffold.py", line 67, in fit
    self.set_parameters(parameters)
  File "C:\Users\Stavros\Desktop\PythonProjects\FlowerYtTut\client_scaffold.py", line 52, in set_parameters
    self.model.load_state_dict(state_dict, strict=True)
  File "C:\Users\Stavros\miniconda3\envs\pyt_pg\Lib\site-packages\torch\nn\modules\module.py", line 2138, in load_state_dict
    load(self, state_dict)
  File "C:\Users\Stavros\miniconda3\envs\pyt_pg\Lib\site-packages\torch\nn\modules\module.py", line 2126, in load
    load(child, child_state_dict, child_prefix)
  File "C:\Users\Stavros\miniconda3\envs\pyt_pg\Lib\site-packages\torch\nn\modules\module.py", line 2126, in load
    load(child, child_state_dict, child_prefix)
  File "C:\Users\Stavros\miniconda3\envs\pyt_pg\Lib\site-packages\torch\nn\modules\module.py", line 2120, in load
    module._load_from_state_dict(
  File "C:\Users\Stavros\miniconda3\envs\pyt_pg\Lib\site-packages\torch\nn\modules\batchnorm.py", line 110, in _load_from_state_dict
    super()._load_from_state_dict(
  File "C:\Users\Stavros\miniconda3\envs\pyt_pg\Lib\site-packages\torch\nn\modules\module.py", line 2015, in _load_from_state_dict
    input_param = input_param[0]
                  ~~~~~~~~~~~^^^
IndexError: index 0 is out of bounds for dimension 0 with size 0

The above exception was the direct cause of the following exception:

[36mray::DefaultActor.run()[39m (pid=7276, ip=127.0.0.1, actor_id=2b56f33712a0c96a8e8982de01000000, repr=<flwr.simulation.ray_transport.ray_actor.DefaultActor object at 0x0000019069371690>)
  File "python\ray\_raylet.pyx", line 1418, in ray._raylet.execute_task
  File "python\ray\_raylet.pyx", line 1498, in ray._raylet.execute_task
  File "python\ray\_raylet.pyx", line 1424, in ray._raylet.execute_task
  File "python\ray\_raylet.pyx", line 1364, in ray._raylet.execute_task.function_executor
  File "C:\Users\Stavros\miniconda3\envs\pyt_pg\Lib\site-packages\ray\_private\function_manager.py", line 726, in actor_method_executor
    return method(__ray_actor, *args, **kwargs)
           ^^^^^^^^^^^^^^^^^^^^^^^^^^^^^^^^^^^^
  File "C:\Users\Stavros\miniconda3\envs\pyt_pg\Lib\site-packages\ray\util\tracing\tracing_helper.py", line 464, in _resume_span
    return method(self, *_args, **_kwargs)
           ^^^^^^^^^^^^^^^^^^^^^^^^^^^^^^^
  File "C:\Users\Stavros\miniconda3\envs\pyt_pg\Lib\site-packages\flwr\simulation\ray_transport\ray_actor.py", line 90, in run
    raise ClientException(str(message)) from ex
flwr.simulation.ray_transport.ray_actor.ClientException: 
>>>>>>>A ClientException occurred.('\n\tSomething went wrong when running your client run.\n\tClient 75 crashed when the DefaultActor was running its run.\n\tException triggered on the client side: Traceback (most recent call last):\n  File "C:\\Users\\Stavros\\miniconda3\\envs\\pyt_pg\\Lib\\site-packages\\flwr\\simulation\\ray_transport\\ray_actor.py", line 76, in run\n    job_results = job_fn(client)\n                  ^^^^^^^^^^^^^^\n  File "C:\\Users\\Stavros\\miniconda3\\envs\\pyt_pg\\Lib\\site-packages\\flwr\\simulation\\ray_transport\\ray_client_proxy.py", line 207, in fit\n    return maybe_call_fit(\n           ^^^^^^^^^^^^^^^\n  File "C:\\Users\\Stavros\\miniconda3\\envs\\pyt_pg\\Lib\\site-packages\\flwr\\client\\client.py", line 234, in maybe_call_fit\n    return client.fit(fit_ins)\n           ^^^^^^^^^^^^^^^^^^^\n  File "C:\\Users\\Stavros\\miniconda3\\envs\\pyt_pg\\Lib\\site-packages\\flwr\\client\\numpy_client.py", line 238, in _fit\n    results = self.numpy_client.fit(parameters, ins.config)  # type: ignore\n              ^^^^^^^^^^^^^^^^^^^^^^^^^^^^^^^^^^^^^^^^^^^^^\n  File "C:\\Users\\Stavros\\Desktop\\PythonProjects\\FlowerYtTut\\client_scaffold.py", line 67, in fit\n    self.set_parameters(parameters)\n  File "C:\\Users\\Stavros\\Desktop\\PythonProjects\\FlowerYtTut\\client_scaffold.py", line 52, in set_parameters\n    self.model.load_state_dict(state_dict, strict=True)\n  File "C:\\Users\\Stavros\\miniconda3\\envs\\pyt_pg\\Lib\\site-packages\\torch\\nn\\modules\\module.py", line 2138, in load_state_dict\n    load(self, state_dict)\n  File "C:\\Users\\Stavros\\miniconda3\\envs\\pyt_pg\\Lib\\site-packages\\torch\\nn\\modules\\module.py", line 2126, in load\n    load(child, child_state_dict, child_prefix)\n  File "C:\\Users\\Stavros\\miniconda3\\envs\\pyt_pg\\Lib\\site-packages\\torch\\nn\\modules\\module.py", line 2126, in load\n    load(child, child_state_dict, child_prefix)\n  File "C:\\Users\\Stavros\\miniconda3\\envs\\pyt_pg\\Lib\\site-packages\\torch\\nn\\modules\\module.py", line 2120, in load\n    module._load_from_state_dict(\n  File "C:\\Users\\Stavros\\miniconda3\\envs\\pyt_pg\\Lib\\site-packages\\torch\\nn\\modules\\batchnorm.py", line 110, in _load_from_state_dict\n    super()._load_from_state_dict(\n  File "C:\\Users\\Stavros\\miniconda3\\envs\\pyt_pg\\Lib\\site-packages\\torch\\nn\\modules\\module.py", line 2015, in _load_from_state_dict\n    input_param = input_param[0]\n                  ~~~~~~~~~~~^^^\nIndexError: index 0 is out of bounds for dimension 0 with size 0\n',)
[2024-02-17 17:38:57,777][flwr][ERROR] - Traceback (most recent call last):
  File "C:\Users\Stavros\miniconda3\envs\pyt_pg\Lib\site-packages\flwr\simulation\ray_transport\ray_client_proxy.py", line 151, in _submit_job
    res, updated_context = self.actor_pool.get_client_result(self.cid, timeout)
                           ^^^^^^^^^^^^^^^^^^^^^^^^^^^^^^^^^^^^^^^^^^^^^^^^^^^^
  File "C:\Users\Stavros\miniconda3\envs\pyt_pg\Lib\site-packages\flwr\simulation\ray_transport\ray_actor.py", line 425, in get_client_result
    return self._fetch_future_result(cid)
           ^^^^^^^^^^^^^^^^^^^^^^^^^^^^^^
  File "C:\Users\Stavros\miniconda3\envs\pyt_pg\Lib\site-packages\flwr\simulation\ray_transport\ray_actor.py", line 306, in _fetch_future_result
    res_cid, res, updated_context = ray.get(
                                    ^^^^^^^^
  File "C:\Users\Stavros\miniconda3\envs\pyt_pg\Lib\site-packages\ray\_private\auto_init_hook.py", line 24, in auto_init_wrapper
    return fn(*args, **kwargs)
           ^^^^^^^^^^^^^^^^^^^
  File "C:\Users\Stavros\miniconda3\envs\pyt_pg\Lib\site-packages\ray\_private\client_mode_hook.py", line 103, in wrapper
    return func(*args, **kwargs)
           ^^^^^^^^^^^^^^^^^^^^^
  File "C:\Users\Stavros\miniconda3\envs\pyt_pg\Lib\site-packages\ray\_private\worker.py", line 2524, in get
    raise value.as_instanceof_cause()
ray.exceptions.RayTaskError(ClientException): [36mray::DefaultActor.run()[39m (pid=1544, ip=127.0.0.1, actor_id=6b72c74b3aa8cd5035cce1c501000000, repr=<flwr.simulation.ray_transport.ray_actor.DefaultActor object at 0x000001F2ED593190>)
                  ^^^^^^^^^^^^^^
  File "C:\Users\Stavros\miniconda3\envs\pyt_pg\Lib\site-packages\flwr\simulation\ray_transport\ray_client_proxy.py", line 207, in fit
    return maybe_call_fit(
           ^^^^^^^^^^^^^^^
  File "C:\Users\Stavros\miniconda3\envs\pyt_pg\Lib\site-packages\flwr\client\client.py", line 234, in maybe_call_fit
    return client.fit(fit_ins)
           ^^^^^^^^^^^^^^^^^^^
  File "C:\Users\Stavros\miniconda3\envs\pyt_pg\Lib\site-packages\flwr\client\numpy_client.py", line 238, in _fit
    results = self.numpy_client.fit(parameters, ins.config)  # type: ignore
              ^^^^^^^^^^^^^^^^^^^^^^^^^^^^^^^^^^^^^^^^^^^^^
  File "C:\Users\Stavros\Desktop\PythonProjects\FlowerYtTut\client_scaffold.py", line 67, in fit
    self.set_parameters(parameters)
  File "C:\Users\Stavros\Desktop\PythonProjects\FlowerYtTut\client_scaffold.py", line 52, in set_parameters
    self.model.load_state_dict(state_dict, strict=True)
  File "C:\Users\Stavros\miniconda3\envs\pyt_pg\Lib\site-packages\torch\nn\modules\module.py", line 2138, in load_state_dict
    load(self, state_dict)
  File "C:\Users\Stavros\miniconda3\envs\pyt_pg\Lib\site-packages\torch\nn\modules\module.py", line 2126, in load
    load(child, child_state_dict, child_prefix)
  File "C:\Users\Stavros\miniconda3\envs\pyt_pg\Lib\site-packages\torch\nn\modules\module.py", line 2126, in load
    load(child, child_state_dict, child_prefix)
  File "C:\Users\Stavros\miniconda3\envs\pyt_pg\Lib\site-packages\torch\nn\modules\module.py", line 2120, in load
    module._load_from_state_dict(
  File "C:\Users\Stavros\miniconda3\envs\pyt_pg\Lib\site-packages\torch\nn\modules\batchnorm.py", line 110, in _load_from_state_dict
    super()._load_from_state_dict(
  File "C:\Users\Stavros\miniconda3\envs\pyt_pg\Lib\site-packages\torch\nn\modules\module.py", line 2015, in _load_from_state_dict
    input_param = input_param[0]
                  ~~~~~~~~~~~^^^
IndexError: index 0 is out of bounds for dimension 0 with size 0

The above exception was the direct cause of the following exception:

[36mray::DefaultActor.run()[39m (pid=1544, ip=127.0.0.1, actor_id=6b72c74b3aa8cd5035cce1c501000000, repr=<flwr.simulation.ray_transport.ray_actor.DefaultActor object at 0x000001F2ED593190>)
  File "python\ray\_raylet.pyx", line 1418, in ray._raylet.execute_task
  File "python\ray\_raylet.pyx", line 1498, in ray._raylet.execute_task
  File "python\ray\_raylet.pyx", line 1424, in ray._raylet.execute_task
  File "python\ray\_raylet.pyx", line 1364, in ray._raylet.execute_task.function_executor
  File "C:\Users\Stavros\miniconda3\envs\pyt_pg\Lib\site-packages\ray\_private\function_manager.py", line 726, in actor_method_executor
    return method(__ray_actor, *args, **kwargs)
           ^^^^^^^^^^^^^^^^^^^^^^^^^^^^^^^^^^^^
  File "C:\Users\Stavros\miniconda3\envs\pyt_pg\Lib\site-packages\ray\util\tracing\tracing_helper.py", line 464, in _resume_span
    return method(self, *_args, **_kwargs)
           ^^^^^^^^^^^^^^^^^^^^^^^^^^^^^^^
  File "C:\Users\Stavros\miniconda3\envs\pyt_pg\Lib\site-packages\flwr\simulation\ray_transport\ray_actor.py", line 90, in run
    raise ClientException(str(message)) from ex
flwr.simulation.ray_transport.ray_actor.ClientException: 
>>>>>>>A ClientException occurred.('\n\tSomething went wrong when running your client run.\n\tClient 30 crashed when the DefaultActor was running its run.\n\tException triggered on the client side: Traceback (most recent call last):\n  File "C:\\Users\\Stavros\\miniconda3\\envs\\pyt_pg\\Lib\\site-packages\\flwr\\simulation\\ray_transport\\ray_actor.py", line 76, in run\n    job_results = job_fn(client)\n                  ^^^^^^^^^^^^^^\n  File "C:\\Users\\Stavros\\miniconda3\\envs\\pyt_pg\\Lib\\site-packages\\flwr\\simulation\\ray_transport\\ray_client_proxy.py", line 207, in fit\n    return maybe_call_fit(\n           ^^^^^^^^^^^^^^^\n  File "C:\\Users\\Stavros\\miniconda3\\envs\\pyt_pg\\Lib\\site-packages\\flwr\\client\\client.py", line 234, in maybe_call_fit\n    return client.fit(fit_ins)\n           ^^^^^^^^^^^^^^^^^^^\n  File "C:\\Users\\Stavros\\miniconda3\\envs\\pyt_pg\\Lib\\site-packages\\flwr\\client\\numpy_client.py", line 238, in _fit\n    results = self.numpy_client.fit(parameters, ins.config)  # type: ignore\n              ^^^^^^^^^^^^^^^^^^^^^^^^^^^^^^^^^^^^^^^^^^^^^\n  File "C:\\Users\\Stavros\\Desktop\\PythonProjects\\FlowerYtTut\\client_scaffold.py", line 67, in fit\n    self.set_parameters(parameters)\n  File "C:\\Users\\Stavros\\Desktop\\PythonProjects\\FlowerYtTut\\client_scaffold.py", line 52, in set_parameters\n    self.model.load_state_dict(state_dict, strict=True)\n  File "C:\\Users\\Stavros\\miniconda3\\envs\\pyt_pg\\Lib\\site-packages\\torch\\nn\\modules\\module.py", line 2138, in load_state_dict\n    load(self, state_dict)\n  File "C:\\Users\\Stavros\\miniconda3\\envs\\pyt_pg\\Lib\\site-packages\\torch\\nn\\modules\\module.py", line 2126, in load\n    load(child, child_state_dict, child_prefix)\n  File "C:\\Users\\Stavros\\miniconda3\\envs\\pyt_pg\\Lib\\site-packages\\torch\\nn\\modules\\module.py", line 2126, in load\n    load(child, child_state_dict, child_prefix)\n  File "C:\\Users\\Stavros\\miniconda3\\envs\\pyt_pg\\Lib\\site-packages\\torch\\nn\\modules\\module.py", line 2120, in load\n    module._load_from_state_dict(\n  File "C:\\Users\\Stavros\\miniconda3\\envs\\pyt_pg\\Lib\\site-packages\\torch\\nn\\modules\\batchnorm.py", line 110, in _load_from_state_dict\n    super()._load_from_state_dict(\n  File "C:\\Users\\Stavros\\miniconda3\\envs\\pyt_pg\\Lib\\site-packages\\torch\\nn\\modules\\module.py", line 2015, in _load_from_state_dict\n    input_param = input_param[0]\n                  ~~~~~~~~~~~^^^\nIndexError: index 0 is out of bounds for dimension 0 with size 0\n',)

[2024-02-17 17:38:57,799][flwr][ERROR] - [36mray::DefaultActor.run()[39m (pid=1544, ip=127.0.0.1, actor_id=6b72c74b3aa8cd5035cce1c501000000, repr=<flwr.simulation.ray_transport.ray_actor.DefaultActor object at 0x000001F2ED593190>)
                  ^^^^^^^^^^^^^^
  File "C:\Users\Stavros\miniconda3\envs\pyt_pg\Lib\site-packages\flwr\simulation\ray_transport\ray_client_proxy.py", line 207, in fit
    return maybe_call_fit(
           ^^^^^^^^^^^^^^^
  File "C:\Users\Stavros\miniconda3\envs\pyt_pg\Lib\site-packages\flwr\client\client.py", line 234, in maybe_call_fit
    return client.fit(fit_ins)
           ^^^^^^^^^^^^^^^^^^^
  File "C:\Users\Stavros\miniconda3\envs\pyt_pg\Lib\site-packages\flwr\client\numpy_client.py", line 238, in _fit
    results = self.numpy_client.fit(parameters, ins.config)  # type: ignore
              ^^^^^^^^^^^^^^^^^^^^^^^^^^^^^^^^^^^^^^^^^^^^^
  File "C:\Users\Stavros\Desktop\PythonProjects\FlowerYtTut\client_scaffold.py", line 67, in fit
    self.set_parameters(parameters)
  File "C:\Users\Stavros\Desktop\PythonProjects\FlowerYtTut\client_scaffold.py", line 52, in set_parameters
    self.model.load_state_dict(state_dict, strict=True)
  File "C:\Users\Stavros\miniconda3\envs\pyt_pg\Lib\site-packages\torch\nn\modules\module.py", line 2138, in load_state_dict
    load(self, state_dict)
  File "C:\Users\Stavros\miniconda3\envs\pyt_pg\Lib\site-packages\torch\nn\modules\module.py", line 2126, in load
    load(child, child_state_dict, child_prefix)
  File "C:\Users\Stavros\miniconda3\envs\pyt_pg\Lib\site-packages\torch\nn\modules\module.py", line 2126, in load
    load(child, child_state_dict, child_prefix)
  File "C:\Users\Stavros\miniconda3\envs\pyt_pg\Lib\site-packages\torch\nn\modules\module.py", line 2120, in load
    module._load_from_state_dict(
  File "C:\Users\Stavros\miniconda3\envs\pyt_pg\Lib\site-packages\torch\nn\modules\batchnorm.py", line 110, in _load_from_state_dict
    super()._load_from_state_dict(
  File "C:\Users\Stavros\miniconda3\envs\pyt_pg\Lib\site-packages\torch\nn\modules\module.py", line 2015, in _load_from_state_dict
    input_param = input_param[0]
                  ~~~~~~~~~~~^^^
IndexError: index 0 is out of bounds for dimension 0 with size 0

The above exception was the direct cause of the following exception:

[36mray::DefaultActor.run()[39m (pid=1544, ip=127.0.0.1, actor_id=6b72c74b3aa8cd5035cce1c501000000, repr=<flwr.simulation.ray_transport.ray_actor.DefaultActor object at 0x000001F2ED593190>)
  File "python\ray\_raylet.pyx", line 1418, in ray._raylet.execute_task
  File "python\ray\_raylet.pyx", line 1498, in ray._raylet.execute_task
  File "python\ray\_raylet.pyx", line 1424, in ray._raylet.execute_task
  File "python\ray\_raylet.pyx", line 1364, in ray._raylet.execute_task.function_executor
  File "C:\Users\Stavros\miniconda3\envs\pyt_pg\Lib\site-packages\ray\_private\function_manager.py", line 726, in actor_method_executor
    return method(__ray_actor, *args, **kwargs)
           ^^^^^^^^^^^^^^^^^^^^^^^^^^^^^^^^^^^^
  File "C:\Users\Stavros\miniconda3\envs\pyt_pg\Lib\site-packages\ray\util\tracing\tracing_helper.py", line 464, in _resume_span
    return method(self, *_args, **_kwargs)
           ^^^^^^^^^^^^^^^^^^^^^^^^^^^^^^^
  File "C:\Users\Stavros\miniconda3\envs\pyt_pg\Lib\site-packages\flwr\simulation\ray_transport\ray_actor.py", line 90, in run
    raise ClientException(str(message)) from ex
flwr.simulation.ray_transport.ray_actor.ClientException: 
>>>>>>>A ClientException occurred.('\n\tSomething went wrong when running your client run.\n\tClient 30 crashed when the DefaultActor was running its run.\n\tException triggered on the client side: Traceback (most recent call last):\n  File "C:\\Users\\Stavros\\miniconda3\\envs\\pyt_pg\\Lib\\site-packages\\flwr\\simulation\\ray_transport\\ray_actor.py", line 76, in run\n    job_results = job_fn(client)\n                  ^^^^^^^^^^^^^^\n  File "C:\\Users\\Stavros\\miniconda3\\envs\\pyt_pg\\Lib\\site-packages\\flwr\\simulation\\ray_transport\\ray_client_proxy.py", line 207, in fit\n    return maybe_call_fit(\n           ^^^^^^^^^^^^^^^\n  File "C:\\Users\\Stavros\\miniconda3\\envs\\pyt_pg\\Lib\\site-packages\\flwr\\client\\client.py", line 234, in maybe_call_fit\n    return client.fit(fit_ins)\n           ^^^^^^^^^^^^^^^^^^^\n  File "C:\\Users\\Stavros\\miniconda3\\envs\\pyt_pg\\Lib\\site-packages\\flwr\\client\\numpy_client.py", line 238, in _fit\n    results = self.numpy_client.fit(parameters, ins.config)  # type: ignore\n              ^^^^^^^^^^^^^^^^^^^^^^^^^^^^^^^^^^^^^^^^^^^^^\n  File "C:\\Users\\Stavros\\Desktop\\PythonProjects\\FlowerYtTut\\client_scaffold.py", line 67, in fit\n    self.set_parameters(parameters)\n  File "C:\\Users\\Stavros\\Desktop\\PythonProjects\\FlowerYtTut\\client_scaffold.py", line 52, in set_parameters\n    self.model.load_state_dict(state_dict, strict=True)\n  File "C:\\Users\\Stavros\\miniconda3\\envs\\pyt_pg\\Lib\\site-packages\\torch\\nn\\modules\\module.py", line 2138, in load_state_dict\n    load(self, state_dict)\n  File "C:\\Users\\Stavros\\miniconda3\\envs\\pyt_pg\\Lib\\site-packages\\torch\\nn\\modules\\module.py", line 2126, in load\n    load(child, child_state_dict, child_prefix)\n  File "C:\\Users\\Stavros\\miniconda3\\envs\\pyt_pg\\Lib\\site-packages\\torch\\nn\\modules\\module.py", line 2126, in load\n    load(child, child_state_dict, child_prefix)\n  File "C:\\Users\\Stavros\\miniconda3\\envs\\pyt_pg\\Lib\\site-packages\\torch\\nn\\modules\\module.py", line 2120, in load\n    module._load_from_state_dict(\n  File "C:\\Users\\Stavros\\miniconda3\\envs\\pyt_pg\\Lib\\site-packages\\torch\\nn\\modules\\batchnorm.py", line 110, in _load_from_state_dict\n    super()._load_from_state_dict(\n  File "C:\\Users\\Stavros\\miniconda3\\envs\\pyt_pg\\Lib\\site-packages\\torch\\nn\\modules\\module.py", line 2015, in _load_from_state_dict\n    input_param = input_param[0]\n                  ~~~~~~~~~~~^^^\nIndexError: index 0 is out of bounds for dimension 0 with size 0\n',)
[2024-02-17 17:38:59,143][flwr][ERROR] - Traceback (most recent call last):
  File "C:\Users\Stavros\miniconda3\envs\pyt_pg\Lib\site-packages\flwr\simulation\ray_transport\ray_client_proxy.py", line 151, in _submit_job
    res, updated_context = self.actor_pool.get_client_result(self.cid, timeout)
                           ^^^^^^^^^^^^^^^^^^^^^^^^^^^^^^^^^^^^^^^^^^^^^^^^^^^^
  File "C:\Users\Stavros\miniconda3\envs\pyt_pg\Lib\site-packages\flwr\simulation\ray_transport\ray_actor.py", line 425, in get_client_result
    return self._fetch_future_result(cid)
           ^^^^^^^^^^^^^^^^^^^^^^^^^^^^^^
  File "C:\Users\Stavros\miniconda3\envs\pyt_pg\Lib\site-packages\flwr\simulation\ray_transport\ray_actor.py", line 306, in _fetch_future_result
    res_cid, res, updated_context = ray.get(
                                    ^^^^^^^^
  File "C:\Users\Stavros\miniconda3\envs\pyt_pg\Lib\site-packages\ray\_private\auto_init_hook.py", line 24, in auto_init_wrapper
    return fn(*args, **kwargs)
           ^^^^^^^^^^^^^^^^^^^
  File "C:\Users\Stavros\miniconda3\envs\pyt_pg\Lib\site-packages\ray\_private\client_mode_hook.py", line 103, in wrapper
    return func(*args, **kwargs)
           ^^^^^^^^^^^^^^^^^^^^^
  File "C:\Users\Stavros\miniconda3\envs\pyt_pg\Lib\site-packages\ray\_private\worker.py", line 2524, in get
    raise value.as_instanceof_cause()
ray.exceptions.RayTaskError(ClientException): [36mray::DefaultActor.run()[39m (pid=7276, ip=127.0.0.1, actor_id=2b56f33712a0c96a8e8982de01000000, repr=<flwr.simulation.ray_transport.ray_actor.DefaultActor object at 0x0000019069371690>)
                  ^^^^^^^^^^^^^^
  File "C:\Users\Stavros\miniconda3\envs\pyt_pg\Lib\site-packages\flwr\simulation\ray_transport\ray_client_proxy.py", line 207, in fit
    return maybe_call_fit(
           ^^^^^^^^^^^^^^^
  File "C:\Users\Stavros\miniconda3\envs\pyt_pg\Lib\site-packages\flwr\client\client.py", line 234, in maybe_call_fit
    return client.fit(fit_ins)
           ^^^^^^^^^^^^^^^^^^^
  File "C:\Users\Stavros\miniconda3\envs\pyt_pg\Lib\site-packages\flwr\client\numpy_client.py", line 238, in _fit
    results = self.numpy_client.fit(parameters, ins.config)  # type: ignore
              ^^^^^^^^^^^^^^^^^^^^^^^^^^^^^^^^^^^^^^^^^^^^^
  File "C:\Users\Stavros\Desktop\PythonProjects\FlowerYtTut\client_scaffold.py", line 67, in fit
    self.set_parameters(parameters)
  File "C:\Users\Stavros\Desktop\PythonProjects\FlowerYtTut\client_scaffold.py", line 52, in set_parameters
    self.model.load_state_dict(state_dict, strict=True)
  File "C:\Users\Stavros\miniconda3\envs\pyt_pg\Lib\site-packages\torch\nn\modules\module.py", line 2138, in load_state_dict
    load(self, state_dict)
  File "C:\Users\Stavros\miniconda3\envs\pyt_pg\Lib\site-packages\torch\nn\modules\module.py", line 2126, in load
    load(child, child_state_dict, child_prefix)
  File "C:\Users\Stavros\miniconda3\envs\pyt_pg\Lib\site-packages\torch\nn\modules\module.py", line 2126, in load
    load(child, child_state_dict, child_prefix)
  File "C:\Users\Stavros\miniconda3\envs\pyt_pg\Lib\site-packages\torch\nn\modules\module.py", line 2120, in load
    module._load_from_state_dict(
  File "C:\Users\Stavros\miniconda3\envs\pyt_pg\Lib\site-packages\torch\nn\modules\batchnorm.py", line 110, in _load_from_state_dict
    super()._load_from_state_dict(
  File "C:\Users\Stavros\miniconda3\envs\pyt_pg\Lib\site-packages\torch\nn\modules\module.py", line 2015, in _load_from_state_dict
    input_param = input_param[0]
                  ~~~~~~~~~~~^^^
IndexError: index 0 is out of bounds for dimension 0 with size 0

The above exception was the direct cause of the following exception:

[36mray::DefaultActor.run()[39m (pid=7276, ip=127.0.0.1, actor_id=2b56f33712a0c96a8e8982de01000000, repr=<flwr.simulation.ray_transport.ray_actor.DefaultActor object at 0x0000019069371690>)
  File "python\ray\_raylet.pyx", line 1418, in ray._raylet.execute_task
  File "python\ray\_raylet.pyx", line 1498, in ray._raylet.execute_task
  File "python\ray\_raylet.pyx", line 1424, in ray._raylet.execute_task
  File "python\ray\_raylet.pyx", line 1364, in ray._raylet.execute_task.function_executor
  File "C:\Users\Stavros\miniconda3\envs\pyt_pg\Lib\site-packages\ray\_private\function_manager.py", line 726, in actor_method_executor
    return method(__ray_actor, *args, **kwargs)
           ^^^^^^^^^^^^^^^^^^^^^^^^^^^^^^^^^^^^
  File "C:\Users\Stavros\miniconda3\envs\pyt_pg\Lib\site-packages\ray\util\tracing\tracing_helper.py", line 464, in _resume_span
    return method(self, *_args, **_kwargs)
           ^^^^^^^^^^^^^^^^^^^^^^^^^^^^^^^
  File "C:\Users\Stavros\miniconda3\envs\pyt_pg\Lib\site-packages\flwr\simulation\ray_transport\ray_actor.py", line 90, in run
    raise ClientException(str(message)) from ex
flwr.simulation.ray_transport.ray_actor.ClientException: 
>>>>>>>A ClientException occurred.('\n\tSomething went wrong when running your client run.\n\tClient 52 crashed when the DefaultActor was running its run.\n\tException triggered on the client side: Traceback (most recent call last):\n  File "C:\\Users\\Stavros\\miniconda3\\envs\\pyt_pg\\Lib\\site-packages\\flwr\\simulation\\ray_transport\\ray_actor.py", line 76, in run\n    job_results = job_fn(client)\n                  ^^^^^^^^^^^^^^\n  File "C:\\Users\\Stavros\\miniconda3\\envs\\pyt_pg\\Lib\\site-packages\\flwr\\simulation\\ray_transport\\ray_client_proxy.py", line 207, in fit\n    return maybe_call_fit(\n           ^^^^^^^^^^^^^^^\n  File "C:\\Users\\Stavros\\miniconda3\\envs\\pyt_pg\\Lib\\site-packages\\flwr\\client\\client.py", line 234, in maybe_call_fit\n    return client.fit(fit_ins)\n           ^^^^^^^^^^^^^^^^^^^\n  File "C:\\Users\\Stavros\\miniconda3\\envs\\pyt_pg\\Lib\\site-packages\\flwr\\client\\numpy_client.py", line 238, in _fit\n    results = self.numpy_client.fit(parameters, ins.config)  # type: ignore\n              ^^^^^^^^^^^^^^^^^^^^^^^^^^^^^^^^^^^^^^^^^^^^^\n  File "C:\\Users\\Stavros\\Desktop\\PythonProjects\\FlowerYtTut\\client_scaffold.py", line 67, in fit\n    self.set_parameters(parameters)\n  File "C:\\Users\\Stavros\\Desktop\\PythonProjects\\FlowerYtTut\\client_scaffold.py", line 52, in set_parameters\n    self.model.load_state_dict(state_dict, strict=True)\n  File "C:\\Users\\Stavros\\miniconda3\\envs\\pyt_pg\\Lib\\site-packages\\torch\\nn\\modules\\module.py", line 2138, in load_state_dict\n    load(self, state_dict)\n  File "C:\\Users\\Stavros\\miniconda3\\envs\\pyt_pg\\Lib\\site-packages\\torch\\nn\\modules\\module.py", line 2126, in load\n    load(child, child_state_dict, child_prefix)\n  File "C:\\Users\\Stavros\\miniconda3\\envs\\pyt_pg\\Lib\\site-packages\\torch\\nn\\modules\\module.py", line 2126, in load\n    load(child, child_state_dict, child_prefix)\n  File "C:\\Users\\Stavros\\miniconda3\\envs\\pyt_pg\\Lib\\site-packages\\torch\\nn\\modules\\module.py", line 2120, in load\n    module._load_from_state_dict(\n  File "C:\\Users\\Stavros\\miniconda3\\envs\\pyt_pg\\Lib\\site-packages\\torch\\nn\\modules\\batchnorm.py", line 110, in _load_from_state_dict\n    super()._load_from_state_dict(\n  File "C:\\Users\\Stavros\\miniconda3\\envs\\pyt_pg\\Lib\\site-packages\\torch\\nn\\modules\\module.py", line 2015, in _load_from_state_dict\n    input_param = input_param[0]\n                  ~~~~~~~~~~~^^^\nIndexError: index 0 is out of bounds for dimension 0 with size 0\n',)

[2024-02-17 17:38:59,157][flwr][ERROR] - [36mray::DefaultActor.run()[39m (pid=7276, ip=127.0.0.1, actor_id=2b56f33712a0c96a8e8982de01000000, repr=<flwr.simulation.ray_transport.ray_actor.DefaultActor object at 0x0000019069371690>)
                  ^^^^^^^^^^^^^^
  File "C:\Users\Stavros\miniconda3\envs\pyt_pg\Lib\site-packages\flwr\simulation\ray_transport\ray_client_proxy.py", line 207, in fit
    return maybe_call_fit(
           ^^^^^^^^^^^^^^^
  File "C:\Users\Stavros\miniconda3\envs\pyt_pg\Lib\site-packages\flwr\client\client.py", line 234, in maybe_call_fit
    return client.fit(fit_ins)
           ^^^^^^^^^^^^^^^^^^^
  File "C:\Users\Stavros\miniconda3\envs\pyt_pg\Lib\site-packages\flwr\client\numpy_client.py", line 238, in _fit
    results = self.numpy_client.fit(parameters, ins.config)  # type: ignore
              ^^^^^^^^^^^^^^^^^^^^^^^^^^^^^^^^^^^^^^^^^^^^^
  File "C:\Users\Stavros\Desktop\PythonProjects\FlowerYtTut\client_scaffold.py", line 67, in fit
    self.set_parameters(parameters)
  File "C:\Users\Stavros\Desktop\PythonProjects\FlowerYtTut\client_scaffold.py", line 52, in set_parameters
    self.model.load_state_dict(state_dict, strict=True)
  File "C:\Users\Stavros\miniconda3\envs\pyt_pg\Lib\site-packages\torch\nn\modules\module.py", line 2138, in load_state_dict
    load(self, state_dict)
  File "C:\Users\Stavros\miniconda3\envs\pyt_pg\Lib\site-packages\torch\nn\modules\module.py", line 2126, in load
    load(child, child_state_dict, child_prefix)
  File "C:\Users\Stavros\miniconda3\envs\pyt_pg\Lib\site-packages\torch\nn\modules\module.py", line 2126, in load
    load(child, child_state_dict, child_prefix)
  File "C:\Users\Stavros\miniconda3\envs\pyt_pg\Lib\site-packages\torch\nn\modules\module.py", line 2120, in load
    module._load_from_state_dict(
  File "C:\Users\Stavros\miniconda3\envs\pyt_pg\Lib\site-packages\torch\nn\modules\batchnorm.py", line 110, in _load_from_state_dict
    super()._load_from_state_dict(
  File "C:\Users\Stavros\miniconda3\envs\pyt_pg\Lib\site-packages\torch\nn\modules\module.py", line 2015, in _load_from_state_dict
    input_param = input_param[0]
                  ~~~~~~~~~~~^^^
IndexError: index 0 is out of bounds for dimension 0 with size 0

The above exception was the direct cause of the following exception:

[36mray::DefaultActor.run()[39m (pid=7276, ip=127.0.0.1, actor_id=2b56f33712a0c96a8e8982de01000000, repr=<flwr.simulation.ray_transport.ray_actor.DefaultActor object at 0x0000019069371690>)
  File "python\ray\_raylet.pyx", line 1418, in ray._raylet.execute_task
  File "python\ray\_raylet.pyx", line 1498, in ray._raylet.execute_task
  File "python\ray\_raylet.pyx", line 1424, in ray._raylet.execute_task
  File "python\ray\_raylet.pyx", line 1364, in ray._raylet.execute_task.function_executor
  File "C:\Users\Stavros\miniconda3\envs\pyt_pg\Lib\site-packages\ray\_private\function_manager.py", line 726, in actor_method_executor
    return method(__ray_actor, *args, **kwargs)
           ^^^^^^^^^^^^^^^^^^^^^^^^^^^^^^^^^^^^
  File "C:\Users\Stavros\miniconda3\envs\pyt_pg\Lib\site-packages\ray\util\tracing\tracing_helper.py", line 464, in _resume_span
    return method(self, *_args, **_kwargs)
           ^^^^^^^^^^^^^^^^^^^^^^^^^^^^^^^
  File "C:\Users\Stavros\miniconda3\envs\pyt_pg\Lib\site-packages\flwr\simulation\ray_transport\ray_actor.py", line 90, in run
    raise ClientException(str(message)) from ex
flwr.simulation.ray_transport.ray_actor.ClientException: 
>>>>>>>A ClientException occurred.('\n\tSomething went wrong when running your client run.\n\tClient 52 crashed when the DefaultActor was running its run.\n\tException triggered on the client side: Traceback (most recent call last):\n  File "C:\\Users\\Stavros\\miniconda3\\envs\\pyt_pg\\Lib\\site-packages\\flwr\\simulation\\ray_transport\\ray_actor.py", line 76, in run\n    job_results = job_fn(client)\n                  ^^^^^^^^^^^^^^\n  File "C:\\Users\\Stavros\\miniconda3\\envs\\pyt_pg\\Lib\\site-packages\\flwr\\simulation\\ray_transport\\ray_client_proxy.py", line 207, in fit\n    return maybe_call_fit(\n           ^^^^^^^^^^^^^^^\n  File "C:\\Users\\Stavros\\miniconda3\\envs\\pyt_pg\\Lib\\site-packages\\flwr\\client\\client.py", line 234, in maybe_call_fit\n    return client.fit(fit_ins)\n           ^^^^^^^^^^^^^^^^^^^\n  File "C:\\Users\\Stavros\\miniconda3\\envs\\pyt_pg\\Lib\\site-packages\\flwr\\client\\numpy_client.py", line 238, in _fit\n    results = self.numpy_client.fit(parameters, ins.config)  # type: ignore\n              ^^^^^^^^^^^^^^^^^^^^^^^^^^^^^^^^^^^^^^^^^^^^^\n  File "C:\\Users\\Stavros\\Desktop\\PythonProjects\\FlowerYtTut\\client_scaffold.py", line 67, in fit\n    self.set_parameters(parameters)\n  File "C:\\Users\\Stavros\\Desktop\\PythonProjects\\FlowerYtTut\\client_scaffold.py", line 52, in set_parameters\n    self.model.load_state_dict(state_dict, strict=True)\n  File "C:\\Users\\Stavros\\miniconda3\\envs\\pyt_pg\\Lib\\site-packages\\torch\\nn\\modules\\module.py", line 2138, in load_state_dict\n    load(self, state_dict)\n  File "C:\\Users\\Stavros\\miniconda3\\envs\\pyt_pg\\Lib\\site-packages\\torch\\nn\\modules\\module.py", line 2126, in load\n    load(child, child_state_dict, child_prefix)\n  File "C:\\Users\\Stavros\\miniconda3\\envs\\pyt_pg\\Lib\\site-packages\\torch\\nn\\modules\\module.py", line 2126, in load\n    load(child, child_state_dict, child_prefix)\n  File "C:\\Users\\Stavros\\miniconda3\\envs\\pyt_pg\\Lib\\site-packages\\torch\\nn\\modules\\module.py", line 2120, in load\n    module._load_from_state_dict(\n  File "C:\\Users\\Stavros\\miniconda3\\envs\\pyt_pg\\Lib\\site-packages\\torch\\nn\\modules\\batchnorm.py", line 110, in _load_from_state_dict\n    super()._load_from_state_dict(\n  File "C:\\Users\\Stavros\\miniconda3\\envs\\pyt_pg\\Lib\\site-packages\\torch\\nn\\modules\\module.py", line 2015, in _load_from_state_dict\n    input_param = input_param[0]\n                  ~~~~~~~~~~~^^^\nIndexError: index 0 is out of bounds for dimension 0 with size 0\n',)
[2024-02-17 17:38:59,814][flwr][ERROR] - Traceback (most recent call last):
  File "C:\Users\Stavros\miniconda3\envs\pyt_pg\Lib\site-packages\flwr\simulation\ray_transport\ray_client_proxy.py", line 151, in _submit_job
    res, updated_context = self.actor_pool.get_client_result(self.cid, timeout)
                           ^^^^^^^^^^^^^^^^^^^^^^^^^^^^^^^^^^^^^^^^^^^^^^^^^^^^
  File "C:\Users\Stavros\miniconda3\envs\pyt_pg\Lib\site-packages\flwr\simulation\ray_transport\ray_actor.py", line 425, in get_client_result
    return self._fetch_future_result(cid)
           ^^^^^^^^^^^^^^^^^^^^^^^^^^^^^^
  File "C:\Users\Stavros\miniconda3\envs\pyt_pg\Lib\site-packages\flwr\simulation\ray_transport\ray_actor.py", line 306, in _fetch_future_result
    res_cid, res, updated_context = ray.get(
                                    ^^^^^^^^
  File "C:\Users\Stavros\miniconda3\envs\pyt_pg\Lib\site-packages\ray\_private\auto_init_hook.py", line 24, in auto_init_wrapper
    return fn(*args, **kwargs)
           ^^^^^^^^^^^^^^^^^^^
  File "C:\Users\Stavros\miniconda3\envs\pyt_pg\Lib\site-packages\ray\_private\client_mode_hook.py", line 103, in wrapper
    return func(*args, **kwargs)
           ^^^^^^^^^^^^^^^^^^^^^
  File "C:\Users\Stavros\miniconda3\envs\pyt_pg\Lib\site-packages\ray\_private\worker.py", line 2524, in get
    raise value.as_instanceof_cause()
ray.exceptions.RayTaskError(ClientException): [36mray::DefaultActor.run()[39m (pid=1544, ip=127.0.0.1, actor_id=6b72c74b3aa8cd5035cce1c501000000, repr=<flwr.simulation.ray_transport.ray_actor.DefaultActor object at 0x000001F2ED593190>)
                  ^^^^^^^^^^^^^^
  File "C:\Users\Stavros\miniconda3\envs\pyt_pg\Lib\site-packages\flwr\simulation\ray_transport\ray_client_proxy.py", line 207, in fit
    return maybe_call_fit(
           ^^^^^^^^^^^^^^^
  File "C:\Users\Stavros\miniconda3\envs\pyt_pg\Lib\site-packages\flwr\client\client.py", line 234, in maybe_call_fit
    return client.fit(fit_ins)
           ^^^^^^^^^^^^^^^^^^^
  File "C:\Users\Stavros\miniconda3\envs\pyt_pg\Lib\site-packages\flwr\client\numpy_client.py", line 238, in _fit
    results = self.numpy_client.fit(parameters, ins.config)  # type: ignore
              ^^^^^^^^^^^^^^^^^^^^^^^^^^^^^^^^^^^^^^^^^^^^^
  File "C:\Users\Stavros\Desktop\PythonProjects\FlowerYtTut\client_scaffold.py", line 67, in fit
    self.set_parameters(parameters)
  File "C:\Users\Stavros\Desktop\PythonProjects\FlowerYtTut\client_scaffold.py", line 52, in set_parameters
    self.model.load_state_dict(state_dict, strict=True)
  File "C:\Users\Stavros\miniconda3\envs\pyt_pg\Lib\site-packages\torch\nn\modules\module.py", line 2138, in load_state_dict
    load(self, state_dict)
  File "C:\Users\Stavros\miniconda3\envs\pyt_pg\Lib\site-packages\torch\nn\modules\module.py", line 2126, in load
    load(child, child_state_dict, child_prefix)
  File "C:\Users\Stavros\miniconda3\envs\pyt_pg\Lib\site-packages\torch\nn\modules\module.py", line 2126, in load
    load(child, child_state_dict, child_prefix)
  File "C:\Users\Stavros\miniconda3\envs\pyt_pg\Lib\site-packages\torch\nn\modules\module.py", line 2120, in load
    module._load_from_state_dict(
  File "C:\Users\Stavros\miniconda3\envs\pyt_pg\Lib\site-packages\torch\nn\modules\batchnorm.py", line 110, in _load_from_state_dict
    super()._load_from_state_dict(
  File "C:\Users\Stavros\miniconda3\envs\pyt_pg\Lib\site-packages\torch\nn\modules\module.py", line 2015, in _load_from_state_dict
    input_param = input_param[0]
                  ~~~~~~~~~~~^^^
IndexError: index 0 is out of bounds for dimension 0 with size 0

The above exception was the direct cause of the following exception:

[36mray::DefaultActor.run()[39m (pid=1544, ip=127.0.0.1, actor_id=6b72c74b3aa8cd5035cce1c501000000, repr=<flwr.simulation.ray_transport.ray_actor.DefaultActor object at 0x000001F2ED593190>)
  File "python\ray\_raylet.pyx", line 1418, in ray._raylet.execute_task
  File "python\ray\_raylet.pyx", line 1498, in ray._raylet.execute_task
  File "python\ray\_raylet.pyx", line 1424, in ray._raylet.execute_task
  File "python\ray\_raylet.pyx", line 1364, in ray._raylet.execute_task.function_executor
  File "C:\Users\Stavros\miniconda3\envs\pyt_pg\Lib\site-packages\ray\_private\function_manager.py", line 726, in actor_method_executor
    return method(__ray_actor, *args, **kwargs)
           ^^^^^^^^^^^^^^^^^^^^^^^^^^^^^^^^^^^^
  File "C:\Users\Stavros\miniconda3\envs\pyt_pg\Lib\site-packages\ray\util\tracing\tracing_helper.py", line 464, in _resume_span
    return method(self, *_args, **_kwargs)
           ^^^^^^^^^^^^^^^^^^^^^^^^^^^^^^^
  File "C:\Users\Stavros\miniconda3\envs\pyt_pg\Lib\site-packages\flwr\simulation\ray_transport\ray_actor.py", line 90, in run
    raise ClientException(str(message)) from ex
flwr.simulation.ray_transport.ray_actor.ClientException: 
>>>>>>>A ClientException occurred.('\n\tSomething went wrong when running your client run.\n\tClient 71 crashed when the DefaultActor was running its run.\n\tException triggered on the client side: Traceback (most recent call last):\n  File "C:\\Users\\Stavros\\miniconda3\\envs\\pyt_pg\\Lib\\site-packages\\flwr\\simulation\\ray_transport\\ray_actor.py", line 76, in run\n    job_results = job_fn(client)\n                  ^^^^^^^^^^^^^^\n  File "C:\\Users\\Stavros\\miniconda3\\envs\\pyt_pg\\Lib\\site-packages\\flwr\\simulation\\ray_transport\\ray_client_proxy.py", line 207, in fit\n    return maybe_call_fit(\n           ^^^^^^^^^^^^^^^\n  File "C:\\Users\\Stavros\\miniconda3\\envs\\pyt_pg\\Lib\\site-packages\\flwr\\client\\client.py", line 234, in maybe_call_fit\n    return client.fit(fit_ins)\n           ^^^^^^^^^^^^^^^^^^^\n  File "C:\\Users\\Stavros\\miniconda3\\envs\\pyt_pg\\Lib\\site-packages\\flwr\\client\\numpy_client.py", line 238, in _fit\n    results = self.numpy_client.fit(parameters, ins.config)  # type: ignore\n              ^^^^^^^^^^^^^^^^^^^^^^^^^^^^^^^^^^^^^^^^^^^^^\n  File "C:\\Users\\Stavros\\Desktop\\PythonProjects\\FlowerYtTut\\client_scaffold.py", line 67, in fit\n    self.set_parameters(parameters)\n  File "C:\\Users\\Stavros\\Desktop\\PythonProjects\\FlowerYtTut\\client_scaffold.py", line 52, in set_parameters\n    self.model.load_state_dict(state_dict, strict=True)\n  File "C:\\Users\\Stavros\\miniconda3\\envs\\pyt_pg\\Lib\\site-packages\\torch\\nn\\modules\\module.py", line 2138, in load_state_dict\n    load(self, state_dict)\n  File "C:\\Users\\Stavros\\miniconda3\\envs\\pyt_pg\\Lib\\site-packages\\torch\\nn\\modules\\module.py", line 2126, in load\n    load(child, child_state_dict, child_prefix)\n  File "C:\\Users\\Stavros\\miniconda3\\envs\\pyt_pg\\Lib\\site-packages\\torch\\nn\\modules\\module.py", line 2126, in load\n    load(child, child_state_dict, child_prefix)\n  File "C:\\Users\\Stavros\\miniconda3\\envs\\pyt_pg\\Lib\\site-packages\\torch\\nn\\modules\\module.py", line 2120, in load\n    module._load_from_state_dict(\n  File "C:\\Users\\Stavros\\miniconda3\\envs\\pyt_pg\\Lib\\site-packages\\torch\\nn\\modules\\batchnorm.py", line 110, in _load_from_state_dict\n    super()._load_from_state_dict(\n  File "C:\\Users\\Stavros\\miniconda3\\envs\\pyt_pg\\Lib\\site-packages\\torch\\nn\\modules\\module.py", line 2015, in _load_from_state_dict\n    input_param = input_param[0]\n                  ~~~~~~~~~~~^^^\nIndexError: index 0 is out of bounds for dimension 0 with size 0\n',)

[2024-02-17 17:38:59,829][flwr][ERROR] - [36mray::DefaultActor.run()[39m (pid=1544, ip=127.0.0.1, actor_id=6b72c74b3aa8cd5035cce1c501000000, repr=<flwr.simulation.ray_transport.ray_actor.DefaultActor object at 0x000001F2ED593190>)
                  ^^^^^^^^^^^^^^
  File "C:\Users\Stavros\miniconda3\envs\pyt_pg\Lib\site-packages\flwr\simulation\ray_transport\ray_client_proxy.py", line 207, in fit
    return maybe_call_fit(
           ^^^^^^^^^^^^^^^
  File "C:\Users\Stavros\miniconda3\envs\pyt_pg\Lib\site-packages\flwr\client\client.py", line 234, in maybe_call_fit
    return client.fit(fit_ins)
           ^^^^^^^^^^^^^^^^^^^
  File "C:\Users\Stavros\miniconda3\envs\pyt_pg\Lib\site-packages\flwr\client\numpy_client.py", line 238, in _fit
    results = self.numpy_client.fit(parameters, ins.config)  # type: ignore
              ^^^^^^^^^^^^^^^^^^^^^^^^^^^^^^^^^^^^^^^^^^^^^
  File "C:\Users\Stavros\Desktop\PythonProjects\FlowerYtTut\client_scaffold.py", line 67, in fit
    self.set_parameters(parameters)
  File "C:\Users\Stavros\Desktop\PythonProjects\FlowerYtTut\client_scaffold.py", line 52, in set_parameters
    self.model.load_state_dict(state_dict, strict=True)
  File "C:\Users\Stavros\miniconda3\envs\pyt_pg\Lib\site-packages\torch\nn\modules\module.py", line 2138, in load_state_dict
    load(self, state_dict)
  File "C:\Users\Stavros\miniconda3\envs\pyt_pg\Lib\site-packages\torch\nn\modules\module.py", line 2126, in load
    load(child, child_state_dict, child_prefix)
  File "C:\Users\Stavros\miniconda3\envs\pyt_pg\Lib\site-packages\torch\nn\modules\module.py", line 2126, in load
    load(child, child_state_dict, child_prefix)
  File "C:\Users\Stavros\miniconda3\envs\pyt_pg\Lib\site-packages\torch\nn\modules\module.py", line 2120, in load
    module._load_from_state_dict(
  File "C:\Users\Stavros\miniconda3\envs\pyt_pg\Lib\site-packages\torch\nn\modules\batchnorm.py", line 110, in _load_from_state_dict
    super()._load_from_state_dict(
  File "C:\Users\Stavros\miniconda3\envs\pyt_pg\Lib\site-packages\torch\nn\modules\module.py", line 2015, in _load_from_state_dict
    input_param = input_param[0]
                  ~~~~~~~~~~~^^^
IndexError: index 0 is out of bounds for dimension 0 with size 0

The above exception was the direct cause of the following exception:

[36mray::DefaultActor.run()[39m (pid=1544, ip=127.0.0.1, actor_id=6b72c74b3aa8cd5035cce1c501000000, repr=<flwr.simulation.ray_transport.ray_actor.DefaultActor object at 0x000001F2ED593190>)
  File "python\ray\_raylet.pyx", line 1418, in ray._raylet.execute_task
  File "python\ray\_raylet.pyx", line 1498, in ray._raylet.execute_task
  File "python\ray\_raylet.pyx", line 1424, in ray._raylet.execute_task
  File "python\ray\_raylet.pyx", line 1364, in ray._raylet.execute_task.function_executor
  File "C:\Users\Stavros\miniconda3\envs\pyt_pg\Lib\site-packages\ray\_private\function_manager.py", line 726, in actor_method_executor
    return method(__ray_actor, *args, **kwargs)
           ^^^^^^^^^^^^^^^^^^^^^^^^^^^^^^^^^^^^
  File "C:\Users\Stavros\miniconda3\envs\pyt_pg\Lib\site-packages\ray\util\tracing\tracing_helper.py", line 464, in _resume_span
    return method(self, *_args, **_kwargs)
           ^^^^^^^^^^^^^^^^^^^^^^^^^^^^^^^
  File "C:\Users\Stavros\miniconda3\envs\pyt_pg\Lib\site-packages\flwr\simulation\ray_transport\ray_actor.py", line 90, in run
    raise ClientException(str(message)) from ex
flwr.simulation.ray_transport.ray_actor.ClientException: 
>>>>>>>A ClientException occurred.('\n\tSomething went wrong when running your client run.\n\tClient 71 crashed when the DefaultActor was running its run.\n\tException triggered on the client side: Traceback (most recent call last):\n  File "C:\\Users\\Stavros\\miniconda3\\envs\\pyt_pg\\Lib\\site-packages\\flwr\\simulation\\ray_transport\\ray_actor.py", line 76, in run\n    job_results = job_fn(client)\n                  ^^^^^^^^^^^^^^\n  File "C:\\Users\\Stavros\\miniconda3\\envs\\pyt_pg\\Lib\\site-packages\\flwr\\simulation\\ray_transport\\ray_client_proxy.py", line 207, in fit\n    return maybe_call_fit(\n           ^^^^^^^^^^^^^^^\n  File "C:\\Users\\Stavros\\miniconda3\\envs\\pyt_pg\\Lib\\site-packages\\flwr\\client\\client.py", line 234, in maybe_call_fit\n    return client.fit(fit_ins)\n           ^^^^^^^^^^^^^^^^^^^\n  File "C:\\Users\\Stavros\\miniconda3\\envs\\pyt_pg\\Lib\\site-packages\\flwr\\client\\numpy_client.py", line 238, in _fit\n    results = self.numpy_client.fit(parameters, ins.config)  # type: ignore\n              ^^^^^^^^^^^^^^^^^^^^^^^^^^^^^^^^^^^^^^^^^^^^^\n  File "C:\\Users\\Stavros\\Desktop\\PythonProjects\\FlowerYtTut\\client_scaffold.py", line 67, in fit\n    self.set_parameters(parameters)\n  File "C:\\Users\\Stavros\\Desktop\\PythonProjects\\FlowerYtTut\\client_scaffold.py", line 52, in set_parameters\n    self.model.load_state_dict(state_dict, strict=True)\n  File "C:\\Users\\Stavros\\miniconda3\\envs\\pyt_pg\\Lib\\site-packages\\torch\\nn\\modules\\module.py", line 2138, in load_state_dict\n    load(self, state_dict)\n  File "C:\\Users\\Stavros\\miniconda3\\envs\\pyt_pg\\Lib\\site-packages\\torch\\nn\\modules\\module.py", line 2126, in load\n    load(child, child_state_dict, child_prefix)\n  File "C:\\Users\\Stavros\\miniconda3\\envs\\pyt_pg\\Lib\\site-packages\\torch\\nn\\modules\\module.py", line 2126, in load\n    load(child, child_state_dict, child_prefix)\n  File "C:\\Users\\Stavros\\miniconda3\\envs\\pyt_pg\\Lib\\site-packages\\torch\\nn\\modules\\module.py", line 2120, in load\n    module._load_from_state_dict(\n  File "C:\\Users\\Stavros\\miniconda3\\envs\\pyt_pg\\Lib\\site-packages\\torch\\nn\\modules\\batchnorm.py", line 110, in _load_from_state_dict\n    super()._load_from_state_dict(\n  File "C:\\Users\\Stavros\\miniconda3\\envs\\pyt_pg\\Lib\\site-packages\\torch\\nn\\modules\\module.py", line 2015, in _load_from_state_dict\n    input_param = input_param[0]\n                  ~~~~~~~~~~~^^^\nIndexError: index 0 is out of bounds for dimension 0 with size 0\n',)
[2024-02-17 17:39:01,157][flwr][ERROR] - Traceback (most recent call last):
  File "C:\Users\Stavros\miniconda3\envs\pyt_pg\Lib\site-packages\flwr\simulation\ray_transport\ray_client_proxy.py", line 151, in _submit_job
    res, updated_context = self.actor_pool.get_client_result(self.cid, timeout)
                           ^^^^^^^^^^^^^^^^^^^^^^^^^^^^^^^^^^^^^^^^^^^^^^^^^^^^
  File "C:\Users\Stavros\miniconda3\envs\pyt_pg\Lib\site-packages\flwr\simulation\ray_transport\ray_actor.py", line 425, in get_client_result
    return self._fetch_future_result(cid)
           ^^^^^^^^^^^^^^^^^^^^^^^^^^^^^^
  File "C:\Users\Stavros\miniconda3\envs\pyt_pg\Lib\site-packages\flwr\simulation\ray_transport\ray_actor.py", line 306, in _fetch_future_result
    res_cid, res, updated_context = ray.get(
                                    ^^^^^^^^
  File "C:\Users\Stavros\miniconda3\envs\pyt_pg\Lib\site-packages\ray\_private\auto_init_hook.py", line 24, in auto_init_wrapper
    return fn(*args, **kwargs)
           ^^^^^^^^^^^^^^^^^^^
  File "C:\Users\Stavros\miniconda3\envs\pyt_pg\Lib\site-packages\ray\_private\client_mode_hook.py", line 103, in wrapper
    return func(*args, **kwargs)
           ^^^^^^^^^^^^^^^^^^^^^
  File "C:\Users\Stavros\miniconda3\envs\pyt_pg\Lib\site-packages\ray\_private\worker.py", line 2524, in get
    raise value.as_instanceof_cause()
ray.exceptions.RayTaskError(ClientException): [36mray::DefaultActor.run()[39m (pid=7276, ip=127.0.0.1, actor_id=2b56f33712a0c96a8e8982de01000000, repr=<flwr.simulation.ray_transport.ray_actor.DefaultActor object at 0x0000019069371690>)
                  ^^^^^^^^^^^^^^
  File "C:\Users\Stavros\miniconda3\envs\pyt_pg\Lib\site-packages\flwr\simulation\ray_transport\ray_client_proxy.py", line 207, in fit
    return maybe_call_fit(
           ^^^^^^^^^^^^^^^
  File "C:\Users\Stavros\miniconda3\envs\pyt_pg\Lib\site-packages\flwr\client\client.py", line 234, in maybe_call_fit
    return client.fit(fit_ins)
           ^^^^^^^^^^^^^^^^^^^
  File "C:\Users\Stavros\miniconda3\envs\pyt_pg\Lib\site-packages\flwr\client\numpy_client.py", line 238, in _fit
    results = self.numpy_client.fit(parameters, ins.config)  # type: ignore
              ^^^^^^^^^^^^^^^^^^^^^^^^^^^^^^^^^^^^^^^^^^^^^
  File "C:\Users\Stavros\Desktop\PythonProjects\FlowerYtTut\client_scaffold.py", line 67, in fit
    self.set_parameters(parameters)
  File "C:\Users\Stavros\Desktop\PythonProjects\FlowerYtTut\client_scaffold.py", line 52, in set_parameters
    self.model.load_state_dict(state_dict, strict=True)
  File "C:\Users\Stavros\miniconda3\envs\pyt_pg\Lib\site-packages\torch\nn\modules\module.py", line 2138, in load_state_dict
    load(self, state_dict)
  File "C:\Users\Stavros\miniconda3\envs\pyt_pg\Lib\site-packages\torch\nn\modules\module.py", line 2126, in load
    load(child, child_state_dict, child_prefix)
  File "C:\Users\Stavros\miniconda3\envs\pyt_pg\Lib\site-packages\torch\nn\modules\module.py", line 2126, in load
    load(child, child_state_dict, child_prefix)
  File "C:\Users\Stavros\miniconda3\envs\pyt_pg\Lib\site-packages\torch\nn\modules\module.py", line 2120, in load
    module._load_from_state_dict(
  File "C:\Users\Stavros\miniconda3\envs\pyt_pg\Lib\site-packages\torch\nn\modules\batchnorm.py", line 110, in _load_from_state_dict
    super()._load_from_state_dict(
  File "C:\Users\Stavros\miniconda3\envs\pyt_pg\Lib\site-packages\torch\nn\modules\module.py", line 2015, in _load_from_state_dict
    input_param = input_param[0]
                  ~~~~~~~~~~~^^^
IndexError: index 0 is out of bounds for dimension 0 with size 0

The above exception was the direct cause of the following exception:

[36mray::DefaultActor.run()[39m (pid=7276, ip=127.0.0.1, actor_id=2b56f33712a0c96a8e8982de01000000, repr=<flwr.simulation.ray_transport.ray_actor.DefaultActor object at 0x0000019069371690>)
  File "python\ray\_raylet.pyx", line 1418, in ray._raylet.execute_task
  File "python\ray\_raylet.pyx", line 1498, in ray._raylet.execute_task
  File "python\ray\_raylet.pyx", line 1424, in ray._raylet.execute_task
  File "python\ray\_raylet.pyx", line 1364, in ray._raylet.execute_task.function_executor
  File "C:\Users\Stavros\miniconda3\envs\pyt_pg\Lib\site-packages\ray\_private\function_manager.py", line 726, in actor_method_executor
    return method(__ray_actor, *args, **kwargs)
           ^^^^^^^^^^^^^^^^^^^^^^^^^^^^^^^^^^^^
  File "C:\Users\Stavros\miniconda3\envs\pyt_pg\Lib\site-packages\ray\util\tracing\tracing_helper.py", line 464, in _resume_span
    return method(self, *_args, **_kwargs)
           ^^^^^^^^^^^^^^^^^^^^^^^^^^^^^^^
  File "C:\Users\Stavros\miniconda3\envs\pyt_pg\Lib\site-packages\flwr\simulation\ray_transport\ray_actor.py", line 90, in run
    raise ClientException(str(message)) from ex
flwr.simulation.ray_transport.ray_actor.ClientException: 
>>>>>>>A ClientException occurred.('\n\tSomething went wrong when running your client run.\n\tClient 93 crashed when the DefaultActor was running its run.\n\tException triggered on the client side: Traceback (most recent call last):\n  File "C:\\Users\\Stavros\\miniconda3\\envs\\pyt_pg\\Lib\\site-packages\\flwr\\simulation\\ray_transport\\ray_actor.py", line 76, in run\n    job_results = job_fn(client)\n                  ^^^^^^^^^^^^^^\n  File "C:\\Users\\Stavros\\miniconda3\\envs\\pyt_pg\\Lib\\site-packages\\flwr\\simulation\\ray_transport\\ray_client_proxy.py", line 207, in fit\n    return maybe_call_fit(\n           ^^^^^^^^^^^^^^^\n  File "C:\\Users\\Stavros\\miniconda3\\envs\\pyt_pg\\Lib\\site-packages\\flwr\\client\\client.py", line 234, in maybe_call_fit\n    return client.fit(fit_ins)\n           ^^^^^^^^^^^^^^^^^^^\n  File "C:\\Users\\Stavros\\miniconda3\\envs\\pyt_pg\\Lib\\site-packages\\flwr\\client\\numpy_client.py", line 238, in _fit\n    results = self.numpy_client.fit(parameters, ins.config)  # type: ignore\n              ^^^^^^^^^^^^^^^^^^^^^^^^^^^^^^^^^^^^^^^^^^^^^\n  File "C:\\Users\\Stavros\\Desktop\\PythonProjects\\FlowerYtTut\\client_scaffold.py", line 67, in fit\n    self.set_parameters(parameters)\n  File "C:\\Users\\Stavros\\Desktop\\PythonProjects\\FlowerYtTut\\client_scaffold.py", line 52, in set_parameters\n    self.model.load_state_dict(state_dict, strict=True)\n  File "C:\\Users\\Stavros\\miniconda3\\envs\\pyt_pg\\Lib\\site-packages\\torch\\nn\\modules\\module.py", line 2138, in load_state_dict\n    load(self, state_dict)\n  File "C:\\Users\\Stavros\\miniconda3\\envs\\pyt_pg\\Lib\\site-packages\\torch\\nn\\modules\\module.py", line 2126, in load\n    load(child, child_state_dict, child_prefix)\n  File "C:\\Users\\Stavros\\miniconda3\\envs\\pyt_pg\\Lib\\site-packages\\torch\\nn\\modules\\module.py", line 2126, in load\n    load(child, child_state_dict, child_prefix)\n  File "C:\\Users\\Stavros\\miniconda3\\envs\\pyt_pg\\Lib\\site-packages\\torch\\nn\\modules\\module.py", line 2120, in load\n    module._load_from_state_dict(\n  File "C:\\Users\\Stavros\\miniconda3\\envs\\pyt_pg\\Lib\\site-packages\\torch\\nn\\modules\\batchnorm.py", line 110, in _load_from_state_dict\n    super()._load_from_state_dict(\n  File "C:\\Users\\Stavros\\miniconda3\\envs\\pyt_pg\\Lib\\site-packages\\torch\\nn\\modules\\module.py", line 2015, in _load_from_state_dict\n    input_param = input_param[0]\n                  ~~~~~~~~~~~^^^\nIndexError: index 0 is out of bounds for dimension 0 with size 0\n',)

[2024-02-17 17:39:01,176][flwr][ERROR] - [36mray::DefaultActor.run()[39m (pid=7276, ip=127.0.0.1, actor_id=2b56f33712a0c96a8e8982de01000000, repr=<flwr.simulation.ray_transport.ray_actor.DefaultActor object at 0x0000019069371690>)
                  ^^^^^^^^^^^^^^
  File "C:\Users\Stavros\miniconda3\envs\pyt_pg\Lib\site-packages\flwr\simulation\ray_transport\ray_client_proxy.py", line 207, in fit
    return maybe_call_fit(
           ^^^^^^^^^^^^^^^
  File "C:\Users\Stavros\miniconda3\envs\pyt_pg\Lib\site-packages\flwr\client\client.py", line 234, in maybe_call_fit
    return client.fit(fit_ins)
           ^^^^^^^^^^^^^^^^^^^
  File "C:\Users\Stavros\miniconda3\envs\pyt_pg\Lib\site-packages\flwr\client\numpy_client.py", line 238, in _fit
    results = self.numpy_client.fit(parameters, ins.config)  # type: ignore
              ^^^^^^^^^^^^^^^^^^^^^^^^^^^^^^^^^^^^^^^^^^^^^
  File "C:\Users\Stavros\Desktop\PythonProjects\FlowerYtTut\client_scaffold.py", line 67, in fit
    self.set_parameters(parameters)
  File "C:\Users\Stavros\Desktop\PythonProjects\FlowerYtTut\client_scaffold.py", line 52, in set_parameters
    self.model.load_state_dict(state_dict, strict=True)
  File "C:\Users\Stavros\miniconda3\envs\pyt_pg\Lib\site-packages\torch\nn\modules\module.py", line 2138, in load_state_dict
    load(self, state_dict)
  File "C:\Users\Stavros\miniconda3\envs\pyt_pg\Lib\site-packages\torch\nn\modules\module.py", line 2126, in load
    load(child, child_state_dict, child_prefix)
  File "C:\Users\Stavros\miniconda3\envs\pyt_pg\Lib\site-packages\torch\nn\modules\module.py", line 2126, in load
    load(child, child_state_dict, child_prefix)
  File "C:\Users\Stavros\miniconda3\envs\pyt_pg\Lib\site-packages\torch\nn\modules\module.py", line 2120, in load
    module._load_from_state_dict(
  File "C:\Users\Stavros\miniconda3\envs\pyt_pg\Lib\site-packages\torch\nn\modules\batchnorm.py", line 110, in _load_from_state_dict
    super()._load_from_state_dict(
  File "C:\Users\Stavros\miniconda3\envs\pyt_pg\Lib\site-packages\torch\nn\modules\module.py", line 2015, in _load_from_state_dict
    input_param = input_param[0]
                  ~~~~~~~~~~~^^^
IndexError: index 0 is out of bounds for dimension 0 with size 0

The above exception was the direct cause of the following exception:

[36mray::DefaultActor.run()[39m (pid=7276, ip=127.0.0.1, actor_id=2b56f33712a0c96a8e8982de01000000, repr=<flwr.simulation.ray_transport.ray_actor.DefaultActor object at 0x0000019069371690>)
  File "python\ray\_raylet.pyx", line 1418, in ray._raylet.execute_task
  File "python\ray\_raylet.pyx", line 1498, in ray._raylet.execute_task
  File "python\ray\_raylet.pyx", line 1424, in ray._raylet.execute_task
  File "python\ray\_raylet.pyx", line 1364, in ray._raylet.execute_task.function_executor
  File "C:\Users\Stavros\miniconda3\envs\pyt_pg\Lib\site-packages\ray\_private\function_manager.py", line 726, in actor_method_executor
    return method(__ray_actor, *args, **kwargs)
           ^^^^^^^^^^^^^^^^^^^^^^^^^^^^^^^^^^^^
  File "C:\Users\Stavros\miniconda3\envs\pyt_pg\Lib\site-packages\ray\util\tracing\tracing_helper.py", line 464, in _resume_span
    return method(self, *_args, **_kwargs)
           ^^^^^^^^^^^^^^^^^^^^^^^^^^^^^^^
  File "C:\Users\Stavros\miniconda3\envs\pyt_pg\Lib\site-packages\flwr\simulation\ray_transport\ray_actor.py", line 90, in run
    raise ClientException(str(message)) from ex
flwr.simulation.ray_transport.ray_actor.ClientException: 
>>>>>>>A ClientException occurred.('\n\tSomething went wrong when running your client run.\n\tClient 93 crashed when the DefaultActor was running its run.\n\tException triggered on the client side: Traceback (most recent call last):\n  File "C:\\Users\\Stavros\\miniconda3\\envs\\pyt_pg\\Lib\\site-packages\\flwr\\simulation\\ray_transport\\ray_actor.py", line 76, in run\n    job_results = job_fn(client)\n                  ^^^^^^^^^^^^^^\n  File "C:\\Users\\Stavros\\miniconda3\\envs\\pyt_pg\\Lib\\site-packages\\flwr\\simulation\\ray_transport\\ray_client_proxy.py", line 207, in fit\n    return maybe_call_fit(\n           ^^^^^^^^^^^^^^^\n  File "C:\\Users\\Stavros\\miniconda3\\envs\\pyt_pg\\Lib\\site-packages\\flwr\\client\\client.py", line 234, in maybe_call_fit\n    return client.fit(fit_ins)\n           ^^^^^^^^^^^^^^^^^^^\n  File "C:\\Users\\Stavros\\miniconda3\\envs\\pyt_pg\\Lib\\site-packages\\flwr\\client\\numpy_client.py", line 238, in _fit\n    results = self.numpy_client.fit(parameters, ins.config)  # type: ignore\n              ^^^^^^^^^^^^^^^^^^^^^^^^^^^^^^^^^^^^^^^^^^^^^\n  File "C:\\Users\\Stavros\\Desktop\\PythonProjects\\FlowerYtTut\\client_scaffold.py", line 67, in fit\n    self.set_parameters(parameters)\n  File "C:\\Users\\Stavros\\Desktop\\PythonProjects\\FlowerYtTut\\client_scaffold.py", line 52, in set_parameters\n    self.model.load_state_dict(state_dict, strict=True)\n  File "C:\\Users\\Stavros\\miniconda3\\envs\\pyt_pg\\Lib\\site-packages\\torch\\nn\\modules\\module.py", line 2138, in load_state_dict\n    load(self, state_dict)\n  File "C:\\Users\\Stavros\\miniconda3\\envs\\pyt_pg\\Lib\\site-packages\\torch\\nn\\modules\\module.py", line 2126, in load\n    load(child, child_state_dict, child_prefix)\n  File "C:\\Users\\Stavros\\miniconda3\\envs\\pyt_pg\\Lib\\site-packages\\torch\\nn\\modules\\module.py", line 2126, in load\n    load(child, child_state_dict, child_prefix)\n  File "C:\\Users\\Stavros\\miniconda3\\envs\\pyt_pg\\Lib\\site-packages\\torch\\nn\\modules\\module.py", line 2120, in load\n    module._load_from_state_dict(\n  File "C:\\Users\\Stavros\\miniconda3\\envs\\pyt_pg\\Lib\\site-packages\\torch\\nn\\modules\\batchnorm.py", line 110, in _load_from_state_dict\n    super()._load_from_state_dict(\n  File "C:\\Users\\Stavros\\miniconda3\\envs\\pyt_pg\\Lib\\site-packages\\torch\\nn\\modules\\module.py", line 2015, in _load_from_state_dict\n    input_param = input_param[0]\n                  ~~~~~~~~~~~^^^\nIndexError: index 0 is out of bounds for dimension 0 with size 0\n',)
[2024-02-17 17:39:01,538][flwr][ERROR] - Traceback (most recent call last):
  File "C:\Users\Stavros\miniconda3\envs\pyt_pg\Lib\site-packages\flwr\simulation\ray_transport\ray_client_proxy.py", line 151, in _submit_job
    res, updated_context = self.actor_pool.get_client_result(self.cid, timeout)
                           ^^^^^^^^^^^^^^^^^^^^^^^^^^^^^^^^^^^^^^^^^^^^^^^^^^^^
  File "C:\Users\Stavros\miniconda3\envs\pyt_pg\Lib\site-packages\flwr\simulation\ray_transport\ray_actor.py", line 425, in get_client_result
    return self._fetch_future_result(cid)
           ^^^^^^^^^^^^^^^^^^^^^^^^^^^^^^
  File "C:\Users\Stavros\miniconda3\envs\pyt_pg\Lib\site-packages\flwr\simulation\ray_transport\ray_actor.py", line 306, in _fetch_future_result
    res_cid, res, updated_context = ray.get(
                                    ^^^^^^^^
  File "C:\Users\Stavros\miniconda3\envs\pyt_pg\Lib\site-packages\ray\_private\auto_init_hook.py", line 24, in auto_init_wrapper
    return fn(*args, **kwargs)
           ^^^^^^^^^^^^^^^^^^^
  File "C:\Users\Stavros\miniconda3\envs\pyt_pg\Lib\site-packages\ray\_private\client_mode_hook.py", line 103, in wrapper
    return func(*args, **kwargs)
           ^^^^^^^^^^^^^^^^^^^^^
  File "C:\Users\Stavros\miniconda3\envs\pyt_pg\Lib\site-packages\ray\_private\worker.py", line 2524, in get
    raise value.as_instanceof_cause()
ray.exceptions.RayTaskError(ClientException): [36mray::DefaultActor.run()[39m (pid=1544, ip=127.0.0.1, actor_id=6b72c74b3aa8cd5035cce1c501000000, repr=<flwr.simulation.ray_transport.ray_actor.DefaultActor object at 0x000001F2ED593190>)
                  ^^^^^^^^^^^^^^
  File "C:\Users\Stavros\miniconda3\envs\pyt_pg\Lib\site-packages\flwr\simulation\ray_transport\ray_client_proxy.py", line 207, in fit
    return maybe_call_fit(
           ^^^^^^^^^^^^^^^
  File "C:\Users\Stavros\miniconda3\envs\pyt_pg\Lib\site-packages\flwr\client\client.py", line 234, in maybe_call_fit
    return client.fit(fit_ins)
           ^^^^^^^^^^^^^^^^^^^
  File "C:\Users\Stavros\miniconda3\envs\pyt_pg\Lib\site-packages\flwr\client\numpy_client.py", line 238, in _fit
    results = self.numpy_client.fit(parameters, ins.config)  # type: ignore
              ^^^^^^^^^^^^^^^^^^^^^^^^^^^^^^^^^^^^^^^^^^^^^
  File "C:\Users\Stavros\Desktop\PythonProjects\FlowerYtTut\client_scaffold.py", line 67, in fit
    self.set_parameters(parameters)
  File "C:\Users\Stavros\Desktop\PythonProjects\FlowerYtTut\client_scaffold.py", line 52, in set_parameters
    self.model.load_state_dict(state_dict, strict=True)
  File "C:\Users\Stavros\miniconda3\envs\pyt_pg\Lib\site-packages\torch\nn\modules\module.py", line 2138, in load_state_dict
    load(self, state_dict)
  File "C:\Users\Stavros\miniconda3\envs\pyt_pg\Lib\site-packages\torch\nn\modules\module.py", line 2126, in load
    load(child, child_state_dict, child_prefix)
  File "C:\Users\Stavros\miniconda3\envs\pyt_pg\Lib\site-packages\torch\nn\modules\module.py", line 2126, in load
    load(child, child_state_dict, child_prefix)
  File "C:\Users\Stavros\miniconda3\envs\pyt_pg\Lib\site-packages\torch\nn\modules\module.py", line 2120, in load
    module._load_from_state_dict(
  File "C:\Users\Stavros\miniconda3\envs\pyt_pg\Lib\site-packages\torch\nn\modules\batchnorm.py", line 110, in _load_from_state_dict
    super()._load_from_state_dict(
  File "C:\Users\Stavros\miniconda3\envs\pyt_pg\Lib\site-packages\torch\nn\modules\module.py", line 2015, in _load_from_state_dict
    input_param = input_param[0]
                  ~~~~~~~~~~~^^^
IndexError: index 0 is out of bounds for dimension 0 with size 0

The above exception was the direct cause of the following exception:

[36mray::DefaultActor.run()[39m (pid=1544, ip=127.0.0.1, actor_id=6b72c74b3aa8cd5035cce1c501000000, repr=<flwr.simulation.ray_transport.ray_actor.DefaultActor object at 0x000001F2ED593190>)
  File "python\ray\_raylet.pyx", line 1418, in ray._raylet.execute_task
  File "python\ray\_raylet.pyx", line 1498, in ray._raylet.execute_task
  File "python\ray\_raylet.pyx", line 1424, in ray._raylet.execute_task
  File "python\ray\_raylet.pyx", line 1364, in ray._raylet.execute_task.function_executor
  File "C:\Users\Stavros\miniconda3\envs\pyt_pg\Lib\site-packages\ray\_private\function_manager.py", line 726, in actor_method_executor
    return method(__ray_actor, *args, **kwargs)
           ^^^^^^^^^^^^^^^^^^^^^^^^^^^^^^^^^^^^
  File "C:\Users\Stavros\miniconda3\envs\pyt_pg\Lib\site-packages\ray\util\tracing\tracing_helper.py", line 464, in _resume_span
    return method(self, *_args, **_kwargs)
           ^^^^^^^^^^^^^^^^^^^^^^^^^^^^^^^
  File "C:\Users\Stavros\miniconda3\envs\pyt_pg\Lib\site-packages\flwr\simulation\ray_transport\ray_actor.py", line 90, in run
    raise ClientException(str(message)) from ex
flwr.simulation.ray_transport.ray_actor.ClientException: 
>>>>>>>A ClientException occurred.('\n\tSomething went wrong when running your client run.\n\tClient 76 crashed when the DefaultActor was running its run.\n\tException triggered on the client side: Traceback (most recent call last):\n  File "C:\\Users\\Stavros\\miniconda3\\envs\\pyt_pg\\Lib\\site-packages\\flwr\\simulation\\ray_transport\\ray_actor.py", line 76, in run\n    job_results = job_fn(client)\n                  ^^^^^^^^^^^^^^\n  File "C:\\Users\\Stavros\\miniconda3\\envs\\pyt_pg\\Lib\\site-packages\\flwr\\simulation\\ray_transport\\ray_client_proxy.py", line 207, in fit\n    return maybe_call_fit(\n           ^^^^^^^^^^^^^^^\n  File "C:\\Users\\Stavros\\miniconda3\\envs\\pyt_pg\\Lib\\site-packages\\flwr\\client\\client.py", line 234, in maybe_call_fit\n    return client.fit(fit_ins)\n           ^^^^^^^^^^^^^^^^^^^\n  File "C:\\Users\\Stavros\\miniconda3\\envs\\pyt_pg\\Lib\\site-packages\\flwr\\client\\numpy_client.py", line 238, in _fit\n    results = self.numpy_client.fit(parameters, ins.config)  # type: ignore\n              ^^^^^^^^^^^^^^^^^^^^^^^^^^^^^^^^^^^^^^^^^^^^^\n  File "C:\\Users\\Stavros\\Desktop\\PythonProjects\\FlowerYtTut\\client_scaffold.py", line 67, in fit\n    self.set_parameters(parameters)\n  File "C:\\Users\\Stavros\\Desktop\\PythonProjects\\FlowerYtTut\\client_scaffold.py", line 52, in set_parameters\n    self.model.load_state_dict(state_dict, strict=True)\n  File "C:\\Users\\Stavros\\miniconda3\\envs\\pyt_pg\\Lib\\site-packages\\torch\\nn\\modules\\module.py", line 2138, in load_state_dict\n    load(self, state_dict)\n  File "C:\\Users\\Stavros\\miniconda3\\envs\\pyt_pg\\Lib\\site-packages\\torch\\nn\\modules\\module.py", line 2126, in load\n    load(child, child_state_dict, child_prefix)\n  File "C:\\Users\\Stavros\\miniconda3\\envs\\pyt_pg\\Lib\\site-packages\\torch\\nn\\modules\\module.py", line 2126, in load\n    load(child, child_state_dict, child_prefix)\n  File "C:\\Users\\Stavros\\miniconda3\\envs\\pyt_pg\\Lib\\site-packages\\torch\\nn\\modules\\module.py", line 2120, in load\n    module._load_from_state_dict(\n  File "C:\\Users\\Stavros\\miniconda3\\envs\\pyt_pg\\Lib\\site-packages\\torch\\nn\\modules\\batchnorm.py", line 110, in _load_from_state_dict\n    super()._load_from_state_dict(\n  File "C:\\Users\\Stavros\\miniconda3\\envs\\pyt_pg\\Lib\\site-packages\\torch\\nn\\modules\\module.py", line 2015, in _load_from_state_dict\n    input_param = input_param[0]\n                  ~~~~~~~~~~~^^^\nIndexError: index 0 is out of bounds for dimension 0 with size 0\n',)

[2024-02-17 17:39:01,555][flwr][ERROR] - [36mray::DefaultActor.run()[39m (pid=1544, ip=127.0.0.1, actor_id=6b72c74b3aa8cd5035cce1c501000000, repr=<flwr.simulation.ray_transport.ray_actor.DefaultActor object at 0x000001F2ED593190>)
                  ^^^^^^^^^^^^^^
  File "C:\Users\Stavros\miniconda3\envs\pyt_pg\Lib\site-packages\flwr\simulation\ray_transport\ray_client_proxy.py", line 207, in fit
    return maybe_call_fit(
           ^^^^^^^^^^^^^^^
  File "C:\Users\Stavros\miniconda3\envs\pyt_pg\Lib\site-packages\flwr\client\client.py", line 234, in maybe_call_fit
    return client.fit(fit_ins)
           ^^^^^^^^^^^^^^^^^^^
  File "C:\Users\Stavros\miniconda3\envs\pyt_pg\Lib\site-packages\flwr\client\numpy_client.py", line 238, in _fit
    results = self.numpy_client.fit(parameters, ins.config)  # type: ignore
              ^^^^^^^^^^^^^^^^^^^^^^^^^^^^^^^^^^^^^^^^^^^^^
  File "C:\Users\Stavros\Desktop\PythonProjects\FlowerYtTut\client_scaffold.py", line 67, in fit
    self.set_parameters(parameters)
  File "C:\Users\Stavros\Desktop\PythonProjects\FlowerYtTut\client_scaffold.py", line 52, in set_parameters
    self.model.load_state_dict(state_dict, strict=True)
  File "C:\Users\Stavros\miniconda3\envs\pyt_pg\Lib\site-packages\torch\nn\modules\module.py", line 2138, in load_state_dict
    load(self, state_dict)
  File "C:\Users\Stavros\miniconda3\envs\pyt_pg\Lib\site-packages\torch\nn\modules\module.py", line 2126, in load
    load(child, child_state_dict, child_prefix)
  File "C:\Users\Stavros\miniconda3\envs\pyt_pg\Lib\site-packages\torch\nn\modules\module.py", line 2126, in load
    load(child, child_state_dict, child_prefix)
  File "C:\Users\Stavros\miniconda3\envs\pyt_pg\Lib\site-packages\torch\nn\modules\module.py", line 2120, in load
    module._load_from_state_dict(
  File "C:\Users\Stavros\miniconda3\envs\pyt_pg\Lib\site-packages\torch\nn\modules\batchnorm.py", line 110, in _load_from_state_dict
    super()._load_from_state_dict(
  File "C:\Users\Stavros\miniconda3\envs\pyt_pg\Lib\site-packages\torch\nn\modules\module.py", line 2015, in _load_from_state_dict
    input_param = input_param[0]
                  ~~~~~~~~~~~^^^
IndexError: index 0 is out of bounds for dimension 0 with size 0

The above exception was the direct cause of the following exception:

[36mray::DefaultActor.run()[39m (pid=1544, ip=127.0.0.1, actor_id=6b72c74b3aa8cd5035cce1c501000000, repr=<flwr.simulation.ray_transport.ray_actor.DefaultActor object at 0x000001F2ED593190>)
  File "python\ray\_raylet.pyx", line 1418, in ray._raylet.execute_task
  File "python\ray\_raylet.pyx", line 1498, in ray._raylet.execute_task
  File "python\ray\_raylet.pyx", line 1424, in ray._raylet.execute_task
  File "python\ray\_raylet.pyx", line 1364, in ray._raylet.execute_task.function_executor
  File "C:\Users\Stavros\miniconda3\envs\pyt_pg\Lib\site-packages\ray\_private\function_manager.py", line 726, in actor_method_executor
    return method(__ray_actor, *args, **kwargs)
           ^^^^^^^^^^^^^^^^^^^^^^^^^^^^^^^^^^^^
  File "C:\Users\Stavros\miniconda3\envs\pyt_pg\Lib\site-packages\ray\util\tracing\tracing_helper.py", line 464, in _resume_span
    return method(self, *_args, **_kwargs)
           ^^^^^^^^^^^^^^^^^^^^^^^^^^^^^^^
  File "C:\Users\Stavros\miniconda3\envs\pyt_pg\Lib\site-packages\flwr\simulation\ray_transport\ray_actor.py", line 90, in run
    raise ClientException(str(message)) from ex
flwr.simulation.ray_transport.ray_actor.ClientException: 
>>>>>>>A ClientException occurred.('\n\tSomething went wrong when running your client run.\n\tClient 76 crashed when the DefaultActor was running its run.\n\tException triggered on the client side: Traceback (most recent call last):\n  File "C:\\Users\\Stavros\\miniconda3\\envs\\pyt_pg\\Lib\\site-packages\\flwr\\simulation\\ray_transport\\ray_actor.py", line 76, in run\n    job_results = job_fn(client)\n                  ^^^^^^^^^^^^^^\n  File "C:\\Users\\Stavros\\miniconda3\\envs\\pyt_pg\\Lib\\site-packages\\flwr\\simulation\\ray_transport\\ray_client_proxy.py", line 207, in fit\n    return maybe_call_fit(\n           ^^^^^^^^^^^^^^^\n  File "C:\\Users\\Stavros\\miniconda3\\envs\\pyt_pg\\Lib\\site-packages\\flwr\\client\\client.py", line 234, in maybe_call_fit\n    return client.fit(fit_ins)\n           ^^^^^^^^^^^^^^^^^^^\n  File "C:\\Users\\Stavros\\miniconda3\\envs\\pyt_pg\\Lib\\site-packages\\flwr\\client\\numpy_client.py", line 238, in _fit\n    results = self.numpy_client.fit(parameters, ins.config)  # type: ignore\n              ^^^^^^^^^^^^^^^^^^^^^^^^^^^^^^^^^^^^^^^^^^^^^\n  File "C:\\Users\\Stavros\\Desktop\\PythonProjects\\FlowerYtTut\\client_scaffold.py", line 67, in fit\n    self.set_parameters(parameters)\n  File "C:\\Users\\Stavros\\Desktop\\PythonProjects\\FlowerYtTut\\client_scaffold.py", line 52, in set_parameters\n    self.model.load_state_dict(state_dict, strict=True)\n  File "C:\\Users\\Stavros\\miniconda3\\envs\\pyt_pg\\Lib\\site-packages\\torch\\nn\\modules\\module.py", line 2138, in load_state_dict\n    load(self, state_dict)\n  File "C:\\Users\\Stavros\\miniconda3\\envs\\pyt_pg\\Lib\\site-packages\\torch\\nn\\modules\\module.py", line 2126, in load\n    load(child, child_state_dict, child_prefix)\n  File "C:\\Users\\Stavros\\miniconda3\\envs\\pyt_pg\\Lib\\site-packages\\torch\\nn\\modules\\module.py", line 2126, in load\n    load(child, child_state_dict, child_prefix)\n  File "C:\\Users\\Stavros\\miniconda3\\envs\\pyt_pg\\Lib\\site-packages\\torch\\nn\\modules\\module.py", line 2120, in load\n    module._load_from_state_dict(\n  File "C:\\Users\\Stavros\\miniconda3\\envs\\pyt_pg\\Lib\\site-packages\\torch\\nn\\modules\\batchnorm.py", line 110, in _load_from_state_dict\n    super()._load_from_state_dict(\n  File "C:\\Users\\Stavros\\miniconda3\\envs\\pyt_pg\\Lib\\site-packages\\torch\\nn\\modules\\module.py", line 2015, in _load_from_state_dict\n    input_param = input_param[0]\n                  ~~~~~~~~~~~^^^\nIndexError: index 0 is out of bounds for dimension 0 with size 0\n',)
[2024-02-17 17:39:02,577][flwr][ERROR] - Traceback (most recent call last):
  File "C:\Users\Stavros\miniconda3\envs\pyt_pg\Lib\site-packages\flwr\simulation\ray_transport\ray_client_proxy.py", line 151, in _submit_job
    res, updated_context = self.actor_pool.get_client_result(self.cid, timeout)
                           ^^^^^^^^^^^^^^^^^^^^^^^^^^^^^^^^^^^^^^^^^^^^^^^^^^^^
  File "C:\Users\Stavros\miniconda3\envs\pyt_pg\Lib\site-packages\flwr\simulation\ray_transport\ray_actor.py", line 425, in get_client_result
    return self._fetch_future_result(cid)
           ^^^^^^^^^^^^^^^^^^^^^^^^^^^^^^
  File "C:\Users\Stavros\miniconda3\envs\pyt_pg\Lib\site-packages\flwr\simulation\ray_transport\ray_actor.py", line 306, in _fetch_future_result
    res_cid, res, updated_context = ray.get(
                                    ^^^^^^^^
  File "C:\Users\Stavros\miniconda3\envs\pyt_pg\Lib\site-packages\ray\_private\auto_init_hook.py", line 24, in auto_init_wrapper
    return fn(*args, **kwargs)
           ^^^^^^^^^^^^^^^^^^^
  File "C:\Users\Stavros\miniconda3\envs\pyt_pg\Lib\site-packages\ray\_private\client_mode_hook.py", line 103, in wrapper
    return func(*args, **kwargs)
           ^^^^^^^^^^^^^^^^^^^^^
  File "C:\Users\Stavros\miniconda3\envs\pyt_pg\Lib\site-packages\ray\_private\worker.py", line 2524, in get
    raise value.as_instanceof_cause()
ray.exceptions.RayTaskError(ClientException): [36mray::DefaultActor.run()[39m (pid=7276, ip=127.0.0.1, actor_id=2b56f33712a0c96a8e8982de01000000, repr=<flwr.simulation.ray_transport.ray_actor.DefaultActor object at 0x0000019069371690>)
                  ^^^^^^^^^^^^^^
  File "C:\Users\Stavros\miniconda3\envs\pyt_pg\Lib\site-packages\flwr\simulation\ray_transport\ray_client_proxy.py", line 207, in fit
    return maybe_call_fit(
           ^^^^^^^^^^^^^^^
  File "C:\Users\Stavros\miniconda3\envs\pyt_pg\Lib\site-packages\flwr\client\client.py", line 234, in maybe_call_fit
    return client.fit(fit_ins)
           ^^^^^^^^^^^^^^^^^^^
  File "C:\Users\Stavros\miniconda3\envs\pyt_pg\Lib\site-packages\flwr\client\numpy_client.py", line 238, in _fit
    results = self.numpy_client.fit(parameters, ins.config)  # type: ignore
              ^^^^^^^^^^^^^^^^^^^^^^^^^^^^^^^^^^^^^^^^^^^^^
  File "C:\Users\Stavros\Desktop\PythonProjects\FlowerYtTut\client_scaffold.py", line 67, in fit
    self.set_parameters(parameters)
  File "C:\Users\Stavros\Desktop\PythonProjects\FlowerYtTut\client_scaffold.py", line 52, in set_parameters
    self.model.load_state_dict(state_dict, strict=True)
  File "C:\Users\Stavros\miniconda3\envs\pyt_pg\Lib\site-packages\torch\nn\modules\module.py", line 2138, in load_state_dict
    load(self, state_dict)
  File "C:\Users\Stavros\miniconda3\envs\pyt_pg\Lib\site-packages\torch\nn\modules\module.py", line 2126, in load
    load(child, child_state_dict, child_prefix)
  File "C:\Users\Stavros\miniconda3\envs\pyt_pg\Lib\site-packages\torch\nn\modules\module.py", line 2126, in load
    load(child, child_state_dict, child_prefix)
  File "C:\Users\Stavros\miniconda3\envs\pyt_pg\Lib\site-packages\torch\nn\modules\module.py", line 2120, in load
    module._load_from_state_dict(
  File "C:\Users\Stavros\miniconda3\envs\pyt_pg\Lib\site-packages\torch\nn\modules\batchnorm.py", line 110, in _load_from_state_dict
    super()._load_from_state_dict(
  File "C:\Users\Stavros\miniconda3\envs\pyt_pg\Lib\site-packages\torch\nn\modules\module.py", line 2015, in _load_from_state_dict
    input_param = input_param[0]
                  ~~~~~~~~~~~^^^
IndexError: index 0 is out of bounds for dimension 0 with size 0

The above exception was the direct cause of the following exception:

[36mray::DefaultActor.run()[39m (pid=7276, ip=127.0.0.1, actor_id=2b56f33712a0c96a8e8982de01000000, repr=<flwr.simulation.ray_transport.ray_actor.DefaultActor object at 0x0000019069371690>)
  File "python\ray\_raylet.pyx", line 1418, in ray._raylet.execute_task
  File "python\ray\_raylet.pyx", line 1498, in ray._raylet.execute_task
  File "python\ray\_raylet.pyx", line 1424, in ray._raylet.execute_task
  File "python\ray\_raylet.pyx", line 1364, in ray._raylet.execute_task.function_executor
  File "C:\Users\Stavros\miniconda3\envs\pyt_pg\Lib\site-packages\ray\_private\function_manager.py", line 726, in actor_method_executor
    return method(__ray_actor, *args, **kwargs)
           ^^^^^^^^^^^^^^^^^^^^^^^^^^^^^^^^^^^^
  File "C:\Users\Stavros\miniconda3\envs\pyt_pg\Lib\site-packages\ray\util\tracing\tracing_helper.py", line 464, in _resume_span
    return method(self, *_args, **_kwargs)
           ^^^^^^^^^^^^^^^^^^^^^^^^^^^^^^^
  File "C:\Users\Stavros\miniconda3\envs\pyt_pg\Lib\site-packages\flwr\simulation\ray_transport\ray_actor.py", line 90, in run
    raise ClientException(str(message)) from ex
flwr.simulation.ray_transport.ray_actor.ClientException: 
>>>>>>>A ClientException occurred.('\n\tSomething went wrong when running your client run.\n\tClient 63 crashed when the DefaultActor was running its run.\n\tException triggered on the client side: Traceback (most recent call last):\n  File "C:\\Users\\Stavros\\miniconda3\\envs\\pyt_pg\\Lib\\site-packages\\flwr\\simulation\\ray_transport\\ray_actor.py", line 76, in run\n    job_results = job_fn(client)\n                  ^^^^^^^^^^^^^^\n  File "C:\\Users\\Stavros\\miniconda3\\envs\\pyt_pg\\Lib\\site-packages\\flwr\\simulation\\ray_transport\\ray_client_proxy.py", line 207, in fit\n    return maybe_call_fit(\n           ^^^^^^^^^^^^^^^\n  File "C:\\Users\\Stavros\\miniconda3\\envs\\pyt_pg\\Lib\\site-packages\\flwr\\client\\client.py", line 234, in maybe_call_fit\n    return client.fit(fit_ins)\n           ^^^^^^^^^^^^^^^^^^^\n  File "C:\\Users\\Stavros\\miniconda3\\envs\\pyt_pg\\Lib\\site-packages\\flwr\\client\\numpy_client.py", line 238, in _fit\n    results = self.numpy_client.fit(parameters, ins.config)  # type: ignore\n              ^^^^^^^^^^^^^^^^^^^^^^^^^^^^^^^^^^^^^^^^^^^^^\n  File "C:\\Users\\Stavros\\Desktop\\PythonProjects\\FlowerYtTut\\client_scaffold.py", line 67, in fit\n    self.set_parameters(parameters)\n  File "C:\\Users\\Stavros\\Desktop\\PythonProjects\\FlowerYtTut\\client_scaffold.py", line 52, in set_parameters\n    self.model.load_state_dict(state_dict, strict=True)\n  File "C:\\Users\\Stavros\\miniconda3\\envs\\pyt_pg\\Lib\\site-packages\\torch\\nn\\modules\\module.py", line 2138, in load_state_dict\n    load(self, state_dict)\n  File "C:\\Users\\Stavros\\miniconda3\\envs\\pyt_pg\\Lib\\site-packages\\torch\\nn\\modules\\module.py", line 2126, in load\n    load(child, child_state_dict, child_prefix)\n  File "C:\\Users\\Stavros\\miniconda3\\envs\\pyt_pg\\Lib\\site-packages\\torch\\nn\\modules\\module.py", line 2126, in load\n    load(child, child_state_dict, child_prefix)\n  File "C:\\Users\\Stavros\\miniconda3\\envs\\pyt_pg\\Lib\\site-packages\\torch\\nn\\modules\\module.py", line 2120, in load\n    module._load_from_state_dict(\n  File "C:\\Users\\Stavros\\miniconda3\\envs\\pyt_pg\\Lib\\site-packages\\torch\\nn\\modules\\batchnorm.py", line 110, in _load_from_state_dict\n    super()._load_from_state_dict(\n  File "C:\\Users\\Stavros\\miniconda3\\envs\\pyt_pg\\Lib\\site-packages\\torch\\nn\\modules\\module.py", line 2015, in _load_from_state_dict\n    input_param = input_param[0]\n                  ~~~~~~~~~~~^^^\nIndexError: index 0 is out of bounds for dimension 0 with size 0\n',)

[2024-02-17 17:39:02,593][flwr][ERROR] - [36mray::DefaultActor.run()[39m (pid=7276, ip=127.0.0.1, actor_id=2b56f33712a0c96a8e8982de01000000, repr=<flwr.simulation.ray_transport.ray_actor.DefaultActor object at 0x0000019069371690>)
                  ^^^^^^^^^^^^^^
  File "C:\Users\Stavros\miniconda3\envs\pyt_pg\Lib\site-packages\flwr\simulation\ray_transport\ray_client_proxy.py", line 207, in fit
    return maybe_call_fit(
           ^^^^^^^^^^^^^^^
  File "C:\Users\Stavros\miniconda3\envs\pyt_pg\Lib\site-packages\flwr\client\client.py", line 234, in maybe_call_fit
    return client.fit(fit_ins)
           ^^^^^^^^^^^^^^^^^^^
  File "C:\Users\Stavros\miniconda3\envs\pyt_pg\Lib\site-packages\flwr\client\numpy_client.py", line 238, in _fit
    results = self.numpy_client.fit(parameters, ins.config)  # type: ignore
              ^^^^^^^^^^^^^^^^^^^^^^^^^^^^^^^^^^^^^^^^^^^^^
  File "C:\Users\Stavros\Desktop\PythonProjects\FlowerYtTut\client_scaffold.py", line 67, in fit
    self.set_parameters(parameters)
  File "C:\Users\Stavros\Desktop\PythonProjects\FlowerYtTut\client_scaffold.py", line 52, in set_parameters
    self.model.load_state_dict(state_dict, strict=True)
  File "C:\Users\Stavros\miniconda3\envs\pyt_pg\Lib\site-packages\torch\nn\modules\module.py", line 2138, in load_state_dict
    load(self, state_dict)
  File "C:\Users\Stavros\miniconda3\envs\pyt_pg\Lib\site-packages\torch\nn\modules\module.py", line 2126, in load
    load(child, child_state_dict, child_prefix)
  File "C:\Users\Stavros\miniconda3\envs\pyt_pg\Lib\site-packages\torch\nn\modules\module.py", line 2126, in load
    load(child, child_state_dict, child_prefix)
  File "C:\Users\Stavros\miniconda3\envs\pyt_pg\Lib\site-packages\torch\nn\modules\module.py", line 2120, in load
    module._load_from_state_dict(
  File "C:\Users\Stavros\miniconda3\envs\pyt_pg\Lib\site-packages\torch\nn\modules\batchnorm.py", line 110, in _load_from_state_dict
    super()._load_from_state_dict(
  File "C:\Users\Stavros\miniconda3\envs\pyt_pg\Lib\site-packages\torch\nn\modules\module.py", line 2015, in _load_from_state_dict
    input_param = input_param[0]
                  ~~~~~~~~~~~^^^
IndexError: index 0 is out of bounds for dimension 0 with size 0

The above exception was the direct cause of the following exception:

[36mray::DefaultActor.run()[39m (pid=7276, ip=127.0.0.1, actor_id=2b56f33712a0c96a8e8982de01000000, repr=<flwr.simulation.ray_transport.ray_actor.DefaultActor object at 0x0000019069371690>)
  File "python\ray\_raylet.pyx", line 1418, in ray._raylet.execute_task
  File "python\ray\_raylet.pyx", line 1498, in ray._raylet.execute_task
  File "python\ray\_raylet.pyx", line 1424, in ray._raylet.execute_task
  File "python\ray\_raylet.pyx", line 1364, in ray._raylet.execute_task.function_executor
  File "C:\Users\Stavros\miniconda3\envs\pyt_pg\Lib\site-packages\ray\_private\function_manager.py", line 726, in actor_method_executor
    return method(__ray_actor, *args, **kwargs)
           ^^^^^^^^^^^^^^^^^^^^^^^^^^^^^^^^^^^^
  File "C:\Users\Stavros\miniconda3\envs\pyt_pg\Lib\site-packages\ray\util\tracing\tracing_helper.py", line 464, in _resume_span
    return method(self, *_args, **_kwargs)
           ^^^^^^^^^^^^^^^^^^^^^^^^^^^^^^^
  File "C:\Users\Stavros\miniconda3\envs\pyt_pg\Lib\site-packages\flwr\simulation\ray_transport\ray_actor.py", line 90, in run
    raise ClientException(str(message)) from ex
flwr.simulation.ray_transport.ray_actor.ClientException: 
>>>>>>>A ClientException occurred.('\n\tSomething went wrong when running your client run.\n\tClient 63 crashed when the DefaultActor was running its run.\n\tException triggered on the client side: Traceback (most recent call last):\n  File "C:\\Users\\Stavros\\miniconda3\\envs\\pyt_pg\\Lib\\site-packages\\flwr\\simulation\\ray_transport\\ray_actor.py", line 76, in run\n    job_results = job_fn(client)\n                  ^^^^^^^^^^^^^^\n  File "C:\\Users\\Stavros\\miniconda3\\envs\\pyt_pg\\Lib\\site-packages\\flwr\\simulation\\ray_transport\\ray_client_proxy.py", line 207, in fit\n    return maybe_call_fit(\n           ^^^^^^^^^^^^^^^\n  File "C:\\Users\\Stavros\\miniconda3\\envs\\pyt_pg\\Lib\\site-packages\\flwr\\client\\client.py", line 234, in maybe_call_fit\n    return client.fit(fit_ins)\n           ^^^^^^^^^^^^^^^^^^^\n  File "C:\\Users\\Stavros\\miniconda3\\envs\\pyt_pg\\Lib\\site-packages\\flwr\\client\\numpy_client.py", line 238, in _fit\n    results = self.numpy_client.fit(parameters, ins.config)  # type: ignore\n              ^^^^^^^^^^^^^^^^^^^^^^^^^^^^^^^^^^^^^^^^^^^^^\n  File "C:\\Users\\Stavros\\Desktop\\PythonProjects\\FlowerYtTut\\client_scaffold.py", line 67, in fit\n    self.set_parameters(parameters)\n  File "C:\\Users\\Stavros\\Desktop\\PythonProjects\\FlowerYtTut\\client_scaffold.py", line 52, in set_parameters\n    self.model.load_state_dict(state_dict, strict=True)\n  File "C:\\Users\\Stavros\\miniconda3\\envs\\pyt_pg\\Lib\\site-packages\\torch\\nn\\modules\\module.py", line 2138, in load_state_dict\n    load(self, state_dict)\n  File "C:\\Users\\Stavros\\miniconda3\\envs\\pyt_pg\\Lib\\site-packages\\torch\\nn\\modules\\module.py", line 2126, in load\n    load(child, child_state_dict, child_prefix)\n  File "C:\\Users\\Stavros\\miniconda3\\envs\\pyt_pg\\Lib\\site-packages\\torch\\nn\\modules\\module.py", line 2126, in load\n    load(child, child_state_dict, child_prefix)\n  File "C:\\Users\\Stavros\\miniconda3\\envs\\pyt_pg\\Lib\\site-packages\\torch\\nn\\modules\\module.py", line 2120, in load\n    module._load_from_state_dict(\n  File "C:\\Users\\Stavros\\miniconda3\\envs\\pyt_pg\\Lib\\site-packages\\torch\\nn\\modules\\batchnorm.py", line 110, in _load_from_state_dict\n    super()._load_from_state_dict(\n  File "C:\\Users\\Stavros\\miniconda3\\envs\\pyt_pg\\Lib\\site-packages\\torch\\nn\\modules\\module.py", line 2015, in _load_from_state_dict\n    input_param = input_param[0]\n                  ~~~~~~~~~~~^^^\nIndexError: index 0 is out of bounds for dimension 0 with size 0\n',)
