[2024-02-17 19:09:19,092][flwr][WARNING] - Both server and strategy were provided, ignoring strategy
[2024-02-17 19:09:19,093][flwr][INFO] - Starting Flower simulation, config: ServerConfig(num_rounds=1, round_timeout=None)
[2024-02-17 19:09:25,568][flwr][INFO] - Flower VCE: Ray initialized with resources: {'node:127.0.0.1': 1.0, 'object_store_memory': 1289385984.0, 'memory': 2578771968.0, 'CPU': 4.0, 'node:__internal_head__': 1.0}
[2024-02-17 19:09:25,570][flwr][INFO] - Optimize your simulation with Flower VCE: https://flower.dev/docs/framework/how-to-run-simulations.html
[2024-02-17 19:09:25,571][flwr][INFO] - Flower VCE: Resources for each Virtual Client: {'num_cpus': 2, 'num_gpus': 0.0}
[2024-02-17 19:09:25,586][flwr][INFO] - Flower VCE: Creating VirtualClientEngineActorPool with 2 actors
[2024-02-17 19:09:25,587][flwr][INFO] - Initializing global parameters
[2024-02-17 19:09:25,588][flwr][INFO] - Requesting initial parameters from one random ScaffoldClient
[2024-02-17 19:09:33,314][flwr][INFO] - Received initial parameters from one random ScaffoldClient
[2024-02-17 19:09:33,343][flwr][INFO] - Evaluating initial parameters
[2024-02-17 19:12:20,505][flwr][INFO] - initial parameters (loss, other metrics): 0.023588945269584657, {'accuracy': 20.80078125}
[2024-02-17 19:12:20,505][flwr][INFO] - FL starting
[2024-02-17 19:12:20,683][flwr][DEBUG] - fit_round 1: strategy sampled 10 clients (out of 100)
[2024-02-17 19:13:16,542][flwr][ERROR] - Traceback (most recent call last):
  File "C:\Users\Stavros\miniconda3\envs\pyt_pg\Lib\site-packages\flwr\simulation\ray_transport\ray_client_proxy.py", line 151, in _submit_job
    res, updated_context = self.actor_pool.get_client_result(self.cid, timeout)
                           ^^^^^^^^^^^^^^^^^^^^^^^^^^^^^^^^^^^^^^^^^^^^^^^^^^^^
  File "C:\Users\Stavros\miniconda3\envs\pyt_pg\Lib\site-packages\flwr\simulation\ray_transport\ray_actor.py", line 425, in get_client_result
    return self._fetch_future_result(cid)
           ^^^^^^^^^^^^^^^^^^^^^^^^^^^^^^
  File "C:\Users\Stavros\miniconda3\envs\pyt_pg\Lib\site-packages\flwr\simulation\ray_transport\ray_actor.py", line 306, in _fetch_future_result
    res_cid, res, updated_context = ray.get(
                                    ^^^^^^^^
  File "C:\Users\Stavros\miniconda3\envs\pyt_pg\Lib\site-packages\ray\_private\auto_init_hook.py", line 24, in auto_init_wrapper
    return fn(*args, **kwargs)
           ^^^^^^^^^^^^^^^^^^^
  File "C:\Users\Stavros\miniconda3\envs\pyt_pg\Lib\site-packages\ray\_private\client_mode_hook.py", line 103, in wrapper
    return func(*args, **kwargs)
           ^^^^^^^^^^^^^^^^^^^^^
  File "C:\Users\Stavros\miniconda3\envs\pyt_pg\Lib\site-packages\ray\_private\worker.py", line 2524, in get
    raise value.as_instanceof_cause()
ray.exceptions.RayTaskError(ClientException): [36mray::DefaultActor.run()[39m (pid=15484, ip=127.0.0.1, actor_id=b70f75f33beb24a380ed1c8b01000000, repr=<flwr.simulation.ray_transport.ray_actor.DefaultActor object at 0x0000020FEA7FB0D0>)
                  ^^^^^^^^^^^^^^
  File "C:\Users\Stavros\miniconda3\envs\pyt_pg\Lib\site-packages\flwr\simulation\ray_transport\ray_client_proxy.py", line 207, in fit
    return maybe_call_fit(
           ^^^^^^^^^^^^^^^
  File "C:\Users\Stavros\miniconda3\envs\pyt_pg\Lib\site-packages\flwr\client\client.py", line 234, in maybe_call_fit
    return client.fit(fit_ins)
           ^^^^^^^^^^^^^^^^^^^
  File "C:\Users\Stavros\miniconda3\envs\pyt_pg\Lib\site-packages\flwr\client\numpy_client.py", line 238, in _fit
    results = self.numpy_client.fit(parameters, ins.config)  # type: ignore
              ^^^^^^^^^^^^^^^^^^^^^^^^^^^^^^^^^^^^^^^^^^^^^
  File "C:\Users\Stavros\Desktop\PythonProjects\FlowerYtTut\client_scaffold.py", line 109, in fit
    train_loss, train_acc = train_scaffold(self.model, self.trainloader, optim, epochs, self.device, server_cv, self.client_cv)
                            ^^^^^^^^^^^^^^^^^^^^^^^^^^^^^^^^^^^^^^^^^^^^^^^^^^^^^^^^^^^^^^^^^^^^^^^^^^^^^^^^^^^^^^^^^^^^^^^^^^^
  File "C:\Users\Stavros\Desktop\PythonProjects\FlowerYtTut\model.py", line 152, in train_scaffold
    optimizer.step_custom(server_cv=server_cv, client_cv=client_cv)
  File "C:\Users\Stavros\Desktop\PythonProjects\FlowerYtTut\model.py", line 132, in step_custom
    par.data.add_(s_cv - c_cv, alpha=-group["lr"])
                  ~~~~~^~~~~~
RuntimeError: The size of tensor a (64) must match the size of tensor b (3) at non-singleton dimension 3

The above exception was the direct cause of the following exception:

[36mray::DefaultActor.run()[39m (pid=15484, ip=127.0.0.1, actor_id=b70f75f33beb24a380ed1c8b01000000, repr=<flwr.simulation.ray_transport.ray_actor.DefaultActor object at 0x0000020FEA7FB0D0>)
  File "python\ray\_raylet.pyx", line 1418, in ray._raylet.execute_task
  File "python\ray\_raylet.pyx", line 1498, in ray._raylet.execute_task
  File "python\ray\_raylet.pyx", line 1424, in ray._raylet.execute_task
  File "python\ray\_raylet.pyx", line 1364, in ray._raylet.execute_task.function_executor
  File "C:\Users\Stavros\miniconda3\envs\pyt_pg\Lib\site-packages\ray\_private\function_manager.py", line 726, in actor_method_executor
    return method(__ray_actor, *args, **kwargs)
           ^^^^^^^^^^^^^^^^^^^^^^^^^^^^^^^^^^^^
  File "C:\Users\Stavros\miniconda3\envs\pyt_pg\Lib\site-packages\ray\util\tracing\tracing_helper.py", line 464, in _resume_span
    return method(self, *_args, **_kwargs)
           ^^^^^^^^^^^^^^^^^^^^^^^^^^^^^^^
  File "C:\Users\Stavros\miniconda3\envs\pyt_pg\Lib\site-packages\flwr\simulation\ray_transport\ray_actor.py", line 90, in run
    raise ClientException(str(message)) from ex
flwr.simulation.ray_transport.ray_actor.ClientException: 
>>>>>>>A ClientException occurred.('\n\tSomething went wrong when running your client run.\n\tClient 92 crashed when the DefaultActor was running its run.\n\tException triggered on the client side: Traceback (most recent call last):\n  File "C:\\Users\\Stavros\\miniconda3\\envs\\pyt_pg\\Lib\\site-packages\\flwr\\simulation\\ray_transport\\ray_actor.py", line 76, in run\n    job_results = job_fn(client)\n                  ^^^^^^^^^^^^^^\n  File "C:\\Users\\Stavros\\miniconda3\\envs\\pyt_pg\\Lib\\site-packages\\flwr\\simulation\\ray_transport\\ray_client_proxy.py", line 207, in fit\n    return maybe_call_fit(\n           ^^^^^^^^^^^^^^^\n  File "C:\\Users\\Stavros\\miniconda3\\envs\\pyt_pg\\Lib\\site-packages\\flwr\\client\\client.py", line 234, in maybe_call_fit\n    return client.fit(fit_ins)\n           ^^^^^^^^^^^^^^^^^^^\n  File "C:\\Users\\Stavros\\miniconda3\\envs\\pyt_pg\\Lib\\site-packages\\flwr\\client\\numpy_client.py", line 238, in _fit\n    results = self.numpy_client.fit(parameters, ins.config)  # type: ignore\n              ^^^^^^^^^^^^^^^^^^^^^^^^^^^^^^^^^^^^^^^^^^^^^\n  File "C:\\Users\\Stavros\\Desktop\\PythonProjects\\FlowerYtTut\\client_scaffold.py", line 109, in fit\n    train_loss, train_acc = train_scaffold(self.model, self.trainloader, optim, epochs, self.device, server_cv, self.client_cv)\n                            ^^^^^^^^^^^^^^^^^^^^^^^^^^^^^^^^^^^^^^^^^^^^^^^^^^^^^^^^^^^^^^^^^^^^^^^^^^^^^^^^^^^^^^^^^^^^^^^^^^^\n  File "C:\\Users\\Stavros\\Desktop\\PythonProjects\\FlowerYtTut\\model.py", line 152, in train_scaffold\n    optimizer.step_custom(server_cv=server_cv, client_cv=client_cv)\n  File "C:\\Users\\Stavros\\Desktop\\PythonProjects\\FlowerYtTut\\model.py", line 132, in step_custom\n    par.data.add_(s_cv - c_cv, alpha=-group["lr"])\n                  ~~~~~^~~~~~\nRuntimeError: The size of tensor a (64) must match the size of tensor b (3) at non-singleton dimension 3\n',)

[2024-02-17 19:13:16,569][flwr][ERROR] - [36mray::DefaultActor.run()[39m (pid=15484, ip=127.0.0.1, actor_id=b70f75f33beb24a380ed1c8b01000000, repr=<flwr.simulation.ray_transport.ray_actor.DefaultActor object at 0x0000020FEA7FB0D0>)
                  ^^^^^^^^^^^^^^
  File "C:\Users\Stavros\miniconda3\envs\pyt_pg\Lib\site-packages\flwr\simulation\ray_transport\ray_client_proxy.py", line 207, in fit
    return maybe_call_fit(
           ^^^^^^^^^^^^^^^
  File "C:\Users\Stavros\miniconda3\envs\pyt_pg\Lib\site-packages\flwr\client\client.py", line 234, in maybe_call_fit
    return client.fit(fit_ins)
           ^^^^^^^^^^^^^^^^^^^
  File "C:\Users\Stavros\miniconda3\envs\pyt_pg\Lib\site-packages\flwr\client\numpy_client.py", line 238, in _fit
    results = self.numpy_client.fit(parameters, ins.config)  # type: ignore
              ^^^^^^^^^^^^^^^^^^^^^^^^^^^^^^^^^^^^^^^^^^^^^
  File "C:\Users\Stavros\Desktop\PythonProjects\FlowerYtTut\client_scaffold.py", line 109, in fit
    train_loss, train_acc = train_scaffold(self.model, self.trainloader, optim, epochs, self.device, server_cv, self.client_cv)
                            ^^^^^^^^^^^^^^^^^^^^^^^^^^^^^^^^^^^^^^^^^^^^^^^^^^^^^^^^^^^^^^^^^^^^^^^^^^^^^^^^^^^^^^^^^^^^^^^^^^^
  File "C:\Users\Stavros\Desktop\PythonProjects\FlowerYtTut\model.py", line 152, in train_scaffold
    optimizer.step_custom(server_cv=server_cv, client_cv=client_cv)
  File "C:\Users\Stavros\Desktop\PythonProjects\FlowerYtTut\model.py", line 132, in step_custom
    par.data.add_(s_cv - c_cv, alpha=-group["lr"])
                  ~~~~~^~~~~~
RuntimeError: The size of tensor a (64) must match the size of tensor b (3) at non-singleton dimension 3

The above exception was the direct cause of the following exception:

[36mray::DefaultActor.run()[39m (pid=15484, ip=127.0.0.1, actor_id=b70f75f33beb24a380ed1c8b01000000, repr=<flwr.simulation.ray_transport.ray_actor.DefaultActor object at 0x0000020FEA7FB0D0>)
  File "python\ray\_raylet.pyx", line 1418, in ray._raylet.execute_task
  File "python\ray\_raylet.pyx", line 1498, in ray._raylet.execute_task
  File "python\ray\_raylet.pyx", line 1424, in ray._raylet.execute_task
  File "python\ray\_raylet.pyx", line 1364, in ray._raylet.execute_task.function_executor
  File "C:\Users\Stavros\miniconda3\envs\pyt_pg\Lib\site-packages\ray\_private\function_manager.py", line 726, in actor_method_executor
    return method(__ray_actor, *args, **kwargs)
           ^^^^^^^^^^^^^^^^^^^^^^^^^^^^^^^^^^^^
  File "C:\Users\Stavros\miniconda3\envs\pyt_pg\Lib\site-packages\ray\util\tracing\tracing_helper.py", line 464, in _resume_span
    return method(self, *_args, **_kwargs)
           ^^^^^^^^^^^^^^^^^^^^^^^^^^^^^^^
  File "C:\Users\Stavros\miniconda3\envs\pyt_pg\Lib\site-packages\flwr\simulation\ray_transport\ray_actor.py", line 90, in run
    raise ClientException(str(message)) from ex
flwr.simulation.ray_transport.ray_actor.ClientException: 
>>>>>>>A ClientException occurred.('\n\tSomething went wrong when running your client run.\n\tClient 92 crashed when the DefaultActor was running its run.\n\tException triggered on the client side: Traceback (most recent call last):\n  File "C:\\Users\\Stavros\\miniconda3\\envs\\pyt_pg\\Lib\\site-packages\\flwr\\simulation\\ray_transport\\ray_actor.py", line 76, in run\n    job_results = job_fn(client)\n                  ^^^^^^^^^^^^^^\n  File "C:\\Users\\Stavros\\miniconda3\\envs\\pyt_pg\\Lib\\site-packages\\flwr\\simulation\\ray_transport\\ray_client_proxy.py", line 207, in fit\n    return maybe_call_fit(\n           ^^^^^^^^^^^^^^^\n  File "C:\\Users\\Stavros\\miniconda3\\envs\\pyt_pg\\Lib\\site-packages\\flwr\\client\\client.py", line 234, in maybe_call_fit\n    return client.fit(fit_ins)\n           ^^^^^^^^^^^^^^^^^^^\n  File "C:\\Users\\Stavros\\miniconda3\\envs\\pyt_pg\\Lib\\site-packages\\flwr\\client\\numpy_client.py", line 238, in _fit\n    results = self.numpy_client.fit(parameters, ins.config)  # type: ignore\n              ^^^^^^^^^^^^^^^^^^^^^^^^^^^^^^^^^^^^^^^^^^^^^\n  File "C:\\Users\\Stavros\\Desktop\\PythonProjects\\FlowerYtTut\\client_scaffold.py", line 109, in fit\n    train_loss, train_acc = train_scaffold(self.model, self.trainloader, optim, epochs, self.device, server_cv, self.client_cv)\n                            ^^^^^^^^^^^^^^^^^^^^^^^^^^^^^^^^^^^^^^^^^^^^^^^^^^^^^^^^^^^^^^^^^^^^^^^^^^^^^^^^^^^^^^^^^^^^^^^^^^^\n  File "C:\\Users\\Stavros\\Desktop\\PythonProjects\\FlowerYtTut\\model.py", line 152, in train_scaffold\n    optimizer.step_custom(server_cv=server_cv, client_cv=client_cv)\n  File "C:\\Users\\Stavros\\Desktop\\PythonProjects\\FlowerYtTut\\model.py", line 132, in step_custom\n    par.data.add_(s_cv - c_cv, alpha=-group["lr"])\n                  ~~~~~^~~~~~\nRuntimeError: The size of tensor a (64) must match the size of tensor b (3) at non-singleton dimension 3\n',)
[2024-02-17 19:13:16,572][flwr][ERROR] - Traceback (most recent call last):
  File "C:\Users\Stavros\miniconda3\envs\pyt_pg\Lib\site-packages\flwr\simulation\ray_transport\ray_client_proxy.py", line 151, in _submit_job
    res, updated_context = self.actor_pool.get_client_result(self.cid, timeout)
                           ^^^^^^^^^^^^^^^^^^^^^^^^^^^^^^^^^^^^^^^^^^^^^^^^^^^^
  File "C:\Users\Stavros\miniconda3\envs\pyt_pg\Lib\site-packages\flwr\simulation\ray_transport\ray_actor.py", line 425, in get_client_result
    return self._fetch_future_result(cid)
           ^^^^^^^^^^^^^^^^^^^^^^^^^^^^^^
  File "C:\Users\Stavros\miniconda3\envs\pyt_pg\Lib\site-packages\flwr\simulation\ray_transport\ray_actor.py", line 306, in _fetch_future_result
    res_cid, res, updated_context = ray.get(
                                    ^^^^^^^^
  File "C:\Users\Stavros\miniconda3\envs\pyt_pg\Lib\site-packages\ray\_private\auto_init_hook.py", line 24, in auto_init_wrapper
    return fn(*args, **kwargs)
           ^^^^^^^^^^^^^^^^^^^
  File "C:\Users\Stavros\miniconda3\envs\pyt_pg\Lib\site-packages\ray\_private\client_mode_hook.py", line 103, in wrapper
    return func(*args, **kwargs)
           ^^^^^^^^^^^^^^^^^^^^^
  File "C:\Users\Stavros\miniconda3\envs\pyt_pg\Lib\site-packages\ray\_private\worker.py", line 2524, in get
    raise value.as_instanceof_cause()
ray.exceptions.RayTaskError(ClientException): [36mray::DefaultActor.run()[39m (pid=15840, ip=127.0.0.1, actor_id=86ae04ba45d66e99ed10d1b501000000, repr=<flwr.simulation.ray_transport.ray_actor.DefaultActor object at 0x0000028E89ADED10>)
                  ^^^^^^^^^^^^^^
  File "C:\Users\Stavros\miniconda3\envs\pyt_pg\Lib\site-packages\flwr\simulation\ray_transport\ray_client_proxy.py", line 207, in fit
    return maybe_call_fit(
           ^^^^^^^^^^^^^^^
  File "C:\Users\Stavros\miniconda3\envs\pyt_pg\Lib\site-packages\flwr\client\client.py", line 234, in maybe_call_fit
    return client.fit(fit_ins)
           ^^^^^^^^^^^^^^^^^^^
  File "C:\Users\Stavros\miniconda3\envs\pyt_pg\Lib\site-packages\flwr\client\numpy_client.py", line 238, in _fit
    results = self.numpy_client.fit(parameters, ins.config)  # type: ignore
              ^^^^^^^^^^^^^^^^^^^^^^^^^^^^^^^^^^^^^^^^^^^^^
  File "C:\Users\Stavros\Desktop\PythonProjects\FlowerYtTut\client_scaffold.py", line 109, in fit
    train_loss, train_acc = train_scaffold(self.model, self.trainloader, optim, epochs, self.device, server_cv, self.client_cv)
                            ^^^^^^^^^^^^^^^^^^^^^^^^^^^^^^^^^^^^^^^^^^^^^^^^^^^^^^^^^^^^^^^^^^^^^^^^^^^^^^^^^^^^^^^^^^^^^^^^^^^
  File "C:\Users\Stavros\Desktop\PythonProjects\FlowerYtTut\model.py", line 152, in train_scaffold
    optimizer.step_custom(server_cv=server_cv, client_cv=client_cv)
  File "C:\Users\Stavros\Desktop\PythonProjects\FlowerYtTut\model.py", line 132, in step_custom
    par.data.add_(s_cv - c_cv, alpha=-group["lr"])
                  ~~~~~^~~~~~
RuntimeError: The size of tensor a (64) must match the size of tensor b (3) at non-singleton dimension 3

The above exception was the direct cause of the following exception:

[36mray::DefaultActor.run()[39m (pid=15840, ip=127.0.0.1, actor_id=86ae04ba45d66e99ed10d1b501000000, repr=<flwr.simulation.ray_transport.ray_actor.DefaultActor object at 0x0000028E89ADED10>)
  File "python\ray\_raylet.pyx", line 1418, in ray._raylet.execute_task
  File "python\ray\_raylet.pyx", line 1498, in ray._raylet.execute_task
  File "python\ray\_raylet.pyx", line 1424, in ray._raylet.execute_task
  File "python\ray\_raylet.pyx", line 1364, in ray._raylet.execute_task.function_executor
  File "C:\Users\Stavros\miniconda3\envs\pyt_pg\Lib\site-packages\ray\_private\function_manager.py", line 726, in actor_method_executor
    return method(__ray_actor, *args, **kwargs)
           ^^^^^^^^^^^^^^^^^^^^^^^^^^^^^^^^^^^^
  File "C:\Users\Stavros\miniconda3\envs\pyt_pg\Lib\site-packages\ray\util\tracing\tracing_helper.py", line 464, in _resume_span
    return method(self, *_args, **_kwargs)
           ^^^^^^^^^^^^^^^^^^^^^^^^^^^^^^^
  File "C:\Users\Stavros\miniconda3\envs\pyt_pg\Lib\site-packages\flwr\simulation\ray_transport\ray_actor.py", line 90, in run
    raise ClientException(str(message)) from ex
flwr.simulation.ray_transport.ray_actor.ClientException: 
>>>>>>>A ClientException occurred.('\n\tSomething went wrong when running your client run.\n\tClient 96 crashed when the DefaultActor was running its run.\n\tException triggered on the client side: Traceback (most recent call last):\n  File "C:\\Users\\Stavros\\miniconda3\\envs\\pyt_pg\\Lib\\site-packages\\flwr\\simulation\\ray_transport\\ray_actor.py", line 76, in run\n    job_results = job_fn(client)\n                  ^^^^^^^^^^^^^^\n  File "C:\\Users\\Stavros\\miniconda3\\envs\\pyt_pg\\Lib\\site-packages\\flwr\\simulation\\ray_transport\\ray_client_proxy.py", line 207, in fit\n    return maybe_call_fit(\n           ^^^^^^^^^^^^^^^\n  File "C:\\Users\\Stavros\\miniconda3\\envs\\pyt_pg\\Lib\\site-packages\\flwr\\client\\client.py", line 234, in maybe_call_fit\n    return client.fit(fit_ins)\n           ^^^^^^^^^^^^^^^^^^^\n  File "C:\\Users\\Stavros\\miniconda3\\envs\\pyt_pg\\Lib\\site-packages\\flwr\\client\\numpy_client.py", line 238, in _fit\n    results = self.numpy_client.fit(parameters, ins.config)  # type: ignore\n              ^^^^^^^^^^^^^^^^^^^^^^^^^^^^^^^^^^^^^^^^^^^^^\n  File "C:\\Users\\Stavros\\Desktop\\PythonProjects\\FlowerYtTut\\client_scaffold.py", line 109, in fit\n    train_loss, train_acc = train_scaffold(self.model, self.trainloader, optim, epochs, self.device, server_cv, self.client_cv)\n                            ^^^^^^^^^^^^^^^^^^^^^^^^^^^^^^^^^^^^^^^^^^^^^^^^^^^^^^^^^^^^^^^^^^^^^^^^^^^^^^^^^^^^^^^^^^^^^^^^^^^\n  File "C:\\Users\\Stavros\\Desktop\\PythonProjects\\FlowerYtTut\\model.py", line 152, in train_scaffold\n    optimizer.step_custom(server_cv=server_cv, client_cv=client_cv)\n  File "C:\\Users\\Stavros\\Desktop\\PythonProjects\\FlowerYtTut\\model.py", line 132, in step_custom\n    par.data.add_(s_cv - c_cv, alpha=-group["lr"])\n                  ~~~~~^~~~~~\nRuntimeError: The size of tensor a (64) must match the size of tensor b (3) at non-singleton dimension 3\n',)

[2024-02-17 19:13:16,589][flwr][ERROR] - [36mray::DefaultActor.run()[39m (pid=15840, ip=127.0.0.1, actor_id=86ae04ba45d66e99ed10d1b501000000, repr=<flwr.simulation.ray_transport.ray_actor.DefaultActor object at 0x0000028E89ADED10>)
                  ^^^^^^^^^^^^^^
  File "C:\Users\Stavros\miniconda3\envs\pyt_pg\Lib\site-packages\flwr\simulation\ray_transport\ray_client_proxy.py", line 207, in fit
    return maybe_call_fit(
           ^^^^^^^^^^^^^^^
  File "C:\Users\Stavros\miniconda3\envs\pyt_pg\Lib\site-packages\flwr\client\client.py", line 234, in maybe_call_fit
    return client.fit(fit_ins)
           ^^^^^^^^^^^^^^^^^^^
  File "C:\Users\Stavros\miniconda3\envs\pyt_pg\Lib\site-packages\flwr\client\numpy_client.py", line 238, in _fit
    results = self.numpy_client.fit(parameters, ins.config)  # type: ignore
              ^^^^^^^^^^^^^^^^^^^^^^^^^^^^^^^^^^^^^^^^^^^^^
  File "C:\Users\Stavros\Desktop\PythonProjects\FlowerYtTut\client_scaffold.py", line 109, in fit
    train_loss, train_acc = train_scaffold(self.model, self.trainloader, optim, epochs, self.device, server_cv, self.client_cv)
                            ^^^^^^^^^^^^^^^^^^^^^^^^^^^^^^^^^^^^^^^^^^^^^^^^^^^^^^^^^^^^^^^^^^^^^^^^^^^^^^^^^^^^^^^^^^^^^^^^^^^
  File "C:\Users\Stavros\Desktop\PythonProjects\FlowerYtTut\model.py", line 152, in train_scaffold
    optimizer.step_custom(server_cv=server_cv, client_cv=client_cv)
  File "C:\Users\Stavros\Desktop\PythonProjects\FlowerYtTut\model.py", line 132, in step_custom
    par.data.add_(s_cv - c_cv, alpha=-group["lr"])
                  ~~~~~^~~~~~
RuntimeError: The size of tensor a (64) must match the size of tensor b (3) at non-singleton dimension 3

The above exception was the direct cause of the following exception:

[36mray::DefaultActor.run()[39m (pid=15840, ip=127.0.0.1, actor_id=86ae04ba45d66e99ed10d1b501000000, repr=<flwr.simulation.ray_transport.ray_actor.DefaultActor object at 0x0000028E89ADED10>)
  File "python\ray\_raylet.pyx", line 1418, in ray._raylet.execute_task
  File "python\ray\_raylet.pyx", line 1498, in ray._raylet.execute_task
  File "python\ray\_raylet.pyx", line 1424, in ray._raylet.execute_task
  File "python\ray\_raylet.pyx", line 1364, in ray._raylet.execute_task.function_executor
  File "C:\Users\Stavros\miniconda3\envs\pyt_pg\Lib\site-packages\ray\_private\function_manager.py", line 726, in actor_method_executor
    return method(__ray_actor, *args, **kwargs)
           ^^^^^^^^^^^^^^^^^^^^^^^^^^^^^^^^^^^^
  File "C:\Users\Stavros\miniconda3\envs\pyt_pg\Lib\site-packages\ray\util\tracing\tracing_helper.py", line 464, in _resume_span
    return method(self, *_args, **_kwargs)
           ^^^^^^^^^^^^^^^^^^^^^^^^^^^^^^^
  File "C:\Users\Stavros\miniconda3\envs\pyt_pg\Lib\site-packages\flwr\simulation\ray_transport\ray_actor.py", line 90, in run
    raise ClientException(str(message)) from ex
flwr.simulation.ray_transport.ray_actor.ClientException: 
>>>>>>>A ClientException occurred.('\n\tSomething went wrong when running your client run.\n\tClient 96 crashed when the DefaultActor was running its run.\n\tException triggered on the client side: Traceback (most recent call last):\n  File "C:\\Users\\Stavros\\miniconda3\\envs\\pyt_pg\\Lib\\site-packages\\flwr\\simulation\\ray_transport\\ray_actor.py", line 76, in run\n    job_results = job_fn(client)\n                  ^^^^^^^^^^^^^^\n  File "C:\\Users\\Stavros\\miniconda3\\envs\\pyt_pg\\Lib\\site-packages\\flwr\\simulation\\ray_transport\\ray_client_proxy.py", line 207, in fit\n    return maybe_call_fit(\n           ^^^^^^^^^^^^^^^\n  File "C:\\Users\\Stavros\\miniconda3\\envs\\pyt_pg\\Lib\\site-packages\\flwr\\client\\client.py", line 234, in maybe_call_fit\n    return client.fit(fit_ins)\n           ^^^^^^^^^^^^^^^^^^^\n  File "C:\\Users\\Stavros\\miniconda3\\envs\\pyt_pg\\Lib\\site-packages\\flwr\\client\\numpy_client.py", line 238, in _fit\n    results = self.numpy_client.fit(parameters, ins.config)  # type: ignore\n              ^^^^^^^^^^^^^^^^^^^^^^^^^^^^^^^^^^^^^^^^^^^^^\n  File "C:\\Users\\Stavros\\Desktop\\PythonProjects\\FlowerYtTut\\client_scaffold.py", line 109, in fit\n    train_loss, train_acc = train_scaffold(self.model, self.trainloader, optim, epochs, self.device, server_cv, self.client_cv)\n                            ^^^^^^^^^^^^^^^^^^^^^^^^^^^^^^^^^^^^^^^^^^^^^^^^^^^^^^^^^^^^^^^^^^^^^^^^^^^^^^^^^^^^^^^^^^^^^^^^^^^\n  File "C:\\Users\\Stavros\\Desktop\\PythonProjects\\FlowerYtTut\\model.py", line 152, in train_scaffold\n    optimizer.step_custom(server_cv=server_cv, client_cv=client_cv)\n  File "C:\\Users\\Stavros\\Desktop\\PythonProjects\\FlowerYtTut\\model.py", line 132, in step_custom\n    par.data.add_(s_cv - c_cv, alpha=-group["lr"])\n                  ~~~~~^~~~~~\nRuntimeError: The size of tensor a (64) must match the size of tensor b (3) at non-singleton dimension 3\n',)
[2024-02-17 19:14:23,579][flwr][ERROR] - Traceback (most recent call last):
  File "C:\Users\Stavros\miniconda3\envs\pyt_pg\Lib\site-packages\flwr\simulation\ray_transport\ray_client_proxy.py", line 151, in _submit_job
    res, updated_context = self.actor_pool.get_client_result(self.cid, timeout)
                           ^^^^^^^^^^^^^^^^^^^^^^^^^^^^^^^^^^^^^^^^^^^^^^^^^^^^
  File "C:\Users\Stavros\miniconda3\envs\pyt_pg\Lib\site-packages\flwr\simulation\ray_transport\ray_actor.py", line 425, in get_client_result
    return self._fetch_future_result(cid)
           ^^^^^^^^^^^^^^^^^^^^^^^^^^^^^^
  File "C:\Users\Stavros\miniconda3\envs\pyt_pg\Lib\site-packages\flwr\simulation\ray_transport\ray_actor.py", line 306, in _fetch_future_result
    res_cid, res, updated_context = ray.get(
                                    ^^^^^^^^
  File "C:\Users\Stavros\miniconda3\envs\pyt_pg\Lib\site-packages\ray\_private\auto_init_hook.py", line 24, in auto_init_wrapper
    return fn(*args, **kwargs)
           ^^^^^^^^^^^^^^^^^^^
  File "C:\Users\Stavros\miniconda3\envs\pyt_pg\Lib\site-packages\ray\_private\client_mode_hook.py", line 103, in wrapper
    return func(*args, **kwargs)
           ^^^^^^^^^^^^^^^^^^^^^
  File "C:\Users\Stavros\miniconda3\envs\pyt_pg\Lib\site-packages\ray\_private\worker.py", line 2524, in get
    raise value.as_instanceof_cause()
ray.exceptions.RayTaskError(ClientException): [36mray::DefaultActor.run()[39m (pid=15484, ip=127.0.0.1, actor_id=b70f75f33beb24a380ed1c8b01000000, repr=<flwr.simulation.ray_transport.ray_actor.DefaultActor object at 0x0000020FEA7FB0D0>)
                  ^^^^^^^^^^^^^^
  File "C:\Users\Stavros\miniconda3\envs\pyt_pg\Lib\site-packages\flwr\simulation\ray_transport\ray_client_proxy.py", line 207, in fit
    return maybe_call_fit(
           ^^^^^^^^^^^^^^^
  File "C:\Users\Stavros\miniconda3\envs\pyt_pg\Lib\site-packages\flwr\client\client.py", line 234, in maybe_call_fit
    return client.fit(fit_ins)
           ^^^^^^^^^^^^^^^^^^^
  File "C:\Users\Stavros\miniconda3\envs\pyt_pg\Lib\site-packages\flwr\client\numpy_client.py", line 238, in _fit
    results = self.numpy_client.fit(parameters, ins.config)  # type: ignore
              ^^^^^^^^^^^^^^^^^^^^^^^^^^^^^^^^^^^^^^^^^^^^^
  File "C:\Users\Stavros\Desktop\PythonProjects\FlowerYtTut\client_scaffold.py", line 109, in fit
    train_loss, train_acc = train_scaffold(self.model, self.trainloader, optim, epochs, self.device, server_cv, self.client_cv)
                            ^^^^^^^^^^^^^^^^^^^^^^^^^^^^^^^^^^^^^^^^^^^^^^^^^^^^^^^^^^^^^^^^^^^^^^^^^^^^^^^^^^^^^^^^^^^^^^^^^^^
  File "C:\Users\Stavros\Desktop\PythonProjects\FlowerYtTut\model.py", line 152, in train_scaffold
    optimizer.step_custom(server_cv=server_cv, client_cv=client_cv)
  File "C:\Users\Stavros\Desktop\PythonProjects\FlowerYtTut\model.py", line 132, in step_custom
    par.data.add_(s_cv - c_cv, alpha=-group["lr"])
                  ~~~~~^~~~~~
RuntimeError: The size of tensor a (64) must match the size of tensor b (3) at non-singleton dimension 3

The above exception was the direct cause of the following exception:

[36mray::DefaultActor.run()[39m (pid=15484, ip=127.0.0.1, actor_id=b70f75f33beb24a380ed1c8b01000000, repr=<flwr.simulation.ray_transport.ray_actor.DefaultActor object at 0x0000020FEA7FB0D0>)
  File "python\ray\_raylet.pyx", line 1418, in ray._raylet.execute_task
  File "python\ray\_raylet.pyx", line 1498, in ray._raylet.execute_task
  File "python\ray\_raylet.pyx", line 1424, in ray._raylet.execute_task
  File "python\ray\_raylet.pyx", line 1364, in ray._raylet.execute_task.function_executor
  File "C:\Users\Stavros\miniconda3\envs\pyt_pg\Lib\site-packages\ray\_private\function_manager.py", line 726, in actor_method_executor
    return method(__ray_actor, *args, **kwargs)
           ^^^^^^^^^^^^^^^^^^^^^^^^^^^^^^^^^^^^
  File "C:\Users\Stavros\miniconda3\envs\pyt_pg\Lib\site-packages\ray\util\tracing\tracing_helper.py", line 464, in _resume_span
    return method(self, *_args, **_kwargs)
           ^^^^^^^^^^^^^^^^^^^^^^^^^^^^^^^
  File "C:\Users\Stavros\miniconda3\envs\pyt_pg\Lib\site-packages\flwr\simulation\ray_transport\ray_actor.py", line 90, in run
    raise ClientException(str(message)) from ex
flwr.simulation.ray_transport.ray_actor.ClientException: 
>>>>>>>A ClientException occurred.('\n\tSomething went wrong when running your client run.\n\tClient 10 crashed when the DefaultActor was running its run.\n\tException triggered on the client side: Traceback (most recent call last):\n  File "C:\\Users\\Stavros\\miniconda3\\envs\\pyt_pg\\Lib\\site-packages\\flwr\\simulation\\ray_transport\\ray_actor.py", line 76, in run\n    job_results = job_fn(client)\n                  ^^^^^^^^^^^^^^\n  File "C:\\Users\\Stavros\\miniconda3\\envs\\pyt_pg\\Lib\\site-packages\\flwr\\simulation\\ray_transport\\ray_client_proxy.py", line 207, in fit\n    return maybe_call_fit(\n           ^^^^^^^^^^^^^^^\n  File "C:\\Users\\Stavros\\miniconda3\\envs\\pyt_pg\\Lib\\site-packages\\flwr\\client\\client.py", line 234, in maybe_call_fit\n    return client.fit(fit_ins)\n           ^^^^^^^^^^^^^^^^^^^\n  File "C:\\Users\\Stavros\\miniconda3\\envs\\pyt_pg\\Lib\\site-packages\\flwr\\client\\numpy_client.py", line 238, in _fit\n    results = self.numpy_client.fit(parameters, ins.config)  # type: ignore\n              ^^^^^^^^^^^^^^^^^^^^^^^^^^^^^^^^^^^^^^^^^^^^^\n  File "C:\\Users\\Stavros\\Desktop\\PythonProjects\\FlowerYtTut\\client_scaffold.py", line 109, in fit\n    train_loss, train_acc = train_scaffold(self.model, self.trainloader, optim, epochs, self.device, server_cv, self.client_cv)\n                            ^^^^^^^^^^^^^^^^^^^^^^^^^^^^^^^^^^^^^^^^^^^^^^^^^^^^^^^^^^^^^^^^^^^^^^^^^^^^^^^^^^^^^^^^^^^^^^^^^^^\n  File "C:\\Users\\Stavros\\Desktop\\PythonProjects\\FlowerYtTut\\model.py", line 152, in train_scaffold\n    optimizer.step_custom(server_cv=server_cv, client_cv=client_cv)\n  File "C:\\Users\\Stavros\\Desktop\\PythonProjects\\FlowerYtTut\\model.py", line 132, in step_custom\n    par.data.add_(s_cv - c_cv, alpha=-group["lr"])\n                  ~~~~~^~~~~~\nRuntimeError: The size of tensor a (64) must match the size of tensor b (3) at non-singleton dimension 3\n',)

[2024-02-17 19:14:23,638][flwr][ERROR] - [36mray::DefaultActor.run()[39m (pid=15484, ip=127.0.0.1, actor_id=b70f75f33beb24a380ed1c8b01000000, repr=<flwr.simulation.ray_transport.ray_actor.DefaultActor object at 0x0000020FEA7FB0D0>)
                  ^^^^^^^^^^^^^^
  File "C:\Users\Stavros\miniconda3\envs\pyt_pg\Lib\site-packages\flwr\simulation\ray_transport\ray_client_proxy.py", line 207, in fit
    return maybe_call_fit(
           ^^^^^^^^^^^^^^^
  File "C:\Users\Stavros\miniconda3\envs\pyt_pg\Lib\site-packages\flwr\client\client.py", line 234, in maybe_call_fit
    return client.fit(fit_ins)
           ^^^^^^^^^^^^^^^^^^^
  File "C:\Users\Stavros\miniconda3\envs\pyt_pg\Lib\site-packages\flwr\client\numpy_client.py", line 238, in _fit
    results = self.numpy_client.fit(parameters, ins.config)  # type: ignore
              ^^^^^^^^^^^^^^^^^^^^^^^^^^^^^^^^^^^^^^^^^^^^^
  File "C:\Users\Stavros\Desktop\PythonProjects\FlowerYtTut\client_scaffold.py", line 109, in fit
    train_loss, train_acc = train_scaffold(self.model, self.trainloader, optim, epochs, self.device, server_cv, self.client_cv)
                            ^^^^^^^^^^^^^^^^^^^^^^^^^^^^^^^^^^^^^^^^^^^^^^^^^^^^^^^^^^^^^^^^^^^^^^^^^^^^^^^^^^^^^^^^^^^^^^^^^^^
  File "C:\Users\Stavros\Desktop\PythonProjects\FlowerYtTut\model.py", line 152, in train_scaffold
    optimizer.step_custom(server_cv=server_cv, client_cv=client_cv)
  File "C:\Users\Stavros\Desktop\PythonProjects\FlowerYtTut\model.py", line 132, in step_custom
    par.data.add_(s_cv - c_cv, alpha=-group["lr"])
                  ~~~~~^~~~~~
RuntimeError: The size of tensor a (64) must match the size of tensor b (3) at non-singleton dimension 3

The above exception was the direct cause of the following exception:

[36mray::DefaultActor.run()[39m (pid=15484, ip=127.0.0.1, actor_id=b70f75f33beb24a380ed1c8b01000000, repr=<flwr.simulation.ray_transport.ray_actor.DefaultActor object at 0x0000020FEA7FB0D0>)
  File "python\ray\_raylet.pyx", line 1418, in ray._raylet.execute_task
  File "python\ray\_raylet.pyx", line 1498, in ray._raylet.execute_task
  File "python\ray\_raylet.pyx", line 1424, in ray._raylet.execute_task
  File "python\ray\_raylet.pyx", line 1364, in ray._raylet.execute_task.function_executor
  File "C:\Users\Stavros\miniconda3\envs\pyt_pg\Lib\site-packages\ray\_private\function_manager.py", line 726, in actor_method_executor
    return method(__ray_actor, *args, **kwargs)
           ^^^^^^^^^^^^^^^^^^^^^^^^^^^^^^^^^^^^
  File "C:\Users\Stavros\miniconda3\envs\pyt_pg\Lib\site-packages\ray\util\tracing\tracing_helper.py", line 464, in _resume_span
    return method(self, *_args, **_kwargs)
           ^^^^^^^^^^^^^^^^^^^^^^^^^^^^^^^
  File "C:\Users\Stavros\miniconda3\envs\pyt_pg\Lib\site-packages\flwr\simulation\ray_transport\ray_actor.py", line 90, in run
    raise ClientException(str(message)) from ex
flwr.simulation.ray_transport.ray_actor.ClientException: 
>>>>>>>A ClientException occurred.('\n\tSomething went wrong when running your client run.\n\tClient 10 crashed when the DefaultActor was running its run.\n\tException triggered on the client side: Traceback (most recent call last):\n  File "C:\\Users\\Stavros\\miniconda3\\envs\\pyt_pg\\Lib\\site-packages\\flwr\\simulation\\ray_transport\\ray_actor.py", line 76, in run\n    job_results = job_fn(client)\n                  ^^^^^^^^^^^^^^\n  File "C:\\Users\\Stavros\\miniconda3\\envs\\pyt_pg\\Lib\\site-packages\\flwr\\simulation\\ray_transport\\ray_client_proxy.py", line 207, in fit\n    return maybe_call_fit(\n           ^^^^^^^^^^^^^^^\n  File "C:\\Users\\Stavros\\miniconda3\\envs\\pyt_pg\\Lib\\site-packages\\flwr\\client\\client.py", line 234, in maybe_call_fit\n    return client.fit(fit_ins)\n           ^^^^^^^^^^^^^^^^^^^\n  File "C:\\Users\\Stavros\\miniconda3\\envs\\pyt_pg\\Lib\\site-packages\\flwr\\client\\numpy_client.py", line 238, in _fit\n    results = self.numpy_client.fit(parameters, ins.config)  # type: ignore\n              ^^^^^^^^^^^^^^^^^^^^^^^^^^^^^^^^^^^^^^^^^^^^^\n  File "C:\\Users\\Stavros\\Desktop\\PythonProjects\\FlowerYtTut\\client_scaffold.py", line 109, in fit\n    train_loss, train_acc = train_scaffold(self.model, self.trainloader, optim, epochs, self.device, server_cv, self.client_cv)\n                            ^^^^^^^^^^^^^^^^^^^^^^^^^^^^^^^^^^^^^^^^^^^^^^^^^^^^^^^^^^^^^^^^^^^^^^^^^^^^^^^^^^^^^^^^^^^^^^^^^^^\n  File "C:\\Users\\Stavros\\Desktop\\PythonProjects\\FlowerYtTut\\model.py", line 152, in train_scaffold\n    optimizer.step_custom(server_cv=server_cv, client_cv=client_cv)\n  File "C:\\Users\\Stavros\\Desktop\\PythonProjects\\FlowerYtTut\\model.py", line 132, in step_custom\n    par.data.add_(s_cv - c_cv, alpha=-group["lr"])\n                  ~~~~~^~~~~~\nRuntimeError: The size of tensor a (64) must match the size of tensor b (3) at non-singleton dimension 3\n',)
[2024-02-17 19:14:24,205][flwr][ERROR] - Traceback (most recent call last):
  File "C:\Users\Stavros\miniconda3\envs\pyt_pg\Lib\site-packages\flwr\simulation\ray_transport\ray_client_proxy.py", line 151, in _submit_job
    res, updated_context = self.actor_pool.get_client_result(self.cid, timeout)
                           ^^^^^^^^^^^^^^^^^^^^^^^^^^^^^^^^^^^^^^^^^^^^^^^^^^^^
  File "C:\Users\Stavros\miniconda3\envs\pyt_pg\Lib\site-packages\flwr\simulation\ray_transport\ray_actor.py", line 425, in get_client_result
    return self._fetch_future_result(cid)
           ^^^^^^^^^^^^^^^^^^^^^^^^^^^^^^
  File "C:\Users\Stavros\miniconda3\envs\pyt_pg\Lib\site-packages\flwr\simulation\ray_transport\ray_actor.py", line 306, in _fetch_future_result
    res_cid, res, updated_context = ray.get(
                                    ^^^^^^^^
  File "C:\Users\Stavros\miniconda3\envs\pyt_pg\Lib\site-packages\ray\_private\auto_init_hook.py", line 24, in auto_init_wrapper
    return fn(*args, **kwargs)
           ^^^^^^^^^^^^^^^^^^^
  File "C:\Users\Stavros\miniconda3\envs\pyt_pg\Lib\site-packages\ray\_private\client_mode_hook.py", line 103, in wrapper
    return func(*args, **kwargs)
           ^^^^^^^^^^^^^^^^^^^^^
  File "C:\Users\Stavros\miniconda3\envs\pyt_pg\Lib\site-packages\ray\_private\worker.py", line 2524, in get
    raise value.as_instanceof_cause()
ray.exceptions.RayTaskError(ClientException): [36mray::DefaultActor.run()[39m (pid=15840, ip=127.0.0.1, actor_id=86ae04ba45d66e99ed10d1b501000000, repr=<flwr.simulation.ray_transport.ray_actor.DefaultActor object at 0x0000028E89ADED10>)
                  ^^^^^^^^^^^^^^
  File "C:\Users\Stavros\miniconda3\envs\pyt_pg\Lib\site-packages\flwr\simulation\ray_transport\ray_client_proxy.py", line 207, in fit
    return maybe_call_fit(
           ^^^^^^^^^^^^^^^
  File "C:\Users\Stavros\miniconda3\envs\pyt_pg\Lib\site-packages\flwr\client\client.py", line 234, in maybe_call_fit
    return client.fit(fit_ins)
           ^^^^^^^^^^^^^^^^^^^
  File "C:\Users\Stavros\miniconda3\envs\pyt_pg\Lib\site-packages\flwr\client\numpy_client.py", line 238, in _fit
    results = self.numpy_client.fit(parameters, ins.config)  # type: ignore
              ^^^^^^^^^^^^^^^^^^^^^^^^^^^^^^^^^^^^^^^^^^^^^
  File "C:\Users\Stavros\Desktop\PythonProjects\FlowerYtTut\client_scaffold.py", line 109, in fit
    train_loss, train_acc = train_scaffold(self.model, self.trainloader, optim, epochs, self.device, server_cv, self.client_cv)
                            ^^^^^^^^^^^^^^^^^^^^^^^^^^^^^^^^^^^^^^^^^^^^^^^^^^^^^^^^^^^^^^^^^^^^^^^^^^^^^^^^^^^^^^^^^^^^^^^^^^^
  File "C:\Users\Stavros\Desktop\PythonProjects\FlowerYtTut\model.py", line 152, in train_scaffold
    optimizer.step_custom(server_cv=server_cv, client_cv=client_cv)
  File "C:\Users\Stavros\Desktop\PythonProjects\FlowerYtTut\model.py", line 132, in step_custom
    par.data.add_(s_cv - c_cv, alpha=-group["lr"])
                  ~~~~~^~~~~~
RuntimeError: The size of tensor a (64) must match the size of tensor b (3) at non-singleton dimension 3

The above exception was the direct cause of the following exception:

[36mray::DefaultActor.run()[39m (pid=15840, ip=127.0.0.1, actor_id=86ae04ba45d66e99ed10d1b501000000, repr=<flwr.simulation.ray_transport.ray_actor.DefaultActor object at 0x0000028E89ADED10>)
  File "python\ray\_raylet.pyx", line 1418, in ray._raylet.execute_task
  File "python\ray\_raylet.pyx", line 1498, in ray._raylet.execute_task
  File "python\ray\_raylet.pyx", line 1424, in ray._raylet.execute_task
  File "python\ray\_raylet.pyx", line 1364, in ray._raylet.execute_task.function_executor
  File "C:\Users\Stavros\miniconda3\envs\pyt_pg\Lib\site-packages\ray\_private\function_manager.py", line 726, in actor_method_executor
    return method(__ray_actor, *args, **kwargs)
           ^^^^^^^^^^^^^^^^^^^^^^^^^^^^^^^^^^^^
  File "C:\Users\Stavros\miniconda3\envs\pyt_pg\Lib\site-packages\ray\util\tracing\tracing_helper.py", line 464, in _resume_span
    return method(self, *_args, **_kwargs)
           ^^^^^^^^^^^^^^^^^^^^^^^^^^^^^^^
  File "C:\Users\Stavros\miniconda3\envs\pyt_pg\Lib\site-packages\flwr\simulation\ray_transport\ray_actor.py", line 90, in run
    raise ClientException(str(message)) from ex
flwr.simulation.ray_transport.ray_actor.ClientException: 
>>>>>>>A ClientException occurred.('\n\tSomething went wrong when running your client run.\n\tClient 46 crashed when the DefaultActor was running its run.\n\tException triggered on the client side: Traceback (most recent call last):\n  File "C:\\Users\\Stavros\\miniconda3\\envs\\pyt_pg\\Lib\\site-packages\\flwr\\simulation\\ray_transport\\ray_actor.py", line 76, in run\n    job_results = job_fn(client)\n                  ^^^^^^^^^^^^^^\n  File "C:\\Users\\Stavros\\miniconda3\\envs\\pyt_pg\\Lib\\site-packages\\flwr\\simulation\\ray_transport\\ray_client_proxy.py", line 207, in fit\n    return maybe_call_fit(\n           ^^^^^^^^^^^^^^^\n  File "C:\\Users\\Stavros\\miniconda3\\envs\\pyt_pg\\Lib\\site-packages\\flwr\\client\\client.py", line 234, in maybe_call_fit\n    return client.fit(fit_ins)\n           ^^^^^^^^^^^^^^^^^^^\n  File "C:\\Users\\Stavros\\miniconda3\\envs\\pyt_pg\\Lib\\site-packages\\flwr\\client\\numpy_client.py", line 238, in _fit\n    results = self.numpy_client.fit(parameters, ins.config)  # type: ignore\n              ^^^^^^^^^^^^^^^^^^^^^^^^^^^^^^^^^^^^^^^^^^^^^\n  File "C:\\Users\\Stavros\\Desktop\\PythonProjects\\FlowerYtTut\\client_scaffold.py", line 109, in fit\n    train_loss, train_acc = train_scaffold(self.model, self.trainloader, optim, epochs, self.device, server_cv, self.client_cv)\n                            ^^^^^^^^^^^^^^^^^^^^^^^^^^^^^^^^^^^^^^^^^^^^^^^^^^^^^^^^^^^^^^^^^^^^^^^^^^^^^^^^^^^^^^^^^^^^^^^^^^^\n  File "C:\\Users\\Stavros\\Desktop\\PythonProjects\\FlowerYtTut\\model.py", line 152, in train_scaffold\n    optimizer.step_custom(server_cv=server_cv, client_cv=client_cv)\n  File "C:\\Users\\Stavros\\Desktop\\PythonProjects\\FlowerYtTut\\model.py", line 132, in step_custom\n    par.data.add_(s_cv - c_cv, alpha=-group["lr"])\n                  ~~~~~^~~~~~\nRuntimeError: The size of tensor a (64) must match the size of tensor b (3) at non-singleton dimension 3\n',)

[2024-02-17 19:14:24,220][flwr][ERROR] - [36mray::DefaultActor.run()[39m (pid=15840, ip=127.0.0.1, actor_id=86ae04ba45d66e99ed10d1b501000000, repr=<flwr.simulation.ray_transport.ray_actor.DefaultActor object at 0x0000028E89ADED10>)
                  ^^^^^^^^^^^^^^
  File "C:\Users\Stavros\miniconda3\envs\pyt_pg\Lib\site-packages\flwr\simulation\ray_transport\ray_client_proxy.py", line 207, in fit
    return maybe_call_fit(
           ^^^^^^^^^^^^^^^
  File "C:\Users\Stavros\miniconda3\envs\pyt_pg\Lib\site-packages\flwr\client\client.py", line 234, in maybe_call_fit
    return client.fit(fit_ins)
           ^^^^^^^^^^^^^^^^^^^
  File "C:\Users\Stavros\miniconda3\envs\pyt_pg\Lib\site-packages\flwr\client\numpy_client.py", line 238, in _fit
    results = self.numpy_client.fit(parameters, ins.config)  # type: ignore
              ^^^^^^^^^^^^^^^^^^^^^^^^^^^^^^^^^^^^^^^^^^^^^
  File "C:\Users\Stavros\Desktop\PythonProjects\FlowerYtTut\client_scaffold.py", line 109, in fit
    train_loss, train_acc = train_scaffold(self.model, self.trainloader, optim, epochs, self.device, server_cv, self.client_cv)
                            ^^^^^^^^^^^^^^^^^^^^^^^^^^^^^^^^^^^^^^^^^^^^^^^^^^^^^^^^^^^^^^^^^^^^^^^^^^^^^^^^^^^^^^^^^^^^^^^^^^^
  File "C:\Users\Stavros\Desktop\PythonProjects\FlowerYtTut\model.py", line 152, in train_scaffold
    optimizer.step_custom(server_cv=server_cv, client_cv=client_cv)
  File "C:\Users\Stavros\Desktop\PythonProjects\FlowerYtTut\model.py", line 132, in step_custom
    par.data.add_(s_cv - c_cv, alpha=-group["lr"])
                  ~~~~~^~~~~~
RuntimeError: The size of tensor a (64) must match the size of tensor b (3) at non-singleton dimension 3

The above exception was the direct cause of the following exception:

[36mray::DefaultActor.run()[39m (pid=15840, ip=127.0.0.1, actor_id=86ae04ba45d66e99ed10d1b501000000, repr=<flwr.simulation.ray_transport.ray_actor.DefaultActor object at 0x0000028E89ADED10>)
  File "python\ray\_raylet.pyx", line 1418, in ray._raylet.execute_task
  File "python\ray\_raylet.pyx", line 1498, in ray._raylet.execute_task
  File "python\ray\_raylet.pyx", line 1424, in ray._raylet.execute_task
  File "python\ray\_raylet.pyx", line 1364, in ray._raylet.execute_task.function_executor
  File "C:\Users\Stavros\miniconda3\envs\pyt_pg\Lib\site-packages\ray\_private\function_manager.py", line 726, in actor_method_executor
    return method(__ray_actor, *args, **kwargs)
           ^^^^^^^^^^^^^^^^^^^^^^^^^^^^^^^^^^^^
  File "C:\Users\Stavros\miniconda3\envs\pyt_pg\Lib\site-packages\ray\util\tracing\tracing_helper.py", line 464, in _resume_span
    return method(self, *_args, **_kwargs)
           ^^^^^^^^^^^^^^^^^^^^^^^^^^^^^^^
  File "C:\Users\Stavros\miniconda3\envs\pyt_pg\Lib\site-packages\flwr\simulation\ray_transport\ray_actor.py", line 90, in run
    raise ClientException(str(message)) from ex
flwr.simulation.ray_transport.ray_actor.ClientException: 
>>>>>>>A ClientException occurred.('\n\tSomething went wrong when running your client run.\n\tClient 46 crashed when the DefaultActor was running its run.\n\tException triggered on the client side: Traceback (most recent call last):\n  File "C:\\Users\\Stavros\\miniconda3\\envs\\pyt_pg\\Lib\\site-packages\\flwr\\simulation\\ray_transport\\ray_actor.py", line 76, in run\n    job_results = job_fn(client)\n                  ^^^^^^^^^^^^^^\n  File "C:\\Users\\Stavros\\miniconda3\\envs\\pyt_pg\\Lib\\site-packages\\flwr\\simulation\\ray_transport\\ray_client_proxy.py", line 207, in fit\n    return maybe_call_fit(\n           ^^^^^^^^^^^^^^^\n  File "C:\\Users\\Stavros\\miniconda3\\envs\\pyt_pg\\Lib\\site-packages\\flwr\\client\\client.py", line 234, in maybe_call_fit\n    return client.fit(fit_ins)\n           ^^^^^^^^^^^^^^^^^^^\n  File "C:\\Users\\Stavros\\miniconda3\\envs\\pyt_pg\\Lib\\site-packages\\flwr\\client\\numpy_client.py", line 238, in _fit\n    results = self.numpy_client.fit(parameters, ins.config)  # type: ignore\n              ^^^^^^^^^^^^^^^^^^^^^^^^^^^^^^^^^^^^^^^^^^^^^\n  File "C:\\Users\\Stavros\\Desktop\\PythonProjects\\FlowerYtTut\\client_scaffold.py", line 109, in fit\n    train_loss, train_acc = train_scaffold(self.model, self.trainloader, optim, epochs, self.device, server_cv, self.client_cv)\n                            ^^^^^^^^^^^^^^^^^^^^^^^^^^^^^^^^^^^^^^^^^^^^^^^^^^^^^^^^^^^^^^^^^^^^^^^^^^^^^^^^^^^^^^^^^^^^^^^^^^^\n  File "C:\\Users\\Stavros\\Desktop\\PythonProjects\\FlowerYtTut\\model.py", line 152, in train_scaffold\n    optimizer.step_custom(server_cv=server_cv, client_cv=client_cv)\n  File "C:\\Users\\Stavros\\Desktop\\PythonProjects\\FlowerYtTut\\model.py", line 132, in step_custom\n    par.data.add_(s_cv - c_cv, alpha=-group["lr"])\n                  ~~~~~^~~~~~\nRuntimeError: The size of tensor a (64) must match the size of tensor b (3) at non-singleton dimension 3\n',)
[2024-02-17 19:15:21,221][flwr][ERROR] - Traceback (most recent call last):
  File "C:\Users\Stavros\miniconda3\envs\pyt_pg\Lib\site-packages\flwr\simulation\ray_transport\ray_client_proxy.py", line 151, in _submit_job
    res, updated_context = self.actor_pool.get_client_result(self.cid, timeout)
                           ^^^^^^^^^^^^^^^^^^^^^^^^^^^^^^^^^^^^^^^^^^^^^^^^^^^^
  File "C:\Users\Stavros\miniconda3\envs\pyt_pg\Lib\site-packages\flwr\simulation\ray_transport\ray_actor.py", line 425, in get_client_result
    return self._fetch_future_result(cid)
           ^^^^^^^^^^^^^^^^^^^^^^^^^^^^^^
  File "C:\Users\Stavros\miniconda3\envs\pyt_pg\Lib\site-packages\flwr\simulation\ray_transport\ray_actor.py", line 306, in _fetch_future_result
    res_cid, res, updated_context = ray.get(
                                    ^^^^^^^^
  File "C:\Users\Stavros\miniconda3\envs\pyt_pg\Lib\site-packages\ray\_private\auto_init_hook.py", line 24, in auto_init_wrapper
    return fn(*args, **kwargs)
           ^^^^^^^^^^^^^^^^^^^
  File "C:\Users\Stavros\miniconda3\envs\pyt_pg\Lib\site-packages\ray\_private\client_mode_hook.py", line 103, in wrapper
    return func(*args, **kwargs)
           ^^^^^^^^^^^^^^^^^^^^^
  File "C:\Users\Stavros\miniconda3\envs\pyt_pg\Lib\site-packages\ray\_private\worker.py", line 2524, in get
    raise value.as_instanceof_cause()
ray.exceptions.RayTaskError(ClientException): [36mray::DefaultActor.run()[39m (pid=15840, ip=127.0.0.1, actor_id=86ae04ba45d66e99ed10d1b501000000, repr=<flwr.simulation.ray_transport.ray_actor.DefaultActor object at 0x0000028E89ADED10>)
                  ^^^^^^^^^^^^^^
  File "C:\Users\Stavros\miniconda3\envs\pyt_pg\Lib\site-packages\flwr\simulation\ray_transport\ray_client_proxy.py", line 207, in fit
    return maybe_call_fit(
           ^^^^^^^^^^^^^^^
  File "C:\Users\Stavros\miniconda3\envs\pyt_pg\Lib\site-packages\flwr\client\client.py", line 234, in maybe_call_fit
    return client.fit(fit_ins)
           ^^^^^^^^^^^^^^^^^^^
  File "C:\Users\Stavros\miniconda3\envs\pyt_pg\Lib\site-packages\flwr\client\numpy_client.py", line 238, in _fit
    results = self.numpy_client.fit(parameters, ins.config)  # type: ignore
              ^^^^^^^^^^^^^^^^^^^^^^^^^^^^^^^^^^^^^^^^^^^^^
  File "C:\Users\Stavros\Desktop\PythonProjects\FlowerYtTut\client_scaffold.py", line 109, in fit
    train_loss, train_acc = train_scaffold(self.model, self.trainloader, optim, epochs, self.device, server_cv, self.client_cv)
                            ^^^^^^^^^^^^^^^^^^^^^^^^^^^^^^^^^^^^^^^^^^^^^^^^^^^^^^^^^^^^^^^^^^^^^^^^^^^^^^^^^^^^^^^^^^^^^^^^^^^
  File "C:\Users\Stavros\Desktop\PythonProjects\FlowerYtTut\model.py", line 152, in train_scaffold
    optimizer.step_custom(server_cv=server_cv, client_cv=client_cv)
  File "C:\Users\Stavros\Desktop\PythonProjects\FlowerYtTut\model.py", line 132, in step_custom
    par.data.add_(s_cv - c_cv, alpha=-group["lr"])
                  ~~~~~^~~~~~
RuntimeError: The size of tensor a (64) must match the size of tensor b (3) at non-singleton dimension 3

The above exception was the direct cause of the following exception:

[36mray::DefaultActor.run()[39m (pid=15840, ip=127.0.0.1, actor_id=86ae04ba45d66e99ed10d1b501000000, repr=<flwr.simulation.ray_transport.ray_actor.DefaultActor object at 0x0000028E89ADED10>)
  File "python\ray\_raylet.pyx", line 1418, in ray._raylet.execute_task
  File "python\ray\_raylet.pyx", line 1498, in ray._raylet.execute_task
  File "python\ray\_raylet.pyx", line 1424, in ray._raylet.execute_task
  File "python\ray\_raylet.pyx", line 1364, in ray._raylet.execute_task.function_executor
  File "C:\Users\Stavros\miniconda3\envs\pyt_pg\Lib\site-packages\ray\_private\function_manager.py", line 726, in actor_method_executor
    return method(__ray_actor, *args, **kwargs)
           ^^^^^^^^^^^^^^^^^^^^^^^^^^^^^^^^^^^^
  File "C:\Users\Stavros\miniconda3\envs\pyt_pg\Lib\site-packages\ray\util\tracing\tracing_helper.py", line 464, in _resume_span
    return method(self, *_args, **_kwargs)
           ^^^^^^^^^^^^^^^^^^^^^^^^^^^^^^^
  File "C:\Users\Stavros\miniconda3\envs\pyt_pg\Lib\site-packages\flwr\simulation\ray_transport\ray_actor.py", line 90, in run
    raise ClientException(str(message)) from ex
flwr.simulation.ray_transport.ray_actor.ClientException: 
>>>>>>>A ClientException occurred.('\n\tSomething went wrong when running your client run.\n\tClient 98 crashed when the DefaultActor was running its run.\n\tException triggered on the client side: Traceback (most recent call last):\n  File "C:\\Users\\Stavros\\miniconda3\\envs\\pyt_pg\\Lib\\site-packages\\flwr\\simulation\\ray_transport\\ray_actor.py", line 76, in run\n    job_results = job_fn(client)\n                  ^^^^^^^^^^^^^^\n  File "C:\\Users\\Stavros\\miniconda3\\envs\\pyt_pg\\Lib\\site-packages\\flwr\\simulation\\ray_transport\\ray_client_proxy.py", line 207, in fit\n    return maybe_call_fit(\n           ^^^^^^^^^^^^^^^\n  File "C:\\Users\\Stavros\\miniconda3\\envs\\pyt_pg\\Lib\\site-packages\\flwr\\client\\client.py", line 234, in maybe_call_fit\n    return client.fit(fit_ins)\n           ^^^^^^^^^^^^^^^^^^^\n  File "C:\\Users\\Stavros\\miniconda3\\envs\\pyt_pg\\Lib\\site-packages\\flwr\\client\\numpy_client.py", line 238, in _fit\n    results = self.numpy_client.fit(parameters, ins.config)  # type: ignore\n              ^^^^^^^^^^^^^^^^^^^^^^^^^^^^^^^^^^^^^^^^^^^^^\n  File "C:\\Users\\Stavros\\Desktop\\PythonProjects\\FlowerYtTut\\client_scaffold.py", line 109, in fit\n    train_loss, train_acc = train_scaffold(self.model, self.trainloader, optim, epochs, self.device, server_cv, self.client_cv)\n                            ^^^^^^^^^^^^^^^^^^^^^^^^^^^^^^^^^^^^^^^^^^^^^^^^^^^^^^^^^^^^^^^^^^^^^^^^^^^^^^^^^^^^^^^^^^^^^^^^^^^\n  File "C:\\Users\\Stavros\\Desktop\\PythonProjects\\FlowerYtTut\\model.py", line 152, in train_scaffold\n    optimizer.step_custom(server_cv=server_cv, client_cv=client_cv)\n  File "C:\\Users\\Stavros\\Desktop\\PythonProjects\\FlowerYtTut\\model.py", line 132, in step_custom\n    par.data.add_(s_cv - c_cv, alpha=-group["lr"])\n                  ~~~~~^~~~~~\nRuntimeError: The size of tensor a (64) must match the size of tensor b (3) at non-singleton dimension 3\n',)

[2024-02-17 19:15:21,306][flwr][ERROR] - [36mray::DefaultActor.run()[39m (pid=15840, ip=127.0.0.1, actor_id=86ae04ba45d66e99ed10d1b501000000, repr=<flwr.simulation.ray_transport.ray_actor.DefaultActor object at 0x0000028E89ADED10>)
                  ^^^^^^^^^^^^^^
  File "C:\Users\Stavros\miniconda3\envs\pyt_pg\Lib\site-packages\flwr\simulation\ray_transport\ray_client_proxy.py", line 207, in fit
    return maybe_call_fit(
           ^^^^^^^^^^^^^^^
  File "C:\Users\Stavros\miniconda3\envs\pyt_pg\Lib\site-packages\flwr\client\client.py", line 234, in maybe_call_fit
    return client.fit(fit_ins)
           ^^^^^^^^^^^^^^^^^^^
  File "C:\Users\Stavros\miniconda3\envs\pyt_pg\Lib\site-packages\flwr\client\numpy_client.py", line 238, in _fit
    results = self.numpy_client.fit(parameters, ins.config)  # type: ignore
              ^^^^^^^^^^^^^^^^^^^^^^^^^^^^^^^^^^^^^^^^^^^^^
  File "C:\Users\Stavros\Desktop\PythonProjects\FlowerYtTut\client_scaffold.py", line 109, in fit
    train_loss, train_acc = train_scaffold(self.model, self.trainloader, optim, epochs, self.device, server_cv, self.client_cv)
                            ^^^^^^^^^^^^^^^^^^^^^^^^^^^^^^^^^^^^^^^^^^^^^^^^^^^^^^^^^^^^^^^^^^^^^^^^^^^^^^^^^^^^^^^^^^^^^^^^^^^
  File "C:\Users\Stavros\Desktop\PythonProjects\FlowerYtTut\model.py", line 152, in train_scaffold
    optimizer.step_custom(server_cv=server_cv, client_cv=client_cv)
  File "C:\Users\Stavros\Desktop\PythonProjects\FlowerYtTut\model.py", line 132, in step_custom
    par.data.add_(s_cv - c_cv, alpha=-group["lr"])
                  ~~~~~^~~~~~
RuntimeError: The size of tensor a (64) must match the size of tensor b (3) at non-singleton dimension 3

The above exception was the direct cause of the following exception:

[36mray::DefaultActor.run()[39m (pid=15840, ip=127.0.0.1, actor_id=86ae04ba45d66e99ed10d1b501000000, repr=<flwr.simulation.ray_transport.ray_actor.DefaultActor object at 0x0000028E89ADED10>)
  File "python\ray\_raylet.pyx", line 1418, in ray._raylet.execute_task
  File "python\ray\_raylet.pyx", line 1498, in ray._raylet.execute_task
  File "python\ray\_raylet.pyx", line 1424, in ray._raylet.execute_task
  File "python\ray\_raylet.pyx", line 1364, in ray._raylet.execute_task.function_executor
  File "C:\Users\Stavros\miniconda3\envs\pyt_pg\Lib\site-packages\ray\_private\function_manager.py", line 726, in actor_method_executor
    return method(__ray_actor, *args, **kwargs)
           ^^^^^^^^^^^^^^^^^^^^^^^^^^^^^^^^^^^^
  File "C:\Users\Stavros\miniconda3\envs\pyt_pg\Lib\site-packages\ray\util\tracing\tracing_helper.py", line 464, in _resume_span
    return method(self, *_args, **_kwargs)
           ^^^^^^^^^^^^^^^^^^^^^^^^^^^^^^^
  File "C:\Users\Stavros\miniconda3\envs\pyt_pg\Lib\site-packages\flwr\simulation\ray_transport\ray_actor.py", line 90, in run
    raise ClientException(str(message)) from ex
flwr.simulation.ray_transport.ray_actor.ClientException: 
>>>>>>>A ClientException occurred.('\n\tSomething went wrong when running your client run.\n\tClient 98 crashed when the DefaultActor was running its run.\n\tException triggered on the client side: Traceback (most recent call last):\n  File "C:\\Users\\Stavros\\miniconda3\\envs\\pyt_pg\\Lib\\site-packages\\flwr\\simulation\\ray_transport\\ray_actor.py", line 76, in run\n    job_results = job_fn(client)\n                  ^^^^^^^^^^^^^^\n  File "C:\\Users\\Stavros\\miniconda3\\envs\\pyt_pg\\Lib\\site-packages\\flwr\\simulation\\ray_transport\\ray_client_proxy.py", line 207, in fit\n    return maybe_call_fit(\n           ^^^^^^^^^^^^^^^\n  File "C:\\Users\\Stavros\\miniconda3\\envs\\pyt_pg\\Lib\\site-packages\\flwr\\client\\client.py", line 234, in maybe_call_fit\n    return client.fit(fit_ins)\n           ^^^^^^^^^^^^^^^^^^^\n  File "C:\\Users\\Stavros\\miniconda3\\envs\\pyt_pg\\Lib\\site-packages\\flwr\\client\\numpy_client.py", line 238, in _fit\n    results = self.numpy_client.fit(parameters, ins.config)  # type: ignore\n              ^^^^^^^^^^^^^^^^^^^^^^^^^^^^^^^^^^^^^^^^^^^^^\n  File "C:\\Users\\Stavros\\Desktop\\PythonProjects\\FlowerYtTut\\client_scaffold.py", line 109, in fit\n    train_loss, train_acc = train_scaffold(self.model, self.trainloader, optim, epochs, self.device, server_cv, self.client_cv)\n                            ^^^^^^^^^^^^^^^^^^^^^^^^^^^^^^^^^^^^^^^^^^^^^^^^^^^^^^^^^^^^^^^^^^^^^^^^^^^^^^^^^^^^^^^^^^^^^^^^^^^\n  File "C:\\Users\\Stavros\\Desktop\\PythonProjects\\FlowerYtTut\\model.py", line 152, in train_scaffold\n    optimizer.step_custom(server_cv=server_cv, client_cv=client_cv)\n  File "C:\\Users\\Stavros\\Desktop\\PythonProjects\\FlowerYtTut\\model.py", line 132, in step_custom\n    par.data.add_(s_cv - c_cv, alpha=-group["lr"])\n                  ~~~~~^~~~~~\nRuntimeError: The size of tensor a (64) must match the size of tensor b (3) at non-singleton dimension 3\n',)
[2024-02-17 19:15:21,915][flwr][ERROR] - Traceback (most recent call last):
  File "C:\Users\Stavros\miniconda3\envs\pyt_pg\Lib\site-packages\flwr\simulation\ray_transport\ray_client_proxy.py", line 151, in _submit_job
    res, updated_context = self.actor_pool.get_client_result(self.cid, timeout)
                           ^^^^^^^^^^^^^^^^^^^^^^^^^^^^^^^^^^^^^^^^^^^^^^^^^^^^
  File "C:\Users\Stavros\miniconda3\envs\pyt_pg\Lib\site-packages\flwr\simulation\ray_transport\ray_actor.py", line 425, in get_client_result
    return self._fetch_future_result(cid)
           ^^^^^^^^^^^^^^^^^^^^^^^^^^^^^^
  File "C:\Users\Stavros\miniconda3\envs\pyt_pg\Lib\site-packages\flwr\simulation\ray_transport\ray_actor.py", line 306, in _fetch_future_result
    res_cid, res, updated_context = ray.get(
                                    ^^^^^^^^
  File "C:\Users\Stavros\miniconda3\envs\pyt_pg\Lib\site-packages\ray\_private\auto_init_hook.py", line 24, in auto_init_wrapper
    return fn(*args, **kwargs)
           ^^^^^^^^^^^^^^^^^^^
  File "C:\Users\Stavros\miniconda3\envs\pyt_pg\Lib\site-packages\ray\_private\client_mode_hook.py", line 103, in wrapper
    return func(*args, **kwargs)
           ^^^^^^^^^^^^^^^^^^^^^
  File "C:\Users\Stavros\miniconda3\envs\pyt_pg\Lib\site-packages\ray\_private\worker.py", line 2524, in get
    raise value.as_instanceof_cause()
ray.exceptions.RayTaskError(ClientException): [36mray::DefaultActor.run()[39m (pid=15484, ip=127.0.0.1, actor_id=b70f75f33beb24a380ed1c8b01000000, repr=<flwr.simulation.ray_transport.ray_actor.DefaultActor object at 0x0000020FEA7FB0D0>)
                  ^^^^^^^^^^^^^^
  File "C:\Users\Stavros\miniconda3\envs\pyt_pg\Lib\site-packages\flwr\simulation\ray_transport\ray_client_proxy.py", line 207, in fit
    return maybe_call_fit(
           ^^^^^^^^^^^^^^^
  File "C:\Users\Stavros\miniconda3\envs\pyt_pg\Lib\site-packages\flwr\client\client.py", line 234, in maybe_call_fit
    return client.fit(fit_ins)
           ^^^^^^^^^^^^^^^^^^^
  File "C:\Users\Stavros\miniconda3\envs\pyt_pg\Lib\site-packages\flwr\client\numpy_client.py", line 238, in _fit
    results = self.numpy_client.fit(parameters, ins.config)  # type: ignore
              ^^^^^^^^^^^^^^^^^^^^^^^^^^^^^^^^^^^^^^^^^^^^^
  File "C:\Users\Stavros\Desktop\PythonProjects\FlowerYtTut\client_scaffold.py", line 109, in fit
    train_loss, train_acc = train_scaffold(self.model, self.trainloader, optim, epochs, self.device, server_cv, self.client_cv)
                            ^^^^^^^^^^^^^^^^^^^^^^^^^^^^^^^^^^^^^^^^^^^^^^^^^^^^^^^^^^^^^^^^^^^^^^^^^^^^^^^^^^^^^^^^^^^^^^^^^^^
  File "C:\Users\Stavros\Desktop\PythonProjects\FlowerYtTut\model.py", line 152, in train_scaffold
    optimizer.step_custom(server_cv=server_cv, client_cv=client_cv)
  File "C:\Users\Stavros\Desktop\PythonProjects\FlowerYtTut\model.py", line 132, in step_custom
    par.data.add_(s_cv - c_cv, alpha=-group["lr"])
                  ~~~~~^~~~~~
RuntimeError: The size of tensor a (64) must match the size of tensor b (3) at non-singleton dimension 3

The above exception was the direct cause of the following exception:

[36mray::DefaultActor.run()[39m (pid=15484, ip=127.0.0.1, actor_id=b70f75f33beb24a380ed1c8b01000000, repr=<flwr.simulation.ray_transport.ray_actor.DefaultActor object at 0x0000020FEA7FB0D0>)
  File "python\ray\_raylet.pyx", line 1418, in ray._raylet.execute_task
  File "python\ray\_raylet.pyx", line 1498, in ray._raylet.execute_task
  File "python\ray\_raylet.pyx", line 1424, in ray._raylet.execute_task
  File "python\ray\_raylet.pyx", line 1364, in ray._raylet.execute_task.function_executor
  File "C:\Users\Stavros\miniconda3\envs\pyt_pg\Lib\site-packages\ray\_private\function_manager.py", line 726, in actor_method_executor
    return method(__ray_actor, *args, **kwargs)
           ^^^^^^^^^^^^^^^^^^^^^^^^^^^^^^^^^^^^
  File "C:\Users\Stavros\miniconda3\envs\pyt_pg\Lib\site-packages\ray\util\tracing\tracing_helper.py", line 464, in _resume_span
    return method(self, *_args, **_kwargs)
           ^^^^^^^^^^^^^^^^^^^^^^^^^^^^^^^
  File "C:\Users\Stavros\miniconda3\envs\pyt_pg\Lib\site-packages\flwr\simulation\ray_transport\ray_actor.py", line 90, in run
    raise ClientException(str(message)) from ex
flwr.simulation.ray_transport.ray_actor.ClientException: 
>>>>>>>A ClientException occurred.('\n\tSomething went wrong when running your client run.\n\tClient 86 crashed when the DefaultActor was running its run.\n\tException triggered on the client side: Traceback (most recent call last):\n  File "C:\\Users\\Stavros\\miniconda3\\envs\\pyt_pg\\Lib\\site-packages\\flwr\\simulation\\ray_transport\\ray_actor.py", line 76, in run\n    job_results = job_fn(client)\n                  ^^^^^^^^^^^^^^\n  File "C:\\Users\\Stavros\\miniconda3\\envs\\pyt_pg\\Lib\\site-packages\\flwr\\simulation\\ray_transport\\ray_client_proxy.py", line 207, in fit\n    return maybe_call_fit(\n           ^^^^^^^^^^^^^^^\n  File "C:\\Users\\Stavros\\miniconda3\\envs\\pyt_pg\\Lib\\site-packages\\flwr\\client\\client.py", line 234, in maybe_call_fit\n    return client.fit(fit_ins)\n           ^^^^^^^^^^^^^^^^^^^\n  File "C:\\Users\\Stavros\\miniconda3\\envs\\pyt_pg\\Lib\\site-packages\\flwr\\client\\numpy_client.py", line 238, in _fit\n    results = self.numpy_client.fit(parameters, ins.config)  # type: ignore\n              ^^^^^^^^^^^^^^^^^^^^^^^^^^^^^^^^^^^^^^^^^^^^^\n  File "C:\\Users\\Stavros\\Desktop\\PythonProjects\\FlowerYtTut\\client_scaffold.py", line 109, in fit\n    train_loss, train_acc = train_scaffold(self.model, self.trainloader, optim, epochs, self.device, server_cv, self.client_cv)\n                            ^^^^^^^^^^^^^^^^^^^^^^^^^^^^^^^^^^^^^^^^^^^^^^^^^^^^^^^^^^^^^^^^^^^^^^^^^^^^^^^^^^^^^^^^^^^^^^^^^^^\n  File "C:\\Users\\Stavros\\Desktop\\PythonProjects\\FlowerYtTut\\model.py", line 152, in train_scaffold\n    optimizer.step_custom(server_cv=server_cv, client_cv=client_cv)\n  File "C:\\Users\\Stavros\\Desktop\\PythonProjects\\FlowerYtTut\\model.py", line 132, in step_custom\n    par.data.add_(s_cv - c_cv, alpha=-group["lr"])\n                  ~~~~~^~~~~~\nRuntimeError: The size of tensor a (64) must match the size of tensor b (3) at non-singleton dimension 3\n',)

[2024-02-17 19:15:21,926][flwr][ERROR] - [36mray::DefaultActor.run()[39m (pid=15484, ip=127.0.0.1, actor_id=b70f75f33beb24a380ed1c8b01000000, repr=<flwr.simulation.ray_transport.ray_actor.DefaultActor object at 0x0000020FEA7FB0D0>)
                  ^^^^^^^^^^^^^^
  File "C:\Users\Stavros\miniconda3\envs\pyt_pg\Lib\site-packages\flwr\simulation\ray_transport\ray_client_proxy.py", line 207, in fit
    return maybe_call_fit(
           ^^^^^^^^^^^^^^^
  File "C:\Users\Stavros\miniconda3\envs\pyt_pg\Lib\site-packages\flwr\client\client.py", line 234, in maybe_call_fit
    return client.fit(fit_ins)
           ^^^^^^^^^^^^^^^^^^^
  File "C:\Users\Stavros\miniconda3\envs\pyt_pg\Lib\site-packages\flwr\client\numpy_client.py", line 238, in _fit
    results = self.numpy_client.fit(parameters, ins.config)  # type: ignore
              ^^^^^^^^^^^^^^^^^^^^^^^^^^^^^^^^^^^^^^^^^^^^^
  File "C:\Users\Stavros\Desktop\PythonProjects\FlowerYtTut\client_scaffold.py", line 109, in fit
    train_loss, train_acc = train_scaffold(self.model, self.trainloader, optim, epochs, self.device, server_cv, self.client_cv)
                            ^^^^^^^^^^^^^^^^^^^^^^^^^^^^^^^^^^^^^^^^^^^^^^^^^^^^^^^^^^^^^^^^^^^^^^^^^^^^^^^^^^^^^^^^^^^^^^^^^^^
  File "C:\Users\Stavros\Desktop\PythonProjects\FlowerYtTut\model.py", line 152, in train_scaffold
    optimizer.step_custom(server_cv=server_cv, client_cv=client_cv)
  File "C:\Users\Stavros\Desktop\PythonProjects\FlowerYtTut\model.py", line 132, in step_custom
    par.data.add_(s_cv - c_cv, alpha=-group["lr"])
                  ~~~~~^~~~~~
RuntimeError: The size of tensor a (64) must match the size of tensor b (3) at non-singleton dimension 3

The above exception was the direct cause of the following exception:

[36mray::DefaultActor.run()[39m (pid=15484, ip=127.0.0.1, actor_id=b70f75f33beb24a380ed1c8b01000000, repr=<flwr.simulation.ray_transport.ray_actor.DefaultActor object at 0x0000020FEA7FB0D0>)
  File "python\ray\_raylet.pyx", line 1418, in ray._raylet.execute_task
  File "python\ray\_raylet.pyx", line 1498, in ray._raylet.execute_task
  File "python\ray\_raylet.pyx", line 1424, in ray._raylet.execute_task
  File "python\ray\_raylet.pyx", line 1364, in ray._raylet.execute_task.function_executor
  File "C:\Users\Stavros\miniconda3\envs\pyt_pg\Lib\site-packages\ray\_private\function_manager.py", line 726, in actor_method_executor
    return method(__ray_actor, *args, **kwargs)
           ^^^^^^^^^^^^^^^^^^^^^^^^^^^^^^^^^^^^
  File "C:\Users\Stavros\miniconda3\envs\pyt_pg\Lib\site-packages\ray\util\tracing\tracing_helper.py", line 464, in _resume_span
    return method(self, *_args, **_kwargs)
           ^^^^^^^^^^^^^^^^^^^^^^^^^^^^^^^
  File "C:\Users\Stavros\miniconda3\envs\pyt_pg\Lib\site-packages\flwr\simulation\ray_transport\ray_actor.py", line 90, in run
    raise ClientException(str(message)) from ex
flwr.simulation.ray_transport.ray_actor.ClientException: 
>>>>>>>A ClientException occurred.('\n\tSomething went wrong when running your client run.\n\tClient 86 crashed when the DefaultActor was running its run.\n\tException triggered on the client side: Traceback (most recent call last):\n  File "C:\\Users\\Stavros\\miniconda3\\envs\\pyt_pg\\Lib\\site-packages\\flwr\\simulation\\ray_transport\\ray_actor.py", line 76, in run\n    job_results = job_fn(client)\n                  ^^^^^^^^^^^^^^\n  File "C:\\Users\\Stavros\\miniconda3\\envs\\pyt_pg\\Lib\\site-packages\\flwr\\simulation\\ray_transport\\ray_client_proxy.py", line 207, in fit\n    return maybe_call_fit(\n           ^^^^^^^^^^^^^^^\n  File "C:\\Users\\Stavros\\miniconda3\\envs\\pyt_pg\\Lib\\site-packages\\flwr\\client\\client.py", line 234, in maybe_call_fit\n    return client.fit(fit_ins)\n           ^^^^^^^^^^^^^^^^^^^\n  File "C:\\Users\\Stavros\\miniconda3\\envs\\pyt_pg\\Lib\\site-packages\\flwr\\client\\numpy_client.py", line 238, in _fit\n    results = self.numpy_client.fit(parameters, ins.config)  # type: ignore\n              ^^^^^^^^^^^^^^^^^^^^^^^^^^^^^^^^^^^^^^^^^^^^^\n  File "C:\\Users\\Stavros\\Desktop\\PythonProjects\\FlowerYtTut\\client_scaffold.py", line 109, in fit\n    train_loss, train_acc = train_scaffold(self.model, self.trainloader, optim, epochs, self.device, server_cv, self.client_cv)\n                            ^^^^^^^^^^^^^^^^^^^^^^^^^^^^^^^^^^^^^^^^^^^^^^^^^^^^^^^^^^^^^^^^^^^^^^^^^^^^^^^^^^^^^^^^^^^^^^^^^^^\n  File "C:\\Users\\Stavros\\Desktop\\PythonProjects\\FlowerYtTut\\model.py", line 152, in train_scaffold\n    optimizer.step_custom(server_cv=server_cv, client_cv=client_cv)\n  File "C:\\Users\\Stavros\\Desktop\\PythonProjects\\FlowerYtTut\\model.py", line 132, in step_custom\n    par.data.add_(s_cv - c_cv, alpha=-group["lr"])\n                  ~~~~~^~~~~~\nRuntimeError: The size of tensor a (64) must match the size of tensor b (3) at non-singleton dimension 3\n',)
[2024-02-17 19:16:16,153][flwr][ERROR] - Traceback (most recent call last):
  File "C:\Users\Stavros\miniconda3\envs\pyt_pg\Lib\site-packages\flwr\simulation\ray_transport\ray_client_proxy.py", line 151, in _submit_job
    res, updated_context = self.actor_pool.get_client_result(self.cid, timeout)
                           ^^^^^^^^^^^^^^^^^^^^^^^^^^^^^^^^^^^^^^^^^^^^^^^^^^^^
  File "C:\Users\Stavros\miniconda3\envs\pyt_pg\Lib\site-packages\flwr\simulation\ray_transport\ray_actor.py", line 425, in get_client_result
    return self._fetch_future_result(cid)
           ^^^^^^^^^^^^^^^^^^^^^^^^^^^^^^
  File "C:\Users\Stavros\miniconda3\envs\pyt_pg\Lib\site-packages\flwr\simulation\ray_transport\ray_actor.py", line 306, in _fetch_future_result
    res_cid, res, updated_context = ray.get(
                                    ^^^^^^^^
  File "C:\Users\Stavros\miniconda3\envs\pyt_pg\Lib\site-packages\ray\_private\auto_init_hook.py", line 24, in auto_init_wrapper
    return fn(*args, **kwargs)
           ^^^^^^^^^^^^^^^^^^^
  File "C:\Users\Stavros\miniconda3\envs\pyt_pg\Lib\site-packages\ray\_private\client_mode_hook.py", line 103, in wrapper
    return func(*args, **kwargs)
           ^^^^^^^^^^^^^^^^^^^^^
  File "C:\Users\Stavros\miniconda3\envs\pyt_pg\Lib\site-packages\ray\_private\worker.py", line 2524, in get
    raise value.as_instanceof_cause()
ray.exceptions.RayTaskError(ClientException): [36mray::DefaultActor.run()[39m (pid=15840, ip=127.0.0.1, actor_id=86ae04ba45d66e99ed10d1b501000000, repr=<flwr.simulation.ray_transport.ray_actor.DefaultActor object at 0x0000028E89ADED10>)
                  ^^^^^^^^^^^^^^
  File "C:\Users\Stavros\miniconda3\envs\pyt_pg\Lib\site-packages\flwr\simulation\ray_transport\ray_client_proxy.py", line 207, in fit
    return maybe_call_fit(
           ^^^^^^^^^^^^^^^
  File "C:\Users\Stavros\miniconda3\envs\pyt_pg\Lib\site-packages\flwr\client\client.py", line 234, in maybe_call_fit
    return client.fit(fit_ins)
           ^^^^^^^^^^^^^^^^^^^
  File "C:\Users\Stavros\miniconda3\envs\pyt_pg\Lib\site-packages\flwr\client\numpy_client.py", line 238, in _fit
    results = self.numpy_client.fit(parameters, ins.config)  # type: ignore
              ^^^^^^^^^^^^^^^^^^^^^^^^^^^^^^^^^^^^^^^^^^^^^
  File "C:\Users\Stavros\Desktop\PythonProjects\FlowerYtTut\client_scaffold.py", line 109, in fit
    train_loss, train_acc = train_scaffold(self.model, self.trainloader, optim, epochs, self.device, server_cv, self.client_cv)
                            ^^^^^^^^^^^^^^^^^^^^^^^^^^^^^^^^^^^^^^^^^^^^^^^^^^^^^^^^^^^^^^^^^^^^^^^^^^^^^^^^^^^^^^^^^^^^^^^^^^^
  File "C:\Users\Stavros\Desktop\PythonProjects\FlowerYtTut\model.py", line 152, in train_scaffold
    optimizer.step_custom(server_cv=server_cv, client_cv=client_cv)
  File "C:\Users\Stavros\Desktop\PythonProjects\FlowerYtTut\model.py", line 132, in step_custom
    par.data.add_(s_cv - c_cv, alpha=-group["lr"])
                  ~~~~~^~~~~~
RuntimeError: The size of tensor a (64) must match the size of tensor b (3) at non-singleton dimension 3

The above exception was the direct cause of the following exception:

[36mray::DefaultActor.run()[39m (pid=15840, ip=127.0.0.1, actor_id=86ae04ba45d66e99ed10d1b501000000, repr=<flwr.simulation.ray_transport.ray_actor.DefaultActor object at 0x0000028E89ADED10>)
  File "python\ray\_raylet.pyx", line 1418, in ray._raylet.execute_task
  File "python\ray\_raylet.pyx", line 1498, in ray._raylet.execute_task
  File "python\ray\_raylet.pyx", line 1424, in ray._raylet.execute_task
  File "python\ray\_raylet.pyx", line 1364, in ray._raylet.execute_task.function_executor
  File "C:\Users\Stavros\miniconda3\envs\pyt_pg\Lib\site-packages\ray\_private\function_manager.py", line 726, in actor_method_executor
    return method(__ray_actor, *args, **kwargs)
           ^^^^^^^^^^^^^^^^^^^^^^^^^^^^^^^^^^^^
  File "C:\Users\Stavros\miniconda3\envs\pyt_pg\Lib\site-packages\ray\util\tracing\tracing_helper.py", line 464, in _resume_span
    return method(self, *_args, **_kwargs)
           ^^^^^^^^^^^^^^^^^^^^^^^^^^^^^^^
  File "C:\Users\Stavros\miniconda3\envs\pyt_pg\Lib\site-packages\flwr\simulation\ray_transport\ray_actor.py", line 90, in run
    raise ClientException(str(message)) from ex
flwr.simulation.ray_transport.ray_actor.ClientException: 
>>>>>>>A ClientException occurred.('\n\tSomething went wrong when running your client run.\n\tClient 69 crashed when the DefaultActor was running its run.\n\tException triggered on the client side: Traceback (most recent call last):\n  File "C:\\Users\\Stavros\\miniconda3\\envs\\pyt_pg\\Lib\\site-packages\\flwr\\simulation\\ray_transport\\ray_actor.py", line 76, in run\n    job_results = job_fn(client)\n                  ^^^^^^^^^^^^^^\n  File "C:\\Users\\Stavros\\miniconda3\\envs\\pyt_pg\\Lib\\site-packages\\flwr\\simulation\\ray_transport\\ray_client_proxy.py", line 207, in fit\n    return maybe_call_fit(\n           ^^^^^^^^^^^^^^^\n  File "C:\\Users\\Stavros\\miniconda3\\envs\\pyt_pg\\Lib\\site-packages\\flwr\\client\\client.py", line 234, in maybe_call_fit\n    return client.fit(fit_ins)\n           ^^^^^^^^^^^^^^^^^^^\n  File "C:\\Users\\Stavros\\miniconda3\\envs\\pyt_pg\\Lib\\site-packages\\flwr\\client\\numpy_client.py", line 238, in _fit\n    results = self.numpy_client.fit(parameters, ins.config)  # type: ignore\n              ^^^^^^^^^^^^^^^^^^^^^^^^^^^^^^^^^^^^^^^^^^^^^\n  File "C:\\Users\\Stavros\\Desktop\\PythonProjects\\FlowerYtTut\\client_scaffold.py", line 109, in fit\n    train_loss, train_acc = train_scaffold(self.model, self.trainloader, optim, epochs, self.device, server_cv, self.client_cv)\n                            ^^^^^^^^^^^^^^^^^^^^^^^^^^^^^^^^^^^^^^^^^^^^^^^^^^^^^^^^^^^^^^^^^^^^^^^^^^^^^^^^^^^^^^^^^^^^^^^^^^^\n  File "C:\\Users\\Stavros\\Desktop\\PythonProjects\\FlowerYtTut\\model.py", line 152, in train_scaffold\n    optimizer.step_custom(server_cv=server_cv, client_cv=client_cv)\n  File "C:\\Users\\Stavros\\Desktop\\PythonProjects\\FlowerYtTut\\model.py", line 132, in step_custom\n    par.data.add_(s_cv - c_cv, alpha=-group["lr"])\n                  ~~~~~^~~~~~\nRuntimeError: The size of tensor a (64) must match the size of tensor b (3) at non-singleton dimension 3\n',)

[2024-02-17 19:16:16,358][flwr][ERROR] - [36mray::DefaultActor.run()[39m (pid=15840, ip=127.0.0.1, actor_id=86ae04ba45d66e99ed10d1b501000000, repr=<flwr.simulation.ray_transport.ray_actor.DefaultActor object at 0x0000028E89ADED10>)
                  ^^^^^^^^^^^^^^
  File "C:\Users\Stavros\miniconda3\envs\pyt_pg\Lib\site-packages\flwr\simulation\ray_transport\ray_client_proxy.py", line 207, in fit
    return maybe_call_fit(
           ^^^^^^^^^^^^^^^
  File "C:\Users\Stavros\miniconda3\envs\pyt_pg\Lib\site-packages\flwr\client\client.py", line 234, in maybe_call_fit
    return client.fit(fit_ins)
           ^^^^^^^^^^^^^^^^^^^
  File "C:\Users\Stavros\miniconda3\envs\pyt_pg\Lib\site-packages\flwr\client\numpy_client.py", line 238, in _fit
    results = self.numpy_client.fit(parameters, ins.config)  # type: ignore
              ^^^^^^^^^^^^^^^^^^^^^^^^^^^^^^^^^^^^^^^^^^^^^
  File "C:\Users\Stavros\Desktop\PythonProjects\FlowerYtTut\client_scaffold.py", line 109, in fit
    train_loss, train_acc = train_scaffold(self.model, self.trainloader, optim, epochs, self.device, server_cv, self.client_cv)
                            ^^^^^^^^^^^^^^^^^^^^^^^^^^^^^^^^^^^^^^^^^^^^^^^^^^^^^^^^^^^^^^^^^^^^^^^^^^^^^^^^^^^^^^^^^^^^^^^^^^^
  File "C:\Users\Stavros\Desktop\PythonProjects\FlowerYtTut\model.py", line 152, in train_scaffold
    optimizer.step_custom(server_cv=server_cv, client_cv=client_cv)
  File "C:\Users\Stavros\Desktop\PythonProjects\FlowerYtTut\model.py", line 132, in step_custom
    par.data.add_(s_cv - c_cv, alpha=-group["lr"])
                  ~~~~~^~~~~~
RuntimeError: The size of tensor a (64) must match the size of tensor b (3) at non-singleton dimension 3

The above exception was the direct cause of the following exception:

[36mray::DefaultActor.run()[39m (pid=15840, ip=127.0.0.1, actor_id=86ae04ba45d66e99ed10d1b501000000, repr=<flwr.simulation.ray_transport.ray_actor.DefaultActor object at 0x0000028E89ADED10>)
  File "python\ray\_raylet.pyx", line 1418, in ray._raylet.execute_task
  File "python\ray\_raylet.pyx", line 1498, in ray._raylet.execute_task
  File "python\ray\_raylet.pyx", line 1424, in ray._raylet.execute_task
  File "python\ray\_raylet.pyx", line 1364, in ray._raylet.execute_task.function_executor
  File "C:\Users\Stavros\miniconda3\envs\pyt_pg\Lib\site-packages\ray\_private\function_manager.py", line 726, in actor_method_executor
    return method(__ray_actor, *args, **kwargs)
           ^^^^^^^^^^^^^^^^^^^^^^^^^^^^^^^^^^^^
  File "C:\Users\Stavros\miniconda3\envs\pyt_pg\Lib\site-packages\ray\util\tracing\tracing_helper.py", line 464, in _resume_span
    return method(self, *_args, **_kwargs)
           ^^^^^^^^^^^^^^^^^^^^^^^^^^^^^^^
  File "C:\Users\Stavros\miniconda3\envs\pyt_pg\Lib\site-packages\flwr\simulation\ray_transport\ray_actor.py", line 90, in run
    raise ClientException(str(message)) from ex
flwr.simulation.ray_transport.ray_actor.ClientException: 
>>>>>>>A ClientException occurred.('\n\tSomething went wrong when running your client run.\n\tClient 69 crashed when the DefaultActor was running its run.\n\tException triggered on the client side: Traceback (most recent call last):\n  File "C:\\Users\\Stavros\\miniconda3\\envs\\pyt_pg\\Lib\\site-packages\\flwr\\simulation\\ray_transport\\ray_actor.py", line 76, in run\n    job_results = job_fn(client)\n                  ^^^^^^^^^^^^^^\n  File "C:\\Users\\Stavros\\miniconda3\\envs\\pyt_pg\\Lib\\site-packages\\flwr\\simulation\\ray_transport\\ray_client_proxy.py", line 207, in fit\n    return maybe_call_fit(\n           ^^^^^^^^^^^^^^^\n  File "C:\\Users\\Stavros\\miniconda3\\envs\\pyt_pg\\Lib\\site-packages\\flwr\\client\\client.py", line 234, in maybe_call_fit\n    return client.fit(fit_ins)\n           ^^^^^^^^^^^^^^^^^^^\n  File "C:\\Users\\Stavros\\miniconda3\\envs\\pyt_pg\\Lib\\site-packages\\flwr\\client\\numpy_client.py", line 238, in _fit\n    results = self.numpy_client.fit(parameters, ins.config)  # type: ignore\n              ^^^^^^^^^^^^^^^^^^^^^^^^^^^^^^^^^^^^^^^^^^^^^\n  File "C:\\Users\\Stavros\\Desktop\\PythonProjects\\FlowerYtTut\\client_scaffold.py", line 109, in fit\n    train_loss, train_acc = train_scaffold(self.model, self.trainloader, optim, epochs, self.device, server_cv, self.client_cv)\n                            ^^^^^^^^^^^^^^^^^^^^^^^^^^^^^^^^^^^^^^^^^^^^^^^^^^^^^^^^^^^^^^^^^^^^^^^^^^^^^^^^^^^^^^^^^^^^^^^^^^^\n  File "C:\\Users\\Stavros\\Desktop\\PythonProjects\\FlowerYtTut\\model.py", line 152, in train_scaffold\n    optimizer.step_custom(server_cv=server_cv, client_cv=client_cv)\n  File "C:\\Users\\Stavros\\Desktop\\PythonProjects\\FlowerYtTut\\model.py", line 132, in step_custom\n    par.data.add_(s_cv - c_cv, alpha=-group["lr"])\n                  ~~~~~^~~~~~\nRuntimeError: The size of tensor a (64) must match the size of tensor b (3) at non-singleton dimension 3\n',)
[2024-02-17 19:16:17,003][flwr][ERROR] - Traceback (most recent call last):
  File "C:\Users\Stavros\miniconda3\envs\pyt_pg\Lib\site-packages\flwr\simulation\ray_transport\ray_client_proxy.py", line 151, in _submit_job
    res, updated_context = self.actor_pool.get_client_result(self.cid, timeout)
                           ^^^^^^^^^^^^^^^^^^^^^^^^^^^^^^^^^^^^^^^^^^^^^^^^^^^^
  File "C:\Users\Stavros\miniconda3\envs\pyt_pg\Lib\site-packages\flwr\simulation\ray_transport\ray_actor.py", line 425, in get_client_result
    return self._fetch_future_result(cid)
           ^^^^^^^^^^^^^^^^^^^^^^^^^^^^^^
  File "C:\Users\Stavros\miniconda3\envs\pyt_pg\Lib\site-packages\flwr\simulation\ray_transport\ray_actor.py", line 306, in _fetch_future_result
    res_cid, res, updated_context = ray.get(
                                    ^^^^^^^^
  File "C:\Users\Stavros\miniconda3\envs\pyt_pg\Lib\site-packages\ray\_private\auto_init_hook.py", line 24, in auto_init_wrapper
    return fn(*args, **kwargs)
           ^^^^^^^^^^^^^^^^^^^
  File "C:\Users\Stavros\miniconda3\envs\pyt_pg\Lib\site-packages\ray\_private\client_mode_hook.py", line 103, in wrapper
    return func(*args, **kwargs)
           ^^^^^^^^^^^^^^^^^^^^^
  File "C:\Users\Stavros\miniconda3\envs\pyt_pg\Lib\site-packages\ray\_private\worker.py", line 2524, in get
    raise value.as_instanceof_cause()
ray.exceptions.RayTaskError(ClientException): [36mray::DefaultActor.run()[39m (pid=15484, ip=127.0.0.1, actor_id=b70f75f33beb24a380ed1c8b01000000, repr=<flwr.simulation.ray_transport.ray_actor.DefaultActor object at 0x0000020FEA7FB0D0>)
                  ^^^^^^^^^^^^^^
  File "C:\Users\Stavros\miniconda3\envs\pyt_pg\Lib\site-packages\flwr\simulation\ray_transport\ray_client_proxy.py", line 207, in fit
    return maybe_call_fit(
           ^^^^^^^^^^^^^^^
  File "C:\Users\Stavros\miniconda3\envs\pyt_pg\Lib\site-packages\flwr\client\client.py", line 234, in maybe_call_fit
    return client.fit(fit_ins)
           ^^^^^^^^^^^^^^^^^^^
  File "C:\Users\Stavros\miniconda3\envs\pyt_pg\Lib\site-packages\flwr\client\numpy_client.py", line 238, in _fit
    results = self.numpy_client.fit(parameters, ins.config)  # type: ignore
              ^^^^^^^^^^^^^^^^^^^^^^^^^^^^^^^^^^^^^^^^^^^^^
  File "C:\Users\Stavros\Desktop\PythonProjects\FlowerYtTut\client_scaffold.py", line 109, in fit
    train_loss, train_acc = train_scaffold(self.model, self.trainloader, optim, epochs, self.device, server_cv, self.client_cv)
                            ^^^^^^^^^^^^^^^^^^^^^^^^^^^^^^^^^^^^^^^^^^^^^^^^^^^^^^^^^^^^^^^^^^^^^^^^^^^^^^^^^^^^^^^^^^^^^^^^^^^
  File "C:\Users\Stavros\Desktop\PythonProjects\FlowerYtTut\model.py", line 152, in train_scaffold
    optimizer.step_custom(server_cv=server_cv, client_cv=client_cv)
  File "C:\Users\Stavros\Desktop\PythonProjects\FlowerYtTut\model.py", line 132, in step_custom
    par.data.add_(s_cv - c_cv, alpha=-group["lr"])
                  ~~~~~^~~~~~
RuntimeError: The size of tensor a (64) must match the size of tensor b (3) at non-singleton dimension 3

The above exception was the direct cause of the following exception:

[36mray::DefaultActor.run()[39m (pid=15484, ip=127.0.0.1, actor_id=b70f75f33beb24a380ed1c8b01000000, repr=<flwr.simulation.ray_transport.ray_actor.DefaultActor object at 0x0000020FEA7FB0D0>)
  File "python\ray\_raylet.pyx", line 1418, in ray._raylet.execute_task
  File "python\ray\_raylet.pyx", line 1498, in ray._raylet.execute_task
  File "python\ray\_raylet.pyx", line 1424, in ray._raylet.execute_task
  File "python\ray\_raylet.pyx", line 1364, in ray._raylet.execute_task.function_executor
  File "C:\Users\Stavros\miniconda3\envs\pyt_pg\Lib\site-packages\ray\_private\function_manager.py", line 726, in actor_method_executor
    return method(__ray_actor, *args, **kwargs)
           ^^^^^^^^^^^^^^^^^^^^^^^^^^^^^^^^^^^^
  File "C:\Users\Stavros\miniconda3\envs\pyt_pg\Lib\site-packages\ray\util\tracing\tracing_helper.py", line 464, in _resume_span
    return method(self, *_args, **_kwargs)
           ^^^^^^^^^^^^^^^^^^^^^^^^^^^^^^^
  File "C:\Users\Stavros\miniconda3\envs\pyt_pg\Lib\site-packages\flwr\simulation\ray_transport\ray_actor.py", line 90, in run
    raise ClientException(str(message)) from ex
flwr.simulation.ray_transport.ray_actor.ClientException: 
>>>>>>>A ClientException occurred.('\n\tSomething went wrong when running your client run.\n\tClient 37 crashed when the DefaultActor was running its run.\n\tException triggered on the client side: Traceback (most recent call last):\n  File "C:\\Users\\Stavros\\miniconda3\\envs\\pyt_pg\\Lib\\site-packages\\flwr\\simulation\\ray_transport\\ray_actor.py", line 76, in run\n    job_results = job_fn(client)\n                  ^^^^^^^^^^^^^^\n  File "C:\\Users\\Stavros\\miniconda3\\envs\\pyt_pg\\Lib\\site-packages\\flwr\\simulation\\ray_transport\\ray_client_proxy.py", line 207, in fit\n    return maybe_call_fit(\n           ^^^^^^^^^^^^^^^\n  File "C:\\Users\\Stavros\\miniconda3\\envs\\pyt_pg\\Lib\\site-packages\\flwr\\client\\client.py", line 234, in maybe_call_fit\n    return client.fit(fit_ins)\n           ^^^^^^^^^^^^^^^^^^^\n  File "C:\\Users\\Stavros\\miniconda3\\envs\\pyt_pg\\Lib\\site-packages\\flwr\\client\\numpy_client.py", line 238, in _fit\n    results = self.numpy_client.fit(parameters, ins.config)  # type: ignore\n              ^^^^^^^^^^^^^^^^^^^^^^^^^^^^^^^^^^^^^^^^^^^^^\n  File "C:\\Users\\Stavros\\Desktop\\PythonProjects\\FlowerYtTut\\client_scaffold.py", line 109, in fit\n    train_loss, train_acc = train_scaffold(self.model, self.trainloader, optim, epochs, self.device, server_cv, self.client_cv)\n                            ^^^^^^^^^^^^^^^^^^^^^^^^^^^^^^^^^^^^^^^^^^^^^^^^^^^^^^^^^^^^^^^^^^^^^^^^^^^^^^^^^^^^^^^^^^^^^^^^^^^\n  File "C:\\Users\\Stavros\\Desktop\\PythonProjects\\FlowerYtTut\\model.py", line 152, in train_scaffold\n    optimizer.step_custom(server_cv=server_cv, client_cv=client_cv)\n  File "C:\\Users\\Stavros\\Desktop\\PythonProjects\\FlowerYtTut\\model.py", line 132, in step_custom\n    par.data.add_(s_cv - c_cv, alpha=-group["lr"])\n                  ~~~~~^~~~~~\nRuntimeError: The size of tensor a (64) must match the size of tensor b (3) at non-singleton dimension 3\n',)

[2024-02-17 19:16:17,017][flwr][ERROR] - [36mray::DefaultActor.run()[39m (pid=15484, ip=127.0.0.1, actor_id=b70f75f33beb24a380ed1c8b01000000, repr=<flwr.simulation.ray_transport.ray_actor.DefaultActor object at 0x0000020FEA7FB0D0>)
                  ^^^^^^^^^^^^^^
  File "C:\Users\Stavros\miniconda3\envs\pyt_pg\Lib\site-packages\flwr\simulation\ray_transport\ray_client_proxy.py", line 207, in fit
    return maybe_call_fit(
           ^^^^^^^^^^^^^^^
  File "C:\Users\Stavros\miniconda3\envs\pyt_pg\Lib\site-packages\flwr\client\client.py", line 234, in maybe_call_fit
    return client.fit(fit_ins)
           ^^^^^^^^^^^^^^^^^^^
  File "C:\Users\Stavros\miniconda3\envs\pyt_pg\Lib\site-packages\flwr\client\numpy_client.py", line 238, in _fit
    results = self.numpy_client.fit(parameters, ins.config)  # type: ignore
              ^^^^^^^^^^^^^^^^^^^^^^^^^^^^^^^^^^^^^^^^^^^^^
  File "C:\Users\Stavros\Desktop\PythonProjects\FlowerYtTut\client_scaffold.py", line 109, in fit
    train_loss, train_acc = train_scaffold(self.model, self.trainloader, optim, epochs, self.device, server_cv, self.client_cv)
                            ^^^^^^^^^^^^^^^^^^^^^^^^^^^^^^^^^^^^^^^^^^^^^^^^^^^^^^^^^^^^^^^^^^^^^^^^^^^^^^^^^^^^^^^^^^^^^^^^^^^
  File "C:\Users\Stavros\Desktop\PythonProjects\FlowerYtTut\model.py", line 152, in train_scaffold
    optimizer.step_custom(server_cv=server_cv, client_cv=client_cv)
  File "C:\Users\Stavros\Desktop\PythonProjects\FlowerYtTut\model.py", line 132, in step_custom
    par.data.add_(s_cv - c_cv, alpha=-group["lr"])
                  ~~~~~^~~~~~
RuntimeError: The size of tensor a (64) must match the size of tensor b (3) at non-singleton dimension 3

The above exception was the direct cause of the following exception:

[36mray::DefaultActor.run()[39m (pid=15484, ip=127.0.0.1, actor_id=b70f75f33beb24a380ed1c8b01000000, repr=<flwr.simulation.ray_transport.ray_actor.DefaultActor object at 0x0000020FEA7FB0D0>)
  File "python\ray\_raylet.pyx", line 1418, in ray._raylet.execute_task
  File "python\ray\_raylet.pyx", line 1498, in ray._raylet.execute_task
  File "python\ray\_raylet.pyx", line 1424, in ray._raylet.execute_task
  File "python\ray\_raylet.pyx", line 1364, in ray._raylet.execute_task.function_executor
  File "C:\Users\Stavros\miniconda3\envs\pyt_pg\Lib\site-packages\ray\_private\function_manager.py", line 726, in actor_method_executor
    return method(__ray_actor, *args, **kwargs)
           ^^^^^^^^^^^^^^^^^^^^^^^^^^^^^^^^^^^^
  File "C:\Users\Stavros\miniconda3\envs\pyt_pg\Lib\site-packages\ray\util\tracing\tracing_helper.py", line 464, in _resume_span
    return method(self, *_args, **_kwargs)
           ^^^^^^^^^^^^^^^^^^^^^^^^^^^^^^^
  File "C:\Users\Stavros\miniconda3\envs\pyt_pg\Lib\site-packages\flwr\simulation\ray_transport\ray_actor.py", line 90, in run
    raise ClientException(str(message)) from ex
flwr.simulation.ray_transport.ray_actor.ClientException: 
>>>>>>>A ClientException occurred.('\n\tSomething went wrong when running your client run.\n\tClient 37 crashed when the DefaultActor was running its run.\n\tException triggered on the client side: Traceback (most recent call last):\n  File "C:\\Users\\Stavros\\miniconda3\\envs\\pyt_pg\\Lib\\site-packages\\flwr\\simulation\\ray_transport\\ray_actor.py", line 76, in run\n    job_results = job_fn(client)\n                  ^^^^^^^^^^^^^^\n  File "C:\\Users\\Stavros\\miniconda3\\envs\\pyt_pg\\Lib\\site-packages\\flwr\\simulation\\ray_transport\\ray_client_proxy.py", line 207, in fit\n    return maybe_call_fit(\n           ^^^^^^^^^^^^^^^\n  File "C:\\Users\\Stavros\\miniconda3\\envs\\pyt_pg\\Lib\\site-packages\\flwr\\client\\client.py", line 234, in maybe_call_fit\n    return client.fit(fit_ins)\n           ^^^^^^^^^^^^^^^^^^^\n  File "C:\\Users\\Stavros\\miniconda3\\envs\\pyt_pg\\Lib\\site-packages\\flwr\\client\\numpy_client.py", line 238, in _fit\n    results = self.numpy_client.fit(parameters, ins.config)  # type: ignore\n              ^^^^^^^^^^^^^^^^^^^^^^^^^^^^^^^^^^^^^^^^^^^^^\n  File "C:\\Users\\Stavros\\Desktop\\PythonProjects\\FlowerYtTut\\client_scaffold.py", line 109, in fit\n    train_loss, train_acc = train_scaffold(self.model, self.trainloader, optim, epochs, self.device, server_cv, self.client_cv)\n                            ^^^^^^^^^^^^^^^^^^^^^^^^^^^^^^^^^^^^^^^^^^^^^^^^^^^^^^^^^^^^^^^^^^^^^^^^^^^^^^^^^^^^^^^^^^^^^^^^^^^\n  File "C:\\Users\\Stavros\\Desktop\\PythonProjects\\FlowerYtTut\\model.py", line 152, in train_scaffold\n    optimizer.step_custom(server_cv=server_cv, client_cv=client_cv)\n  File "C:\\Users\\Stavros\\Desktop\\PythonProjects\\FlowerYtTut\\model.py", line 132, in step_custom\n    par.data.add_(s_cv - c_cv, alpha=-group["lr"])\n                  ~~~~~^~~~~~\nRuntimeError: The size of tensor a (64) must match the size of tensor b (3) at non-singleton dimension 3\n',)
[2024-02-17 19:17:10,649][flwr][ERROR] - Traceback (most recent call last):
  File "C:\Users\Stavros\miniconda3\envs\pyt_pg\Lib\site-packages\flwr\simulation\ray_transport\ray_client_proxy.py", line 151, in _submit_job
    res, updated_context = self.actor_pool.get_client_result(self.cid, timeout)
                           ^^^^^^^^^^^^^^^^^^^^^^^^^^^^^^^^^^^^^^^^^^^^^^^^^^^^
  File "C:\Users\Stavros\miniconda3\envs\pyt_pg\Lib\site-packages\flwr\simulation\ray_transport\ray_actor.py", line 425, in get_client_result
    return self._fetch_future_result(cid)
           ^^^^^^^^^^^^^^^^^^^^^^^^^^^^^^
  File "C:\Users\Stavros\miniconda3\envs\pyt_pg\Lib\site-packages\flwr\simulation\ray_transport\ray_actor.py", line 306, in _fetch_future_result
    res_cid, res, updated_context = ray.get(
                                    ^^^^^^^^
  File "C:\Users\Stavros\miniconda3\envs\pyt_pg\Lib\site-packages\ray\_private\auto_init_hook.py", line 24, in auto_init_wrapper
    return fn(*args, **kwargs)
           ^^^^^^^^^^^^^^^^^^^
  File "C:\Users\Stavros\miniconda3\envs\pyt_pg\Lib\site-packages\ray\_private\client_mode_hook.py", line 103, in wrapper
    return func(*args, **kwargs)
           ^^^^^^^^^^^^^^^^^^^^^
  File "C:\Users\Stavros\miniconda3\envs\pyt_pg\Lib\site-packages\ray\_private\worker.py", line 2524, in get
    raise value.as_instanceof_cause()
ray.exceptions.RayTaskError(ClientException): [36mray::DefaultActor.run()[39m (pid=15840, ip=127.0.0.1, actor_id=86ae04ba45d66e99ed10d1b501000000, repr=<flwr.simulation.ray_transport.ray_actor.DefaultActor object at 0x0000028E89ADED10>)
                  ^^^^^^^^^^^^^^
  File "C:\Users\Stavros\miniconda3\envs\pyt_pg\Lib\site-packages\flwr\simulation\ray_transport\ray_client_proxy.py", line 207, in fit
    return maybe_call_fit(
           ^^^^^^^^^^^^^^^
  File "C:\Users\Stavros\miniconda3\envs\pyt_pg\Lib\site-packages\flwr\client\client.py", line 234, in maybe_call_fit
    return client.fit(fit_ins)
           ^^^^^^^^^^^^^^^^^^^
  File "C:\Users\Stavros\miniconda3\envs\pyt_pg\Lib\site-packages\flwr\client\numpy_client.py", line 238, in _fit
    results = self.numpy_client.fit(parameters, ins.config)  # type: ignore
              ^^^^^^^^^^^^^^^^^^^^^^^^^^^^^^^^^^^^^^^^^^^^^
  File "C:\Users\Stavros\Desktop\PythonProjects\FlowerYtTut\client_scaffold.py", line 109, in fit
    train_loss, train_acc = train_scaffold(self.model, self.trainloader, optim, epochs, self.device, server_cv, self.client_cv)
                            ^^^^^^^^^^^^^^^^^^^^^^^^^^^^^^^^^^^^^^^^^^^^^^^^^^^^^^^^^^^^^^^^^^^^^^^^^^^^^^^^^^^^^^^^^^^^^^^^^^^
  File "C:\Users\Stavros\Desktop\PythonProjects\FlowerYtTut\model.py", line 152, in train_scaffold
    optimizer.step_custom(server_cv=server_cv, client_cv=client_cv)
  File "C:\Users\Stavros\Desktop\PythonProjects\FlowerYtTut\model.py", line 132, in step_custom
    par.data.add_(s_cv - c_cv, alpha=-group["lr"])
                  ~~~~~^~~~~~
RuntimeError: The size of tensor a (64) must match the size of tensor b (3) at non-singleton dimension 3

The above exception was the direct cause of the following exception:

[36mray::DefaultActor.run()[39m (pid=15840, ip=127.0.0.1, actor_id=86ae04ba45d66e99ed10d1b501000000, repr=<flwr.simulation.ray_transport.ray_actor.DefaultActor object at 0x0000028E89ADED10>)
  File "python\ray\_raylet.pyx", line 1418, in ray._raylet.execute_task
  File "python\ray\_raylet.pyx", line 1498, in ray._raylet.execute_task
  File "python\ray\_raylet.pyx", line 1424, in ray._raylet.execute_task
  File "python\ray\_raylet.pyx", line 1364, in ray._raylet.execute_task.function_executor
  File "C:\Users\Stavros\miniconda3\envs\pyt_pg\Lib\site-packages\ray\_private\function_manager.py", line 726, in actor_method_executor
    return method(__ray_actor, *args, **kwargs)
           ^^^^^^^^^^^^^^^^^^^^^^^^^^^^^^^^^^^^
  File "C:\Users\Stavros\miniconda3\envs\pyt_pg\Lib\site-packages\ray\util\tracing\tracing_helper.py", line 464, in _resume_span
    return method(self, *_args, **_kwargs)
           ^^^^^^^^^^^^^^^^^^^^^^^^^^^^^^^
  File "C:\Users\Stavros\miniconda3\envs\pyt_pg\Lib\site-packages\flwr\simulation\ray_transport\ray_actor.py", line 90, in run
    raise ClientException(str(message)) from ex
flwr.simulation.ray_transport.ray_actor.ClientException: 
>>>>>>>A ClientException occurred.('\n\tSomething went wrong when running your client run.\n\tClient 88 crashed when the DefaultActor was running its run.\n\tException triggered on the client side: Traceback (most recent call last):\n  File "C:\\Users\\Stavros\\miniconda3\\envs\\pyt_pg\\Lib\\site-packages\\flwr\\simulation\\ray_transport\\ray_actor.py", line 76, in run\n    job_results = job_fn(client)\n                  ^^^^^^^^^^^^^^\n  File "C:\\Users\\Stavros\\miniconda3\\envs\\pyt_pg\\Lib\\site-packages\\flwr\\simulation\\ray_transport\\ray_client_proxy.py", line 207, in fit\n    return maybe_call_fit(\n           ^^^^^^^^^^^^^^^\n  File "C:\\Users\\Stavros\\miniconda3\\envs\\pyt_pg\\Lib\\site-packages\\flwr\\client\\client.py", line 234, in maybe_call_fit\n    return client.fit(fit_ins)\n           ^^^^^^^^^^^^^^^^^^^\n  File "C:\\Users\\Stavros\\miniconda3\\envs\\pyt_pg\\Lib\\site-packages\\flwr\\client\\numpy_client.py", line 238, in _fit\n    results = self.numpy_client.fit(parameters, ins.config)  # type: ignore\n              ^^^^^^^^^^^^^^^^^^^^^^^^^^^^^^^^^^^^^^^^^^^^^\n  File "C:\\Users\\Stavros\\Desktop\\PythonProjects\\FlowerYtTut\\client_scaffold.py", line 109, in fit\n    train_loss, train_acc = train_scaffold(self.model, self.trainloader, optim, epochs, self.device, server_cv, self.client_cv)\n                            ^^^^^^^^^^^^^^^^^^^^^^^^^^^^^^^^^^^^^^^^^^^^^^^^^^^^^^^^^^^^^^^^^^^^^^^^^^^^^^^^^^^^^^^^^^^^^^^^^^^\n  File "C:\\Users\\Stavros\\Desktop\\PythonProjects\\FlowerYtTut\\model.py", line 152, in train_scaffold\n    optimizer.step_custom(server_cv=server_cv, client_cv=client_cv)\n  File "C:\\Users\\Stavros\\Desktop\\PythonProjects\\FlowerYtTut\\model.py", line 132, in step_custom\n    par.data.add_(s_cv - c_cv, alpha=-group["lr"])\n                  ~~~~~^~~~~~\nRuntimeError: The size of tensor a (64) must match the size of tensor b (3) at non-singleton dimension 3\n',)

[2024-02-17 19:17:10,710][flwr][ERROR] - [36mray::DefaultActor.run()[39m (pid=15840, ip=127.0.0.1, actor_id=86ae04ba45d66e99ed10d1b501000000, repr=<flwr.simulation.ray_transport.ray_actor.DefaultActor object at 0x0000028E89ADED10>)
                  ^^^^^^^^^^^^^^
  File "C:\Users\Stavros\miniconda3\envs\pyt_pg\Lib\site-packages\flwr\simulation\ray_transport\ray_client_proxy.py", line 207, in fit
    return maybe_call_fit(
           ^^^^^^^^^^^^^^^
  File "C:\Users\Stavros\miniconda3\envs\pyt_pg\Lib\site-packages\flwr\client\client.py", line 234, in maybe_call_fit
    return client.fit(fit_ins)
           ^^^^^^^^^^^^^^^^^^^
  File "C:\Users\Stavros\miniconda3\envs\pyt_pg\Lib\site-packages\flwr\client\numpy_client.py", line 238, in _fit
    results = self.numpy_client.fit(parameters, ins.config)  # type: ignore
              ^^^^^^^^^^^^^^^^^^^^^^^^^^^^^^^^^^^^^^^^^^^^^
  File "C:\Users\Stavros\Desktop\PythonProjects\FlowerYtTut\client_scaffold.py", line 109, in fit
    train_loss, train_acc = train_scaffold(self.model, self.trainloader, optim, epochs, self.device, server_cv, self.client_cv)
                            ^^^^^^^^^^^^^^^^^^^^^^^^^^^^^^^^^^^^^^^^^^^^^^^^^^^^^^^^^^^^^^^^^^^^^^^^^^^^^^^^^^^^^^^^^^^^^^^^^^^
  File "C:\Users\Stavros\Desktop\PythonProjects\FlowerYtTut\model.py", line 152, in train_scaffold
    optimizer.step_custom(server_cv=server_cv, client_cv=client_cv)
  File "C:\Users\Stavros\Desktop\PythonProjects\FlowerYtTut\model.py", line 132, in step_custom
    par.data.add_(s_cv - c_cv, alpha=-group["lr"])
                  ~~~~~^~~~~~
RuntimeError: The size of tensor a (64) must match the size of tensor b (3) at non-singleton dimension 3

The above exception was the direct cause of the following exception:

[36mray::DefaultActor.run()[39m (pid=15840, ip=127.0.0.1, actor_id=86ae04ba45d66e99ed10d1b501000000, repr=<flwr.simulation.ray_transport.ray_actor.DefaultActor object at 0x0000028E89ADED10>)
  File "python\ray\_raylet.pyx", line 1418, in ray._raylet.execute_task
  File "python\ray\_raylet.pyx", line 1498, in ray._raylet.execute_task
  File "python\ray\_raylet.pyx", line 1424, in ray._raylet.execute_task
  File "python\ray\_raylet.pyx", line 1364, in ray._raylet.execute_task.function_executor
  File "C:\Users\Stavros\miniconda3\envs\pyt_pg\Lib\site-packages\ray\_private\function_manager.py", line 726, in actor_method_executor
    return method(__ray_actor, *args, **kwargs)
           ^^^^^^^^^^^^^^^^^^^^^^^^^^^^^^^^^^^^
  File "C:\Users\Stavros\miniconda3\envs\pyt_pg\Lib\site-packages\ray\util\tracing\tracing_helper.py", line 464, in _resume_span
    return method(self, *_args, **_kwargs)
           ^^^^^^^^^^^^^^^^^^^^^^^^^^^^^^^
  File "C:\Users\Stavros\miniconda3\envs\pyt_pg\Lib\site-packages\flwr\simulation\ray_transport\ray_actor.py", line 90, in run
    raise ClientException(str(message)) from ex
flwr.simulation.ray_transport.ray_actor.ClientException: 
>>>>>>>A ClientException occurred.('\n\tSomething went wrong when running your client run.\n\tClient 88 crashed when the DefaultActor was running its run.\n\tException triggered on the client side: Traceback (most recent call last):\n  File "C:\\Users\\Stavros\\miniconda3\\envs\\pyt_pg\\Lib\\site-packages\\flwr\\simulation\\ray_transport\\ray_actor.py", line 76, in run\n    job_results = job_fn(client)\n                  ^^^^^^^^^^^^^^\n  File "C:\\Users\\Stavros\\miniconda3\\envs\\pyt_pg\\Lib\\site-packages\\flwr\\simulation\\ray_transport\\ray_client_proxy.py", line 207, in fit\n    return maybe_call_fit(\n           ^^^^^^^^^^^^^^^\n  File "C:\\Users\\Stavros\\miniconda3\\envs\\pyt_pg\\Lib\\site-packages\\flwr\\client\\client.py", line 234, in maybe_call_fit\n    return client.fit(fit_ins)\n           ^^^^^^^^^^^^^^^^^^^\n  File "C:\\Users\\Stavros\\miniconda3\\envs\\pyt_pg\\Lib\\site-packages\\flwr\\client\\numpy_client.py", line 238, in _fit\n    results = self.numpy_client.fit(parameters, ins.config)  # type: ignore\n              ^^^^^^^^^^^^^^^^^^^^^^^^^^^^^^^^^^^^^^^^^^^^^\n  File "C:\\Users\\Stavros\\Desktop\\PythonProjects\\FlowerYtTut\\client_scaffold.py", line 109, in fit\n    train_loss, train_acc = train_scaffold(self.model, self.trainloader, optim, epochs, self.device, server_cv, self.client_cv)\n                            ^^^^^^^^^^^^^^^^^^^^^^^^^^^^^^^^^^^^^^^^^^^^^^^^^^^^^^^^^^^^^^^^^^^^^^^^^^^^^^^^^^^^^^^^^^^^^^^^^^^\n  File "C:\\Users\\Stavros\\Desktop\\PythonProjects\\FlowerYtTut\\model.py", line 152, in train_scaffold\n    optimizer.step_custom(server_cv=server_cv, client_cv=client_cv)\n  File "C:\\Users\\Stavros\\Desktop\\PythonProjects\\FlowerYtTut\\model.py", line 132, in step_custom\n    par.data.add_(s_cv - c_cv, alpha=-group["lr"])\n                  ~~~~~^~~~~~\nRuntimeError: The size of tensor a (64) must match the size of tensor b (3) at non-singleton dimension 3\n',)
[2024-02-17 19:17:10,782][flwr][ERROR] - Traceback (most recent call last):
  File "C:\Users\Stavros\miniconda3\envs\pyt_pg\Lib\site-packages\flwr\simulation\ray_transport\ray_client_proxy.py", line 151, in _submit_job
    res, updated_context = self.actor_pool.get_client_result(self.cid, timeout)
                           ^^^^^^^^^^^^^^^^^^^^^^^^^^^^^^^^^^^^^^^^^^^^^^^^^^^^
  File "C:\Users\Stavros\miniconda3\envs\pyt_pg\Lib\site-packages\flwr\simulation\ray_transport\ray_actor.py", line 425, in get_client_result
    return self._fetch_future_result(cid)
           ^^^^^^^^^^^^^^^^^^^^^^^^^^^^^^
  File "C:\Users\Stavros\miniconda3\envs\pyt_pg\Lib\site-packages\flwr\simulation\ray_transport\ray_actor.py", line 306, in _fetch_future_result
    res_cid, res, updated_context = ray.get(
                                    ^^^^^^^^
  File "C:\Users\Stavros\miniconda3\envs\pyt_pg\Lib\site-packages\ray\_private\auto_init_hook.py", line 24, in auto_init_wrapper
    return fn(*args, **kwargs)
           ^^^^^^^^^^^^^^^^^^^
  File "C:\Users\Stavros\miniconda3\envs\pyt_pg\Lib\site-packages\ray\_private\client_mode_hook.py", line 103, in wrapper
    return func(*args, **kwargs)
           ^^^^^^^^^^^^^^^^^^^^^
  File "C:\Users\Stavros\miniconda3\envs\pyt_pg\Lib\site-packages\ray\_private\worker.py", line 2524, in get
    raise value.as_instanceof_cause()
ray.exceptions.RayTaskError(ClientException): [36mray::DefaultActor.run()[39m (pid=15484, ip=127.0.0.1, actor_id=b70f75f33beb24a380ed1c8b01000000, repr=<flwr.simulation.ray_transport.ray_actor.DefaultActor object at 0x0000020FEA7FB0D0>)
                  ^^^^^^^^^^^^^^
  File "C:\Users\Stavros\miniconda3\envs\pyt_pg\Lib\site-packages\flwr\simulation\ray_transport\ray_client_proxy.py", line 207, in fit
    return maybe_call_fit(
           ^^^^^^^^^^^^^^^
  File "C:\Users\Stavros\miniconda3\envs\pyt_pg\Lib\site-packages\flwr\client\client.py", line 234, in maybe_call_fit
    return client.fit(fit_ins)
           ^^^^^^^^^^^^^^^^^^^
  File "C:\Users\Stavros\miniconda3\envs\pyt_pg\Lib\site-packages\flwr\client\numpy_client.py", line 238, in _fit
    results = self.numpy_client.fit(parameters, ins.config)  # type: ignore
              ^^^^^^^^^^^^^^^^^^^^^^^^^^^^^^^^^^^^^^^^^^^^^
  File "C:\Users\Stavros\Desktop\PythonProjects\FlowerYtTut\client_scaffold.py", line 109, in fit
    train_loss, train_acc = train_scaffold(self.model, self.trainloader, optim, epochs, self.device, server_cv, self.client_cv)
                            ^^^^^^^^^^^^^^^^^^^^^^^^^^^^^^^^^^^^^^^^^^^^^^^^^^^^^^^^^^^^^^^^^^^^^^^^^^^^^^^^^^^^^^^^^^^^^^^^^^^
  File "C:\Users\Stavros\Desktop\PythonProjects\FlowerYtTut\model.py", line 152, in train_scaffold
    optimizer.step_custom(server_cv=server_cv, client_cv=client_cv)
  File "C:\Users\Stavros\Desktop\PythonProjects\FlowerYtTut\model.py", line 132, in step_custom
    par.data.add_(s_cv - c_cv, alpha=-group["lr"])
                  ~~~~~^~~~~~
RuntimeError: The size of tensor a (64) must match the size of tensor b (3) at non-singleton dimension 3

The above exception was the direct cause of the following exception:

[36mray::DefaultActor.run()[39m (pid=15484, ip=127.0.0.1, actor_id=b70f75f33beb24a380ed1c8b01000000, repr=<flwr.simulation.ray_transport.ray_actor.DefaultActor object at 0x0000020FEA7FB0D0>)
  File "python\ray\_raylet.pyx", line 1418, in ray._raylet.execute_task
  File "python\ray\_raylet.pyx", line 1498, in ray._raylet.execute_task
  File "python\ray\_raylet.pyx", line 1424, in ray._raylet.execute_task
  File "python\ray\_raylet.pyx", line 1364, in ray._raylet.execute_task.function_executor
  File "C:\Users\Stavros\miniconda3\envs\pyt_pg\Lib\site-packages\ray\_private\function_manager.py", line 726, in actor_method_executor
    return method(__ray_actor, *args, **kwargs)
           ^^^^^^^^^^^^^^^^^^^^^^^^^^^^^^^^^^^^
  File "C:\Users\Stavros\miniconda3\envs\pyt_pg\Lib\site-packages\ray\util\tracing\tracing_helper.py", line 464, in _resume_span
    return method(self, *_args, **_kwargs)
           ^^^^^^^^^^^^^^^^^^^^^^^^^^^^^^^
  File "C:\Users\Stavros\miniconda3\envs\pyt_pg\Lib\site-packages\flwr\simulation\ray_transport\ray_actor.py", line 90, in run
    raise ClientException(str(message)) from ex
flwr.simulation.ray_transport.ray_actor.ClientException: 
>>>>>>>A ClientException occurred.('\n\tSomething went wrong when running your client run.\n\tClient 89 crashed when the DefaultActor was running its run.\n\tException triggered on the client side: Traceback (most recent call last):\n  File "C:\\Users\\Stavros\\miniconda3\\envs\\pyt_pg\\Lib\\site-packages\\flwr\\simulation\\ray_transport\\ray_actor.py", line 76, in run\n    job_results = job_fn(client)\n                  ^^^^^^^^^^^^^^\n  File "C:\\Users\\Stavros\\miniconda3\\envs\\pyt_pg\\Lib\\site-packages\\flwr\\simulation\\ray_transport\\ray_client_proxy.py", line 207, in fit\n    return maybe_call_fit(\n           ^^^^^^^^^^^^^^^\n  File "C:\\Users\\Stavros\\miniconda3\\envs\\pyt_pg\\Lib\\site-packages\\flwr\\client\\client.py", line 234, in maybe_call_fit\n    return client.fit(fit_ins)\n           ^^^^^^^^^^^^^^^^^^^\n  File "C:\\Users\\Stavros\\miniconda3\\envs\\pyt_pg\\Lib\\site-packages\\flwr\\client\\numpy_client.py", line 238, in _fit\n    results = self.numpy_client.fit(parameters, ins.config)  # type: ignore\n              ^^^^^^^^^^^^^^^^^^^^^^^^^^^^^^^^^^^^^^^^^^^^^\n  File "C:\\Users\\Stavros\\Desktop\\PythonProjects\\FlowerYtTut\\client_scaffold.py", line 109, in fit\n    train_loss, train_acc = train_scaffold(self.model, self.trainloader, optim, epochs, self.device, server_cv, self.client_cv)\n                            ^^^^^^^^^^^^^^^^^^^^^^^^^^^^^^^^^^^^^^^^^^^^^^^^^^^^^^^^^^^^^^^^^^^^^^^^^^^^^^^^^^^^^^^^^^^^^^^^^^^\n  File "C:\\Users\\Stavros\\Desktop\\PythonProjects\\FlowerYtTut\\model.py", line 152, in train_scaffold\n    optimizer.step_custom(server_cv=server_cv, client_cv=client_cv)\n  File "C:\\Users\\Stavros\\Desktop\\PythonProjects\\FlowerYtTut\\model.py", line 132, in step_custom\n    par.data.add_(s_cv - c_cv, alpha=-group["lr"])\n                  ~~~~~^~~~~~\nRuntimeError: The size of tensor a (64) must match the size of tensor b (3) at non-singleton dimension 3\n',)

[2024-02-17 19:17:10,803][flwr][ERROR] - [36mray::DefaultActor.run()[39m (pid=15484, ip=127.0.0.1, actor_id=b70f75f33beb24a380ed1c8b01000000, repr=<flwr.simulation.ray_transport.ray_actor.DefaultActor object at 0x0000020FEA7FB0D0>)
                  ^^^^^^^^^^^^^^
  File "C:\Users\Stavros\miniconda3\envs\pyt_pg\Lib\site-packages\flwr\simulation\ray_transport\ray_client_proxy.py", line 207, in fit
    return maybe_call_fit(
           ^^^^^^^^^^^^^^^
  File "C:\Users\Stavros\miniconda3\envs\pyt_pg\Lib\site-packages\flwr\client\client.py", line 234, in maybe_call_fit
    return client.fit(fit_ins)
           ^^^^^^^^^^^^^^^^^^^
  File "C:\Users\Stavros\miniconda3\envs\pyt_pg\Lib\site-packages\flwr\client\numpy_client.py", line 238, in _fit
    results = self.numpy_client.fit(parameters, ins.config)  # type: ignore
              ^^^^^^^^^^^^^^^^^^^^^^^^^^^^^^^^^^^^^^^^^^^^^
  File "C:\Users\Stavros\Desktop\PythonProjects\FlowerYtTut\client_scaffold.py", line 109, in fit
    train_loss, train_acc = train_scaffold(self.model, self.trainloader, optim, epochs, self.device, server_cv, self.client_cv)
                            ^^^^^^^^^^^^^^^^^^^^^^^^^^^^^^^^^^^^^^^^^^^^^^^^^^^^^^^^^^^^^^^^^^^^^^^^^^^^^^^^^^^^^^^^^^^^^^^^^^^
  File "C:\Users\Stavros\Desktop\PythonProjects\FlowerYtTut\model.py", line 152, in train_scaffold
    optimizer.step_custom(server_cv=server_cv, client_cv=client_cv)
  File "C:\Users\Stavros\Desktop\PythonProjects\FlowerYtTut\model.py", line 132, in step_custom
    par.data.add_(s_cv - c_cv, alpha=-group["lr"])
                  ~~~~~^~~~~~
RuntimeError: The size of tensor a (64) must match the size of tensor b (3) at non-singleton dimension 3

The above exception was the direct cause of the following exception:

[36mray::DefaultActor.run()[39m (pid=15484, ip=127.0.0.1, actor_id=b70f75f33beb24a380ed1c8b01000000, repr=<flwr.simulation.ray_transport.ray_actor.DefaultActor object at 0x0000020FEA7FB0D0>)
  File "python\ray\_raylet.pyx", line 1418, in ray._raylet.execute_task
  File "python\ray\_raylet.pyx", line 1498, in ray._raylet.execute_task
  File "python\ray\_raylet.pyx", line 1424, in ray._raylet.execute_task
  File "python\ray\_raylet.pyx", line 1364, in ray._raylet.execute_task.function_executor
  File "C:\Users\Stavros\miniconda3\envs\pyt_pg\Lib\site-packages\ray\_private\function_manager.py", line 726, in actor_method_executor
    return method(__ray_actor, *args, **kwargs)
           ^^^^^^^^^^^^^^^^^^^^^^^^^^^^^^^^^^^^
  File "C:\Users\Stavros\miniconda3\envs\pyt_pg\Lib\site-packages\ray\util\tracing\tracing_helper.py", line 464, in _resume_span
    return method(self, *_args, **_kwargs)
           ^^^^^^^^^^^^^^^^^^^^^^^^^^^^^^^
  File "C:\Users\Stavros\miniconda3\envs\pyt_pg\Lib\site-packages\flwr\simulation\ray_transport\ray_actor.py", line 90, in run
    raise ClientException(str(message)) from ex
flwr.simulation.ray_transport.ray_actor.ClientException: 
>>>>>>>A ClientException occurred.('\n\tSomething went wrong when running your client run.\n\tClient 89 crashed when the DefaultActor was running its run.\n\tException triggered on the client side: Traceback (most recent call last):\n  File "C:\\Users\\Stavros\\miniconda3\\envs\\pyt_pg\\Lib\\site-packages\\flwr\\simulation\\ray_transport\\ray_actor.py", line 76, in run\n    job_results = job_fn(client)\n                  ^^^^^^^^^^^^^^\n  File "C:\\Users\\Stavros\\miniconda3\\envs\\pyt_pg\\Lib\\site-packages\\flwr\\simulation\\ray_transport\\ray_client_proxy.py", line 207, in fit\n    return maybe_call_fit(\n           ^^^^^^^^^^^^^^^\n  File "C:\\Users\\Stavros\\miniconda3\\envs\\pyt_pg\\Lib\\site-packages\\flwr\\client\\client.py", line 234, in maybe_call_fit\n    return client.fit(fit_ins)\n           ^^^^^^^^^^^^^^^^^^^\n  File "C:\\Users\\Stavros\\miniconda3\\envs\\pyt_pg\\Lib\\site-packages\\flwr\\client\\numpy_client.py", line 238, in _fit\n    results = self.numpy_client.fit(parameters, ins.config)  # type: ignore\n              ^^^^^^^^^^^^^^^^^^^^^^^^^^^^^^^^^^^^^^^^^^^^^\n  File "C:\\Users\\Stavros\\Desktop\\PythonProjects\\FlowerYtTut\\client_scaffold.py", line 109, in fit\n    train_loss, train_acc = train_scaffold(self.model, self.trainloader, optim, epochs, self.device, server_cv, self.client_cv)\n                            ^^^^^^^^^^^^^^^^^^^^^^^^^^^^^^^^^^^^^^^^^^^^^^^^^^^^^^^^^^^^^^^^^^^^^^^^^^^^^^^^^^^^^^^^^^^^^^^^^^^\n  File "C:\\Users\\Stavros\\Desktop\\PythonProjects\\FlowerYtTut\\model.py", line 152, in train_scaffold\n    optimizer.step_custom(server_cv=server_cv, client_cv=client_cv)\n  File "C:\\Users\\Stavros\\Desktop\\PythonProjects\\FlowerYtTut\\model.py", line 132, in step_custom\n    par.data.add_(s_cv - c_cv, alpha=-group["lr"])\n                  ~~~~~^~~~~~\nRuntimeError: The size of tensor a (64) must match the size of tensor b (3) at non-singleton dimension 3\n',)
