[2024-03-11 09:50:53,687][flwr][WARNING] - Both server and strategy were provided, ignoring strategy
[2024-03-11 09:50:53,688][flwr][INFO] - Starting Flower simulation, config: ServerConfig(num_rounds=1, round_timeout=None)
[2024-03-11 09:51:01,132][flwr][INFO] - Flower VCE: Ray initialized with resources: {'CPU': 4.0, 'node:127.0.0.1': 1.0, 'memory': 874101966.0, 'object_store_memory': 437050982.0, 'node:__internal_head__': 1.0}
[2024-03-11 09:51:01,133][flwr][INFO] - Optimize your simulation with Flower VCE: https://flower.dev/docs/framework/how-to-run-simulations.html
[2024-03-11 09:51:01,133][flwr][INFO] - Flower VCE: Resources for each Virtual Client: {'num_cpus': 4, 'num_gpus': 0.0}
[2024-03-11 09:51:01,149][flwr][INFO] - Flower VCE: Creating VirtualClientEngineActorPool with 1 actors
[2024-03-11 09:51:01,156][flwr][INFO] - Initializing global parameters
[2024-03-11 09:51:01,157][flwr][INFO] - Requesting initial parameters from one random client
[2024-03-11 09:51:09,432][flwr][INFO] - Received initial parameters from one random client
[2024-03-11 09:51:09,433][flwr][INFO] - Evaluating initial parameters
[2024-03-11 09:54:05,022][flwr][INFO] - initial parameters (loss, other metrics): 0.0231983380317688, {'accuracy': 22.48046875}
[2024-03-11 09:54:05,029][flwr][INFO] - FL starting
[2024-03-11 09:54:05,034][flwr][DEBUG] - fit_round 1: strategy sampled 2 clients (out of 50)
[2024-03-11 09:56:37,457][flwr][ERROR] - Traceback (most recent call last):
  File "C:\Users\Stavros\miniconda3\envs\pyt_pg\Lib\site-packages\flwr\simulation\ray_transport\ray_client_proxy.py", line 151, in _submit_job
    res, updated_context = self.actor_pool.get_client_result(self.cid, timeout)
                           ^^^^^^^^^^^^^^^^^^^^^^^^^^^^^^^^^^^^^^^^^^^^^^^^^^^^
  File "C:\Users\Stavros\miniconda3\envs\pyt_pg\Lib\site-packages\flwr\simulation\ray_transport\ray_actor.py", line 425, in get_client_result
    return self._fetch_future_result(cid)
           ^^^^^^^^^^^^^^^^^^^^^^^^^^^^^^
  File "C:\Users\Stavros\miniconda3\envs\pyt_pg\Lib\site-packages\flwr\simulation\ray_transport\ray_actor.py", line 306, in _fetch_future_result
    res_cid, res, updated_context = ray.get(
                                    ^^^^^^^^
  File "C:\Users\Stavros\miniconda3\envs\pyt_pg\Lib\site-packages\ray\_private\auto_init_hook.py", line 24, in auto_init_wrapper
    return fn(*args, **kwargs)
           ^^^^^^^^^^^^^^^^^^^
  File "C:\Users\Stavros\miniconda3\envs\pyt_pg\Lib\site-packages\ray\_private\client_mode_hook.py", line 103, in wrapper
    return func(*args, **kwargs)
           ^^^^^^^^^^^^^^^^^^^^^
  File "C:\Users\Stavros\miniconda3\envs\pyt_pg\Lib\site-packages\ray\_private\worker.py", line 2524, in get
    raise value.as_instanceof_cause()
ray.exceptions.RayTaskError(ClientException): [36mray::DefaultActor.run()[39m (pid=10256, ip=127.0.0.1, actor_id=4a4f187d6c08c1cdd50dbd6d01000000, repr=<flwr.simulation.ray_transport.ray_actor.DefaultActor object at 0x000001B47CCC1690>)
                  ^^^^^^^^^^^^^^
  File "C:\Users\Stavros\miniconda3\envs\pyt_pg\Lib\site-packages\flwr\simulation\ray_transport\ray_client_proxy.py", line 207, in fit
    return maybe_call_fit(
           ^^^^^^^^^^^^^^^
  File "C:\Users\Stavros\miniconda3\envs\pyt_pg\Lib\site-packages\flwr\client\client.py", line 234, in maybe_call_fit
    return client.fit(fit_ins)
           ^^^^^^^^^^^^^^^^^^^
  File "C:\Users\Stavros\miniconda3\envs\pyt_pg\Lib\site-packages\flwr\client\numpy_client.py", line 238, in _fit
    results = self.numpy_client.fit(parameters, ins.config)  # type: ignore
              ^^^^^^^^^^^^^^^^^^^^^^^^^^^^^^^^^^^^^^^^^^^^^
  File "C:\Users\Stavros\Desktop\PythonProjects\FlowerYtTut\client.py", line 101, in fit
    temp_df.to_csv(f"{self.dir}/client_progress_{self.cid}.csv", index=False)
  File "C:\Users\Stavros\miniconda3\envs\pyt_pg\Lib\site-packages\pandas\core\generic.py", line 3902, in to_csv
    return DataFrameRenderer(formatter).to_csv(
           ^^^^^^^^^^^^^^^^^^^^^^^^^^^^^^^^^^^^
  File "C:\Users\Stavros\miniconda3\envs\pyt_pg\Lib\site-packages\pandas\io\formats\format.py", line 1152, in to_csv
    csv_formatter.save()
  File "C:\Users\Stavros\miniconda3\envs\pyt_pg\Lib\site-packages\pandas\io\formats\csvs.py", line 247, in save
    with get_handle(
         ^^^^^^^^^^^
  File "C:\Users\Stavros\miniconda3\envs\pyt_pg\Lib\site-packages\pandas\io\common.py", line 739, in get_handle
    check_parent_directory(str(handle))
  File "C:\Users\Stavros\miniconda3\envs\pyt_pg\Lib\site-packages\pandas\io\common.py", line 604, in check_parent_directory
    raise OSError(rf"Cannot save file into a non-existent directory: '{parent}'")
OSError: Cannot save file into a non-existent directory: 'C:\Users\Stavros\Desktop\PythonProjects\FlowerYtTut\outputs\2024-03-11\09-50-48\clients'

The above exception was the direct cause of the following exception:

[36mray::DefaultActor.run()[39m (pid=10256, ip=127.0.0.1, actor_id=4a4f187d6c08c1cdd50dbd6d01000000, repr=<flwr.simulation.ray_transport.ray_actor.DefaultActor object at 0x000001B47CCC1690>)
  File "python\ray\_raylet.pyx", line 1418, in ray._raylet.execute_task
  File "python\ray\_raylet.pyx", line 1498, in ray._raylet.execute_task
  File "python\ray\_raylet.pyx", line 1424, in ray._raylet.execute_task
  File "python\ray\_raylet.pyx", line 1364, in ray._raylet.execute_task.function_executor
  File "C:\Users\Stavros\miniconda3\envs\pyt_pg\Lib\site-packages\ray\_private\function_manager.py", line 726, in actor_method_executor
    return method(__ray_actor, *args, **kwargs)
           ^^^^^^^^^^^^^^^^^^^^^^^^^^^^^^^^^^^^
  File "C:\Users\Stavros\miniconda3\envs\pyt_pg\Lib\site-packages\ray\util\tracing\tracing_helper.py", line 464, in _resume_span
    return method(self, *_args, **_kwargs)
           ^^^^^^^^^^^^^^^^^^^^^^^^^^^^^^^
  File "C:\Users\Stavros\miniconda3\envs\pyt_pg\Lib\site-packages\flwr\simulation\ray_transport\ray_actor.py", line 90, in run
    raise ClientException(str(message)) from ex
flwr.simulation.ray_transport.ray_actor.ClientException: 
>>>>>>>A ClientException occurred.('\n\tSomething went wrong when running your client run.\n\tClient 12 crashed when the DefaultActor was running its run.\n\tException triggered on the client side: Traceback (most recent call last):\n  File "C:\\Users\\Stavros\\miniconda3\\envs\\pyt_pg\\Lib\\site-packages\\flwr\\simulation\\ray_transport\\ray_actor.py", line 76, in run\n    job_results = job_fn(client)\n                  ^^^^^^^^^^^^^^\n  File "C:\\Users\\Stavros\\miniconda3\\envs\\pyt_pg\\Lib\\site-packages\\flwr\\simulation\\ray_transport\\ray_client_proxy.py", line 207, in fit\n    return maybe_call_fit(\n           ^^^^^^^^^^^^^^^\n  File "C:\\Users\\Stavros\\miniconda3\\envs\\pyt_pg\\Lib\\site-packages\\flwr\\client\\client.py", line 234, in maybe_call_fit\n    return client.fit(fit_ins)\n           ^^^^^^^^^^^^^^^^^^^\n  File "C:\\Users\\Stavros\\miniconda3\\envs\\pyt_pg\\Lib\\site-packages\\flwr\\client\\numpy_client.py", line 238, in _fit\n    results = self.numpy_client.fit(parameters, ins.config)  # type: ignore\n              ^^^^^^^^^^^^^^^^^^^^^^^^^^^^^^^^^^^^^^^^^^^^^\n  File "C:\\Users\\Stavros\\Desktop\\PythonProjects\\FlowerYtTut\\client.py", line 101, in fit\n    temp_df.to_csv(f"{self.dir}/client_progress_{self.cid}.csv", index=False)\n  File "C:\\Users\\Stavros\\miniconda3\\envs\\pyt_pg\\Lib\\site-packages\\pandas\\core\\generic.py", line 3902, in to_csv\n    return DataFrameRenderer(formatter).to_csv(\n           ^^^^^^^^^^^^^^^^^^^^^^^^^^^^^^^^^^^^\n  File "C:\\Users\\Stavros\\miniconda3\\envs\\pyt_pg\\Lib\\site-packages\\pandas\\io\\formats\\format.py", line 1152, in to_csv\n    csv_formatter.save()\n  File "C:\\Users\\Stavros\\miniconda3\\envs\\pyt_pg\\Lib\\site-packages\\pandas\\io\\formats\\csvs.py", line 247, in save\n    with get_handle(\n         ^^^^^^^^^^^\n  File "C:\\Users\\Stavros\\miniconda3\\envs\\pyt_pg\\Lib\\site-packages\\pandas\\io\\common.py", line 739, in get_handle\n    check_parent_directory(str(handle))\n  File "C:\\Users\\Stavros\\miniconda3\\envs\\pyt_pg\\Lib\\site-packages\\pandas\\io\\common.py", line 604, in check_parent_directory\n    raise OSError(rf"Cannot save file into a non-existent directory: \'{parent}\'")\nOSError: Cannot save file into a non-existent directory: \'C:\\Users\\Stavros\\Desktop\\PythonProjects\\FlowerYtTut\\outputs\\2024-03-11\\09-50-48\\clients\'\n',)

[2024-03-11 09:56:37,894][flwr][ERROR] - [36mray::DefaultActor.run()[39m (pid=10256, ip=127.0.0.1, actor_id=4a4f187d6c08c1cdd50dbd6d01000000, repr=<flwr.simulation.ray_transport.ray_actor.DefaultActor object at 0x000001B47CCC1690>)
                  ^^^^^^^^^^^^^^
  File "C:\Users\Stavros\miniconda3\envs\pyt_pg\Lib\site-packages\flwr\simulation\ray_transport\ray_client_proxy.py", line 207, in fit
    return maybe_call_fit(
           ^^^^^^^^^^^^^^^
  File "C:\Users\Stavros\miniconda3\envs\pyt_pg\Lib\site-packages\flwr\client\client.py", line 234, in maybe_call_fit
    return client.fit(fit_ins)
           ^^^^^^^^^^^^^^^^^^^
  File "C:\Users\Stavros\miniconda3\envs\pyt_pg\Lib\site-packages\flwr\client\numpy_client.py", line 238, in _fit
    results = self.numpy_client.fit(parameters, ins.config)  # type: ignore
              ^^^^^^^^^^^^^^^^^^^^^^^^^^^^^^^^^^^^^^^^^^^^^
  File "C:\Users\Stavros\Desktop\PythonProjects\FlowerYtTut\client.py", line 101, in fit
    temp_df.to_csv(f"{self.dir}/client_progress_{self.cid}.csv", index=False)
  File "C:\Users\Stavros\miniconda3\envs\pyt_pg\Lib\site-packages\pandas\core\generic.py", line 3902, in to_csv
    return DataFrameRenderer(formatter).to_csv(
           ^^^^^^^^^^^^^^^^^^^^^^^^^^^^^^^^^^^^
  File "C:\Users\Stavros\miniconda3\envs\pyt_pg\Lib\site-packages\pandas\io\formats\format.py", line 1152, in to_csv
    csv_formatter.save()
  File "C:\Users\Stavros\miniconda3\envs\pyt_pg\Lib\site-packages\pandas\io\formats\csvs.py", line 247, in save
    with get_handle(
         ^^^^^^^^^^^
  File "C:\Users\Stavros\miniconda3\envs\pyt_pg\Lib\site-packages\pandas\io\common.py", line 739, in get_handle
    check_parent_directory(str(handle))
  File "C:\Users\Stavros\miniconda3\envs\pyt_pg\Lib\site-packages\pandas\io\common.py", line 604, in check_parent_directory
    raise OSError(rf"Cannot save file into a non-existent directory: '{parent}'")
OSError: Cannot save file into a non-existent directory: 'C:\Users\Stavros\Desktop\PythonProjects\FlowerYtTut\outputs\2024-03-11\09-50-48\clients'

The above exception was the direct cause of the following exception:

[36mray::DefaultActor.run()[39m (pid=10256, ip=127.0.0.1, actor_id=4a4f187d6c08c1cdd50dbd6d01000000, repr=<flwr.simulation.ray_transport.ray_actor.DefaultActor object at 0x000001B47CCC1690>)
  File "python\ray\_raylet.pyx", line 1418, in ray._raylet.execute_task
  File "python\ray\_raylet.pyx", line 1498, in ray._raylet.execute_task
  File "python\ray\_raylet.pyx", line 1424, in ray._raylet.execute_task
  File "python\ray\_raylet.pyx", line 1364, in ray._raylet.execute_task.function_executor
  File "C:\Users\Stavros\miniconda3\envs\pyt_pg\Lib\site-packages\ray\_private\function_manager.py", line 726, in actor_method_executor
    return method(__ray_actor, *args, **kwargs)
           ^^^^^^^^^^^^^^^^^^^^^^^^^^^^^^^^^^^^
  File "C:\Users\Stavros\miniconda3\envs\pyt_pg\Lib\site-packages\ray\util\tracing\tracing_helper.py", line 464, in _resume_span
    return method(self, *_args, **_kwargs)
           ^^^^^^^^^^^^^^^^^^^^^^^^^^^^^^^
  File "C:\Users\Stavros\miniconda3\envs\pyt_pg\Lib\site-packages\flwr\simulation\ray_transport\ray_actor.py", line 90, in run
    raise ClientException(str(message)) from ex
flwr.simulation.ray_transport.ray_actor.ClientException: 
>>>>>>>A ClientException occurred.('\n\tSomething went wrong when running your client run.\n\tClient 12 crashed when the DefaultActor was running its run.\n\tException triggered on the client side: Traceback (most recent call last):\n  File "C:\\Users\\Stavros\\miniconda3\\envs\\pyt_pg\\Lib\\site-packages\\flwr\\simulation\\ray_transport\\ray_actor.py", line 76, in run\n    job_results = job_fn(client)\n                  ^^^^^^^^^^^^^^\n  File "C:\\Users\\Stavros\\miniconda3\\envs\\pyt_pg\\Lib\\site-packages\\flwr\\simulation\\ray_transport\\ray_client_proxy.py", line 207, in fit\n    return maybe_call_fit(\n           ^^^^^^^^^^^^^^^\n  File "C:\\Users\\Stavros\\miniconda3\\envs\\pyt_pg\\Lib\\site-packages\\flwr\\client\\client.py", line 234, in maybe_call_fit\n    return client.fit(fit_ins)\n           ^^^^^^^^^^^^^^^^^^^\n  File "C:\\Users\\Stavros\\miniconda3\\envs\\pyt_pg\\Lib\\site-packages\\flwr\\client\\numpy_client.py", line 238, in _fit\n    results = self.numpy_client.fit(parameters, ins.config)  # type: ignore\n              ^^^^^^^^^^^^^^^^^^^^^^^^^^^^^^^^^^^^^^^^^^^^^\n  File "C:\\Users\\Stavros\\Desktop\\PythonProjects\\FlowerYtTut\\client.py", line 101, in fit\n    temp_df.to_csv(f"{self.dir}/client_progress_{self.cid}.csv", index=False)\n  File "C:\\Users\\Stavros\\miniconda3\\envs\\pyt_pg\\Lib\\site-packages\\pandas\\core\\generic.py", line 3902, in to_csv\n    return DataFrameRenderer(formatter).to_csv(\n           ^^^^^^^^^^^^^^^^^^^^^^^^^^^^^^^^^^^^\n  File "C:\\Users\\Stavros\\miniconda3\\envs\\pyt_pg\\Lib\\site-packages\\pandas\\io\\formats\\format.py", line 1152, in to_csv\n    csv_formatter.save()\n  File "C:\\Users\\Stavros\\miniconda3\\envs\\pyt_pg\\Lib\\site-packages\\pandas\\io\\formats\\csvs.py", line 247, in save\n    with get_handle(\n         ^^^^^^^^^^^\n  File "C:\\Users\\Stavros\\miniconda3\\envs\\pyt_pg\\Lib\\site-packages\\pandas\\io\\common.py", line 739, in get_handle\n    check_parent_directory(str(handle))\n  File "C:\\Users\\Stavros\\miniconda3\\envs\\pyt_pg\\Lib\\site-packages\\pandas\\io\\common.py", line 604, in check_parent_directory\n    raise OSError(rf"Cannot save file into a non-existent directory: \'{parent}\'")\nOSError: Cannot save file into a non-existent directory: \'C:\\Users\\Stavros\\Desktop\\PythonProjects\\FlowerYtTut\\outputs\\2024-03-11\\09-50-48\\clients\'\n',)
