[2024-02-18 15:22:42,362][flwr][WARNING] - Both server and strategy were provided, ignoring strategy
[2024-02-18 15:22:42,362][flwr][INFO] - Starting Flower simulation, config: ServerConfig(num_rounds=1, round_timeout=None)
[2024-02-18 15:22:48,858][flwr][INFO] - Flower VCE: Ray initialized with resources: {'object_store_memory': 1329219993.0, 'node:127.0.0.1': 1.0, 'memory': 2658439988.0, 'node:__internal_head__': 1.0, 'CPU': 4.0}
[2024-02-18 15:22:48,859][flwr][INFO] - Optimize your simulation with Flower VCE: https://flower.dev/docs/framework/how-to-run-simulations.html
[2024-02-18 15:22:48,860][flwr][INFO] - Flower VCE: Resources for each Virtual Client: {'num_cpus': 2, 'num_gpus': 0.0}
[2024-02-18 15:22:48,876][flwr][INFO] - Flower VCE: Creating VirtualClientEngineActorPool with 2 actors
[2024-02-18 15:22:48,878][flwr][INFO] - Initializing global parameters
[2024-02-18 15:22:48,878][flwr][INFO] - Requesting initial parameters from one random client
[2024-02-18 15:22:56,864][flwr][INFO] - Received initial parameters from one random client
[2024-02-18 15:22:56,864][flwr][INFO] - Evaluating initial parameters
[2024-02-18 15:25:48,532][flwr][INFO] - initial parameters (loss, other metrics): 0.02356067109107971, {'accuracy': 21.640625}
[2024-02-18 15:25:48,535][flwr][INFO] - FL starting
[2024-02-18 15:25:48,540][flwr][DEBUG] - fit_round 1: strategy sampled 10 clients (out of 100)
[2024-02-18 15:28:04,115][flwr][ERROR] - Traceback (most recent call last):
  File "C:\Users\Stavros\miniconda3\envs\pyt_pg\Lib\site-packages\flwr\simulation\ray_transport\ray_client_proxy.py", line 151, in _submit_job
    res, updated_context = self.actor_pool.get_client_result(self.cid, timeout)
                           ^^^^^^^^^^^^^^^^^^^^^^^^^^^^^^^^^^^^^^^^^^^^^^^^^^^^
  File "C:\Users\Stavros\miniconda3\envs\pyt_pg\Lib\site-packages\flwr\simulation\ray_transport\ray_actor.py", line 418, in get_client_result
    self.process_unordered_future(timeout=timeout)
  File "C:\Users\Stavros\miniconda3\envs\pyt_pg\Lib\site-packages\flwr\simulation\ray_transport\ray_actor.py", line 400, in process_unordered_future
    self._return_actor(actor)  # type: ignore
    ^^^^^^^^^^^^^^^^^^^^^^^^^
  File "C:\Users\Stavros\miniconda3\envs\pyt_pg\Lib\site-packages\ray\util\actor_pool.py", line 366, in _return_actor
    self.submit(*self._pending_submits.pop(0))
  File "C:\Users\Stavros\miniconda3\envs\pyt_pg\Lib\site-packages\flwr\simulation\ray_transport\ray_actor.py", line 249, in submit
    future = fn(actor, client_fn, job_fn, cid, context)
             ^^^^^^^^^^^^^^^^^^^^^^^^^^^^^^^^^^^^^^^^^^
  File "C:\Users\Stavros\miniconda3\envs\pyt_pg\Lib\site-packages\flwr\simulation\ray_transport\ray_client_proxy.py", line 148, in <lambda>
    lambda a, c_fn, j_fn, cid, state: a.run.remote(c_fn, j_fn, cid, state),
                                      ^^^^^^^^^^^^^^^^^^^^^^^^^^^^^^^^^^^^
  File "C:\Users\Stavros\miniconda3\envs\pyt_pg\Lib\site-packages\ray\actor.py", line 144, in remote
    return self._remote(args, kwargs)
           ^^^^^^^^^^^^^^^^^^^^^^^^^^
  File "C:\Users\Stavros\miniconda3\envs\pyt_pg\Lib\site-packages\ray\util\tracing\tracing_helper.py", line 423, in _start_span
    return method(self, args, kwargs, *_args, **_kwargs)
           ^^^^^^^^^^^^^^^^^^^^^^^^^^^^^^^^^^^^^^^^^^^^^
  File "C:\Users\Stavros\miniconda3\envs\pyt_pg\Lib\site-packages\ray\actor.py", line 190, in _remote
    return invocation(args, kwargs)
           ^^^^^^^^^^^^^^^^^^^^^^^^
  File "C:\Users\Stavros\miniconda3\envs\pyt_pg\Lib\site-packages\ray\actor.py", line 177, in invocation
    return actor._actor_method_call(
           ^^^^^^^^^^^^^^^^^^^^^^^^^
  File "C:\Users\Stavros\miniconda3\envs\pyt_pg\Lib\site-packages\ray\actor.py", line 1175, in _actor_method_call
    object_refs = worker.core_worker.submit_actor_task(
                  ^^^^^^^^^^^^^^^^^^^^^^^^^^^^^^^^^^^^^
  File "python\ray\_raylet.pyx", line 3350, in ray._raylet.CoreWorker.submit_actor_task
  File "python\ray\_raylet.pyx", line 3355, in ray._raylet.CoreWorker.submit_actor_task
  File "python\ray\_raylet.pyx", line 649, in ray._raylet.prepare_args_and_increment_put_refs
  File "python\ray\_raylet.pyx", line 640, in ray._raylet.prepare_args_and_increment_put_refs
  File "python\ray\_raylet.pyx", line 734, in ray._raylet.prepare_args_internal
  File "python\ray\_raylet.pyx", line 2939, in ray._raylet.CoreWorker.put_serialized_object_and_increment_local_ref
  File "python\ray\_raylet.pyx", line 2831, in ray._raylet.CoreWorker._create_put_buffer
  File "python\ray\_raylet.pyx", line 412, in ray._raylet.check_status
ray.exceptions.RaySystemError: System error: Unknown error

[2024-02-18 15:28:04,120][flwr][ERROR] - System error: Unknown error
[2024-02-18 15:28:06,274][flwr][ERROR] - The actor died unexpectedly before finishing this task.
[2024-02-18 15:28:06,284][flwr][ERROR] - Traceback (most recent call last):
  File "C:\Users\Stavros\miniconda3\envs\pyt_pg\Lib\site-packages\flwr\simulation\ray_transport\ray_client_proxy.py", line 151, in _submit_job
    res, updated_context = self.actor_pool.get_client_result(self.cid, timeout)
                           ^^^^^^^^^^^^^^^^^^^^^^^^^^^^^^^^^^^^^^^^^^^^^^^^^^^^
  File "C:\Users\Stavros\miniconda3\envs\pyt_pg\Lib\site-packages\flwr\simulation\ray_transport\ray_actor.py", line 418, in get_client_result
    self.process_unordered_future(timeout=timeout)
  File "C:\Users\Stavros\miniconda3\envs\pyt_pg\Lib\site-packages\flwr\simulation\ray_transport\ray_actor.py", line 400, in process_unordered_future
    self._return_actor(actor)  # type: ignore
    ^^^^^^^^^^^^^^^^^^^^^^^^^
  File "C:\Users\Stavros\miniconda3\envs\pyt_pg\Lib\site-packages\ray\util\actor_pool.py", line 366, in _return_actor
    self.submit(*self._pending_submits.pop(0))
  File "C:\Users\Stavros\miniconda3\envs\pyt_pg\Lib\site-packages\flwr\simulation\ray_transport\ray_actor.py", line 249, in submit
    future = fn(actor, client_fn, job_fn, cid, context)
             ^^^^^^^^^^^^^^^^^^^^^^^^^^^^^^^^^^^^^^^^^^
  File "C:\Users\Stavros\miniconda3\envs\pyt_pg\Lib\site-packages\flwr\simulation\ray_transport\ray_client_proxy.py", line 148, in <lambda>
    lambda a, c_fn, j_fn, cid, state: a.run.remote(c_fn, j_fn, cid, state),
                                      ^^^^^^^^^^^^^^^^^^^^^^^^^^^^^^^^^^^^
  File "C:\Users\Stavros\miniconda3\envs\pyt_pg\Lib\site-packages\ray\actor.py", line 144, in remote
    return self._remote(args, kwargs)
           ^^^^^^^^^^^^^^^^^^^^^^^^^^
  File "C:\Users\Stavros\miniconda3\envs\pyt_pg\Lib\site-packages\ray\util\tracing\tracing_helper.py", line 423, in _start_span
    return method(self, args, kwargs, *_args, **_kwargs)
           ^^^^^^^^^^^^^^^^^^^^^^^^^^^^^^^^^^^^^^^^^^^^^
  File "C:\Users\Stavros\miniconda3\envs\pyt_pg\Lib\site-packages\ray\actor.py", line 190, in _remote
    return invocation(args, kwargs)
           ^^^^^^^^^^^^^^^^^^^^^^^^
  File "C:\Users\Stavros\miniconda3\envs\pyt_pg\Lib\site-packages\ray\actor.py", line 177, in invocation
    return actor._actor_method_call(
           ^^^^^^^^^^^^^^^^^^^^^^^^^
  File "C:\Users\Stavros\miniconda3\envs\pyt_pg\Lib\site-packages\ray\actor.py", line 1175, in _actor_method_call
    object_refs = worker.core_worker.submit_actor_task(
                  ^^^^^^^^^^^^^^^^^^^^^^^^^^^^^^^^^^^^^
  File "python\ray\_raylet.pyx", line 3350, in ray._raylet.CoreWorker.submit_actor_task
  File "python\ray\_raylet.pyx", line 3355, in ray._raylet.CoreWorker.submit_actor_task
  File "python\ray\_raylet.pyx", line 649, in ray._raylet.prepare_args_and_increment_put_refs
  File "python\ray\_raylet.pyx", line 640, in ray._raylet.prepare_args_and_increment_put_refs
  File "python\ray\_raylet.pyx", line 734, in ray._raylet.prepare_args_internal
  File "python\ray\_raylet.pyx", line 2939, in ray._raylet.CoreWorker.put_serialized_object_and_increment_local_ref
  File "python\ray\_raylet.pyx", line 2831, in ray._raylet.CoreWorker._create_put_buffer
  File "python\ray\_raylet.pyx", line 412, in ray._raylet.check_status
ray.exceptions.RaySystemError: System error: Unknown error

[2024-02-18 15:28:06,286][flwr][ERROR] - System error: Unknown error
[2024-02-18 15:28:06,484][flwr][ERROR] - Traceback (most recent call last):
  File "C:\Users\Stavros\miniconda3\envs\pyt_pg\Lib\site-packages\flwr\simulation\ray_transport\ray_client_proxy.py", line 151, in _submit_job
    res, updated_context = self.actor_pool.get_client_result(self.cid, timeout)
                           ^^^^^^^^^^^^^^^^^^^^^^^^^^^^^^^^^^^^^^^^^^^^^^^^^^^^
  File "C:\Users\Stavros\miniconda3\envs\pyt_pg\Lib\site-packages\flwr\simulation\ray_transport\ray_actor.py", line 425, in get_client_result
    return self._fetch_future_result(cid)
           ^^^^^^^^^^^^^^^^^^^^^^^^^^^^^^
  File "C:\Users\Stavros\miniconda3\envs\pyt_pg\Lib\site-packages\flwr\simulation\ray_transport\ray_actor.py", line 306, in _fetch_future_result
    res_cid, res, updated_context = ray.get(
                                    ^^^^^^^^
  File "C:\Users\Stavros\miniconda3\envs\pyt_pg\Lib\site-packages\ray\_private\auto_init_hook.py", line 24, in auto_init_wrapper
    return fn(*args, **kwargs)
           ^^^^^^^^^^^^^^^^^^^
  File "C:\Users\Stavros\miniconda3\envs\pyt_pg\Lib\site-packages\ray\_private\client_mode_hook.py", line 103, in wrapper
    return func(*args, **kwargs)
           ^^^^^^^^^^^^^^^^^^^^^
  File "C:\Users\Stavros\miniconda3\envs\pyt_pg\Lib\site-packages\ray\_private\worker.py", line 2513, in get
    raise ValueError(
ValueError: 'object_refs' must either be an ObjectRef or a list of ObjectRefs.

[2024-02-18 15:28:06,487][flwr][ERROR] - Traceback (most recent call last):
  File "C:\Users\Stavros\miniconda3\envs\pyt_pg\Lib\site-packages\flwr\simulation\ray_transport\ray_client_proxy.py", line 151, in _submit_job
    res, updated_context = self.actor_pool.get_client_result(self.cid, timeout)
                           ^^^^^^^^^^^^^^^^^^^^^^^^^^^^^^^^^^^^^^^^^^^^^^^^^^^^
  File "C:\Users\Stavros\miniconda3\envs\pyt_pg\Lib\site-packages\flwr\simulation\ray_transport\ray_actor.py", line 425, in get_client_result
    return self._fetch_future_result(cid)
           ^^^^^^^^^^^^^^^^^^^^^^^^^^^^^^
  File "C:\Users\Stavros\miniconda3\envs\pyt_pg\Lib\site-packages\flwr\simulation\ray_transport\ray_actor.py", line 306, in _fetch_future_result
    res_cid, res, updated_context = ray.get(
                                    ^^^^^^^^
  File "C:\Users\Stavros\miniconda3\envs\pyt_pg\Lib\site-packages\ray\_private\auto_init_hook.py", line 24, in auto_init_wrapper
    return fn(*args, **kwargs)
           ^^^^^^^^^^^^^^^^^^^
  File "C:\Users\Stavros\miniconda3\envs\pyt_pg\Lib\site-packages\ray\_private\client_mode_hook.py", line 103, in wrapper
    return func(*args, **kwargs)
           ^^^^^^^^^^^^^^^^^^^^^
  File "C:\Users\Stavros\miniconda3\envs\pyt_pg\Lib\site-packages\ray\_private\worker.py", line 2513, in get
    raise ValueError(
ValueError: 'object_refs' must either be an ObjectRef or a list of ObjectRefs.

[2024-02-18 15:28:06,490][flwr][ERROR] - Traceback (most recent call last):
  File "C:\Users\Stavros\miniconda3\envs\pyt_pg\Lib\site-packages\flwr\simulation\ray_transport\ray_client_proxy.py", line 151, in _submit_job
    res, updated_context = self.actor_pool.get_client_result(self.cid, timeout)
                           ^^^^^^^^^^^^^^^^^^^^^^^^^^^^^^^^^^^^^^^^^^^^^^^^^^^^
  File "C:\Users\Stavros\miniconda3\envs\pyt_pg\Lib\site-packages\flwr\simulation\ray_transport\ray_actor.py", line 425, in get_client_result
    return self._fetch_future_result(cid)
           ^^^^^^^^^^^^^^^^^^^^^^^^^^^^^^
  File "C:\Users\Stavros\miniconda3\envs\pyt_pg\Lib\site-packages\flwr\simulation\ray_transport\ray_actor.py", line 315, in _fetch_future_result
    raise ex
  File "C:\Users\Stavros\miniconda3\envs\pyt_pg\Lib\site-packages\flwr\simulation\ray_transport\ray_actor.py", line 306, in _fetch_future_result
    res_cid, res, updated_context = ray.get(
                                    ^^^^^^^^
  File "C:\Users\Stavros\miniconda3\envs\pyt_pg\Lib\site-packages\ray\_private\auto_init_hook.py", line 24, in auto_init_wrapper
    return fn(*args, **kwargs)
           ^^^^^^^^^^^^^^^^^^^
  File "C:\Users\Stavros\miniconda3\envs\pyt_pg\Lib\site-packages\ray\_private\client_mode_hook.py", line 103, in wrapper
    return func(*args, **kwargs)
           ^^^^^^^^^^^^^^^^^^^^^
  File "C:\Users\Stavros\miniconda3\envs\pyt_pg\Lib\site-packages\ray\_private\worker.py", line 2526, in get
    raise value
ray.exceptions.RayActorError: The actor died unexpectedly before finishing this task.

[2024-02-18 15:28:06,491][flwr][ERROR] - 'object_refs' must either be an ObjectRef or a list of ObjectRefs.
[2024-02-18 15:28:06,492][flwr][ERROR] - Traceback (most recent call last):
  File "C:\Users\Stavros\miniconda3\envs\pyt_pg\Lib\site-packages\flwr\simulation\ray_transport\ray_client_proxy.py", line 151, in _submit_job
    res, updated_context = self.actor_pool.get_client_result(self.cid, timeout)
                           ^^^^^^^^^^^^^^^^^^^^^^^^^^^^^^^^^^^^^^^^^^^^^^^^^^^^
  File "C:\Users\Stavros\miniconda3\envs\pyt_pg\Lib\site-packages\flwr\simulation\ray_transport\ray_actor.py", line 425, in get_client_result
    return self._fetch_future_result(cid)
           ^^^^^^^^^^^^^^^^^^^^^^^^^^^^^^
  File "C:\Users\Stavros\miniconda3\envs\pyt_pg\Lib\site-packages\flwr\simulation\ray_transport\ray_actor.py", line 306, in _fetch_future_result
    res_cid, res, updated_context = ray.get(
                                    ^^^^^^^^
  File "C:\Users\Stavros\miniconda3\envs\pyt_pg\Lib\site-packages\ray\_private\auto_init_hook.py", line 24, in auto_init_wrapper
    return fn(*args, **kwargs)
           ^^^^^^^^^^^^^^^^^^^
  File "C:\Users\Stavros\miniconda3\envs\pyt_pg\Lib\site-packages\ray\_private\client_mode_hook.py", line 103, in wrapper
    return func(*args, **kwargs)
           ^^^^^^^^^^^^^^^^^^^^^
  File "C:\Users\Stavros\miniconda3\envs\pyt_pg\Lib\site-packages\ray\_private\worker.py", line 2513, in get
    raise ValueError(
ValueError: 'object_refs' must either be an ObjectRef or a list of ObjectRefs.

[2024-02-18 15:28:06,494][flwr][ERROR] - 'object_refs' must either be an ObjectRef or a list of ObjectRefs.
[2024-02-18 15:28:06,494][flwr][ERROR] - The actor died unexpectedly before finishing this task.
[2024-02-18 15:28:06,495][flwr][ERROR] - 'object_refs' must either be an ObjectRef or a list of ObjectRefs.
